File: Tensile_tests/PA12vp_C2_XZ_2 05-24-22 14 11 27 PM/DAQ- Time, … - (Timed).txt
File Path: C:\MTS TestSuite\Data Files\Chahine\DOE\PA12vp_C2_XZ_2 05-24-22 14 11 27 PM\DAQ- Time, … - (Timed).txt
Test: MTS EM Tension (Extensometer)_Grand_Chahine 1
Test Run: PA12vp_C2_XZ_2
Date: 5/24/2022 2:11:03 PM


Time 	Load 	Crosshead 	Extensometer 	Strain 	Stress
sec	N	mm	mm	mm/mm	N/mm²
0.100000001490116	38.9040641784668	0.0606941757723689	0.0182926833076635	0.000292682932922617	0.975772875
0.200000002980232	95.1394577026367	0.144004428875633	0.0512195110786706	0.000951219466514885	2.38624175
0.300000011920929	154.083526611328	0.228007018449716	0.0768292666180059	0.00146341463550925	3.86464825
0.400000005960464	206.736053466797	0.311548035824671	0.106097562820651	0.00204878044314682	5.1852535
0.5	261.278259277344	0.395089067751542	0.13902438513469	0.00270731723867357	6.5532545
0.600000023841858	313.978820800781	0.478399335406721	0.175609762663953	0.00343902455642819	7.8750645
0.699999988079071	366.070343017578	0.561940367333591	0.212195125641301	0.00417073164135218	9.181599
0.800000011920929	418.50537109375	0.645250605884939	0.252439029281959	0.00497560948133469	10.496749
0.899999976158142	465.570617675781	0.728330109268427	0.289024377707392	0.00570731703191996	11.677216
1	515.839172363281	0.811409554444253	0.325609755236655	0.00651219487190247	12.938028
1.10000002384186	566.967590332031	0.894489057827741	0.362195132765919	0.00717073166742921	14.220406
1.20000004768372	613.843872070313	0.977568561211228	0.391463428968564	0.00775609724223614	15.396134
1.29999995231628	661.95458984375	1.06087874155492	0.428048777393997	0.00848780479282141	16.602824
1.39999997615814	707.820739746094	1.14395830314606	0.457317073596641	0.00914634112268686	17.753216
1.5	758.073181152344	1.22726848348975	0.493902422022074	0.00980487838387489	19.013624
1.60000002384186	803.641235351563	1.3103480450809	0.526829273439944	0.0104634147137403	20.15654
1.70000004768372	848.463439941406	1.39342749025673	0.559756124857813	0.0111219510436058	21.280748
1.79999995231628	891.762084960938	1.47673778701574	0.596341444179416	0.0119268288835883	22.366744
1.89999997615814	934.952941894531	1.56004796735942	0.632926821708679	0.0125853661447763	23.450036
2	978.748596191406	1.64335826411843	0.669512199237943	0.0132439024746418	24.548498
2.09999990463257	1017.44561767578	1.7268992960453	0.702439050655812	0.0139756090939045	25.519078
2.20000004768372	1060.41906738281	1.81020959280431	0.739024369977415	0.0147804878652096	26.596916
2.29999995231628	1096.62133789063	1.893519773148	0.775609747506678	0.015439024195075	27.504924
2.40000009536743	1136.11535644531	1.97706092149019	0.812195125035942	0.0161707326769829	28.495494
2.5	1175.568359375	2.06060195341706	0.845121976453811	0.0168292671442032	29.485036
2.59999990463257	1216.06982421875	2.14391201734543	0.878048769664019	0.017560975626111	30.500874
2.70000004768372	1249.83166503906	2.2274530492723	0.910975621081889	0.0182195119559765	31.347672
2.79999995231628	1288.15014648438	2.31099408119917	0.947560998611152	0.0188780482858419	32.308758
2.90000009536743	1320.98620605469	2.39430437795818	0.980487791821361	0.0196097567677498	33.132336
3	1356.00415039063	2.47761467471719	1.02073175366968	0.0203414633870125	34.01064
3.09999990463257	1386.14416503906	2.56115570664406	1.05731713119894	0.0210731700062752	34.766596
3.20000004768372	1419.82580566406	2.64446600340307	1.09390239231288	0.021804878488183	35.611384
3.29999995231628	1447.52795410156	2.72777630016208	1.12682930193841	0.0225365869700909	36.306192
3.40000009536743	1478.27355957031	2.81108659692109	1.16707314737141	0.0233414620161057	37.07734
3.5	1503.09399414063	2.89439666084945	1.21097557712346	0.0241463426500559	37.699876
3.59999990463257	1528.34594726563	2.9774762224406	1.24756095465273	0.0248048789799213	38.333232
3.70000004768372	1555.68103027344	3.06078651919961	1.28780491650105	0.0256829261779785	39.018836
3.79999995231628	1580.51977539063	3.14409681595862	1.32804876193404	0.0264878049492836	39.641832
3.90000009536743	1603.49328613281	3.22717614471912	1.36829272378236	0.0272926837205887	40.21804
4	1624.41809082031	3.31025570631027	1.41219515353441	0.0281707309186459	40.742868
4.09999990463257	1645.90966796875	3.39333526790142	1.45243899896741	0.0289024394005537	41.281908
4.19999980926514	1661.82824707031	3.47664533182979	1.48902437649667	0.0297073181718588	41.681168
4.30000019073486	1681.65087890625	3.55972489342093	1.53658539056778	0.0306585356593132	42.178352
4.40000009536743	1696.36291503906	3.64280445501208	1.57682923600078	0.0313902422785759	42.547352
4.5	1713.74194335938	3.72611475177109	1.61707319784909	0.0322682932019234	42.983244
4.59999990463257	1729.85290527344	3.80942481569946	1.66097562760115	0.0332195125520229	43.387332
4.69999980926514	1741.80407714844	3.89250437729061	1.71219510957599	0.0340975597500801	43.687084
4.80000019073486	1754.37048339844	3.97581467404962	1.75975612364709	0.03504878282547	44.002268
4.90000009536743	1766.65295410156	4.05935570597649	1.80365855339915	0.0359268300235271	44.310332
5	1777.81567382813	4.14266576990485	1.8475609831512	0.0369512215256691	44.590312
5.09999990463257	1790.83044433594	4.2259762994945	1.8951219972223	0.0377560965716839	44.91674
5.19999980926514	1799.92126464844	4.30951733142138	1.94268289487809	0.0387804880738258	45.144752
5.30000019073486	1810.38317871094	4.39282739534974	1.99024379253387	0.0396585389971733	45.407152
5.40000009536743	1818.7138671875	4.47613792493939	2.03780480660498	0.040682926774025	45.6161
5.5	1828.5712890625	4.55967895686626	2.08902428857982	0.0417073145508766	45.86334
5.59999990463257	1838.73864746094	4.64298902079463	2.13658530265093	0.0426585376262665	46.118352
5.69999980926514	1844.7998046875	4.7265300527215	2.1804878488183	0.043536588549614	46.270372
5.80000019073486	1848.64990234375	4.81007108464837	2.22804886288941	0.0444878041744232	46.36694
5.90000009536743	1860.33605957031	4.89338114857674	2.27926834486425	0.0455121919512749	46.660048
6	1863.49670410156	4.97669167816639	2.33048782683909	0.0465365871787071	46.73932
6.09999990463257	1871.35559082031	5.06000174209476	2.38170730881393	0.0475609749555588	46.936432
6.19999980926514	1874.55249023438	5.14331227168441	2.43292679078877	0.0485853664577007	47.016616
6.30000019073486	1885.45886230469	5.22662233561277	2.48780497349799	0.0496097579598427	47.290164
6.40000009536743	1890.09057617188	5.30993239954114	2.53170728683472	0.0505609773099422	47.406336
6.5	1894.19750976563	5.39301196113229	2.57926830090582	0.0514390245079994	47.509344
6.59999990463257	1901.15148925781	5.47609152272344	2.62682931497693	0.052390243858099	47.68376
6.69999980926514	1906.76611328125	5.55917108431458	2.6817072648555	0.0535609759390354	47.824584
6.80000019073486	1911.30847167969	5.64248114824295	2.73658544756472	0.0545853674411774	47.938512
6.90000009536743	1915.611328125	5.7255607098341	2.78780492953956	0.0556829236447811	48.046436
7	1919.62744140625	5.80864027142525	2.8390244115144	0.0566341429948807	48.147164
7.09999990463257	1925.27392578125	5.8917198330164	2.88658542558551	0.0576585344970226	48.288788
7.19999980926514	1929.67700195313	5.97479939460754	2.93414643965662	0.0585365854203701	48.399224
7.30000019073486	1932.16430664063	6.05787849053741	2.98902438953519	0.0597073175013065	48.461608
7.40000009536743	1934.91882324219	6.14118902012706	3.04024387151003	0.0606585368514061	48.530696
7.5	1941.45202636719	6.22449908405542	3.09512205421925	0.0617560967803001	48.694556
7.59999990463257	1944.13879394531	6.30757864564657	3.14634153619409	0.0628536567091942	48.761948
7.69999980926514	1948.56518554688	6.39065820723772	3.19756101816893	0.0638780519366264	48.872968
7.80000019073486	1951.24133300781	6.47396827116609	3.24878050014377	0.0649024397134781	48.940088
7.90000009536743	1954.77282714844	6.55727880075574	3.29999998211861	0.0659268274903297	49.028664
8	1955.23291015625	6.6405888646841	3.35121946409345	0.066951222717762	49.040204
8.10000038146973	1961.11950683594	6.72389939427376	3.40609764680266	0.0679024383425713	49.187848
8.19999980926514	1961.78039550781	6.80697849020362	3.46097559668124	0.0690731704235077	49.204424
8.30000019073486	1966.43579101563	6.89028901979327	3.51219507865608	0.0701707303524017	49.321188
8.39999961853027	1967.72290039063	6.97383005172014	3.56341456063092	0.071195125579834	49.353472
8.5	1972.77294921875	7.05714011564851	3.61463404260576	0.0721463412046433	49.480136
8.60000038146973	1971.13439941406	7.14045064523816	3.66585375741124	0.0732439011335373	49.439036
8.69999980926514	1973.06384277344	7.22376070916653	3.72073170728981	0.0743414610624313	49.487432
8.80000019073486	1977.10583496094	7.30707077309489	3.77560965716839	0.0754390209913254	49.588808
8.89999961853027	1984.40844726563	7.39038130268455	3.83048783987761	0.0764634162187576	49.771972
9	1983.08190917969	7.47369136661291	3.89268295839429	0.0777073130011559	49.7387
9.10000038146973	1985.44519042969	7.55700189620256	3.94390244036913	0.0787317082285881	49.797972
9.19999980926514	1985.92260742188	7.64031196013093	3.99878062307835	0.0799024403095245	49.809948
9.30000019073486	1987.4921875	7.72362248972058	4.05000010505319	0.0809268280863762	49.849316
9.39999961853027	1990.72937011719	7.80693255364895	4.10487782210112	0.0820243954658508	49.930508
9.5	1991.62060546875	7.8900121152401	4.16341470554471	0.0831219553947449	49.95286
9.60000038146973	1989.90173339844	7.97332264482975	4.21829288825393	0.0842195078730583	49.909752
9.69999980926514	1991.25866699219	8.05640127509832	4.27682930603623	0.085317075252533	49.943784
9.80000019073486	1993.50048828125	8.13971180468798	4.33170748874545	0.0865609794855118	50.000012
9.89999961853027	1994.89636230469	8.22302233427763	4.38658520579338	0.0875853672623634	50.035024
10	1993.97485351563	8.30610189586878	4.4414633885026	0.0887560918927193	50.011912
10.1000003814697	1997.10205078125	8.38941242545843	4.49634157121181	0.0898536592721939	50.090344
10.1999998092651	1999.73986816406	8.47249105572701	4.55487798899412	0.090951219201088	50.156504
10.3000001907349	1998.5205078125	8.55580158531666	4.61341440677643	0.0921951234340668	50.12592
10.3999996185303	2000.65197753906	8.63934308290482	4.66829258948565	0.0932195112109184	50.179384
10.5	1997.04956054688	8.72265268117189	4.73048770800233	0.0944634154438972	50.089028
10.6000003814697	2001.63391113281	8.80596321076155	4.78902459144592	0.0956341475248337	50.204012
10.6999998092651	1999.83630371094	8.8892737403512	4.84756100922823	0.0968780443072319	50.158924
10.8000001907349	2000.78112792969	8.97258333861828	4.90975612774491	0.0980487838387489	50.18262
10.8999996185303	1998.89892578125	9.05589386820793	4.96829254552722	0.0992926880717278	50.135412
11	1998.84313964844	9.13966540247202	5.02682942897081	0.100390240550041	50.134016
11.1000003814697	2000.57629394531	9.22320690006018	5.08170714601874	0.101487800478935	50.177484
11.1999998092651	1999.8798828125	9.30628646165133	5.14390226453543	0.102731704711914	50.160016
11.3000001907349	2000.7119140625	9.38982702791691	5.20609738305211	0.103975608944893	50.180884
11.3999996185303	1996.8076171875	9.47336852550507	5.26829250156879	0.105219513177872	50.08296
11.5	1997.85534667969	9.55667905509472	5.33414632081985	0.106536589562893	50.10924
11.5900001525879	3.9762556552887	9.63191129267216	5.51707297563553	0.10836585611105	0.099730515625