File: Tensile_tests/PA12_C6_XZ_1 08-30-22 13 49 14 PM/DAQ- Time, … - (Timed).txt
File Path: C:\MTS TestSuite\Data Files\Chahine\DOE\PA12_C6_XZ_1 08-30-22 13 49 14 PM\DAQ- Time, … - (Timed).txt
Test: MTS EM Tension (Extensometer)_Grand_Chahine 1
Test Run: PA12_C6_XZ_1
Date: 8/30/2022 1:48:44 PM


Time 	Load 	Crosshead 	Extensometer 	Strain 	Stress
sec	N	mm	mm	mm/mm	N/mm²
0.0999999716877937	42.7147102355957	0.061848055338487	0.0146341462823329	0.000292682932922617	1.068594375
0.199999943375587	94.1091537475586	0.144696765346453	0.04756097405334	0.00102439022157341	2.35432975
0.299999892711639	147.270736694336	0.228468561545014	0.0731707332306542	0.00139024388045073	3.68427375
0.399999886751175	200.26806640625	0.312009593471885	0.102439022157341	0.0019756096880883	5.0101085
0.500000178813934	251.108963012695	0.395319861127064	0.128048777696677	0.00248780474066734	6.281996
0.600000143051147	299.204040527344	0.478860893053934	0.153658533236012	0.00300000002607703	7.485191
0.700000107288361	352.362731933594	0.562171160709113	0.179268288775347	0.00351219531148672	8.815063
0.800000071525574	397.810882568359	0.645250605884939	0.219512192416005	0.0042439023964107	9.952039
0.900000035762787	445.873352050781	0.728560902643949	0.263414636719972	0.00526829250156879	11.154419
1	493.870300292969	0.811640347819775	0.314634147798643	0.00629268307238817	12.355159
1.10000002384186	540.629028320313	0.894950586371124	0.365853658877313	0.00717073166742921	13.524923
1.19999992847443	585.184814453125	0.978260883130133	0.402439036406577	0.00797560997307301	14.639575
1.29999995231628	632.052429199219	1.061801915057	0.43902438483201	0.00870731752365828	15.812063
1.39999985694885	672.794860839844	1.14511221181601	0.475609762361273	0.00943902414292097	16.831316
1.50000011920929	719.559814453125	1.22865324374288	0.512195110786706	0.0101707316935062	18.001236
1.60000014305115	763.197692871094	1.31219427566975	0.541463436093181	0.0107560968026519	19.092926
1.70000004768372	803.756530761719	1.39550445601344	0.57439022930339	0.0114146340638399	20.107586
1.80000007152557	847.932861328125	1.47904548794031	0.607317080721259	0.0120731713250279	21.212746
1.89999997615814	885.301452636719	1.56258651986718	0.640243873931468	0.0127317067235708	22.147596
2	930.633117675781	1.64589681662619	0.665853673126549	0.0133170736953616	23.28166
2.09999990463257	967.126403808594	1.72920699696988	0.702439050655812	0.0139756090939045	24.194612
2.20000004768372	1003.5439453125	1.81274802889675	0.739024369977415	0.0147073166444898	25.10567
2.29999995231628	1044.88513183594	1.8958275904879	0.775609747506678	0.015439024195075	26.139904
2.39999985694885	1077.38647460938	1.97913777083158	0.812195125035942	0.0161707326769829	26.95299
2.50000023841858	1111.005859375	2.06267880275846	0.852439028676599	0.0169756095856428	27.794046
2.60000014305115	1146.56213378906	2.1457583643496	0.889024406205863	0.0177073180675507	28.683558
2.70000004768372	1181.80456542969	2.22906866110861	0.925609783735126	0.0184390246868134	29.565218
2.79999995231628	1213.9697265625	2.31237895786762	0.962195103056729	0.0190975610166788	30.369894
2.90000009536743	1243.20593261719	2.39545828662813	0.995121896266937	0.0199024379253387	31.101298
3	1274.75476074219	2.47853784821928	1.0317072737962	0.0205609761178494	31.890554
3.09999990463257	1301.787109375	2.56161717697978	1.07195123564452	0.0213658530265093	32.566824
3.20000004768372	1331.69543457031	2.64469673857093	1.11585366539657	0.0222439020872116	33.31504
3.29999995231628	1357.86328125	2.72777630016208	1.15609751082957	0.0229756087064743	33.96968
3.39999985694885	1381.91259765625	2.81108659692109	1.19634147267789	0.0238536577671766	34.571324
3.50000023841858	1405.71557617188	2.89416592568159	1.23292685020715	0.0245853662490845	35.166804
3.60000014305115	1427.41625976563	2.97724548727274	1.28048774786294	0.0254634134471416	35.709688
3.70000004768372	1447.20654296875	3.06055578403175	1.3170731253922	0.0261951219290495	36.204784
3.79999995231628	1469.8740234375	3.14363511279225	1.35731708724052	0.0270731709897518	36.771856
3.90000009536743	1489.34033203125	3.22717614471912	1.39756093267351	0.0278780497610569	37.258844
4	1504.81945800781	3.31048644147813	1.43780489452183	0.0286829266697168	37.646084
4.09999990463257	1522.61743164063	3.39379673823714	1.48902437649667	0.0297073181718588	38.091336
4.19999980926514	1541.15869140625	3.47733777016401	1.53292680624872	0.0306585356593132	38.555184
4.29999971389771	1557.1171875	3.56087880209088	1.57317076809704	0.0313902422785759	38.95442
4.40000009536743	1571.99291992188	3.64395836368203	1.60975614562631	0.0320487804710865	39.326564
4.5	1583.04846191406	3.7274993956089	1.6499999910593	0.032926831394434	39.60314
4.59999990463257	1595.8759765625	3.81104042753577	1.70121947303414	0.0339512191712856	39.924048
4.70000028610229	1611.47668457031	3.89435049146414	1.75243907142431	0.0349756106734276	40.314332
4.80000019073486	1618.70690917969	3.97789152339101	1.80365855339915	0.0359268300235271	40.495208
4.90000009536743	1631.05395507813	4.06166352331638	1.85121956747025	0.0369512215256691	40.804096
5	1639.81469726563	4.14474308490753	1.89878046512604	0.0379024408757687	41.023264
5.09999990463257	1649.72485351563	4.2280531488359	1.94999994710088	0.0387804880738258	41.271184
5.19999980926514	1658.40954589844	4.31159418076277	1.99390249326825	0.0398048758506775	41.488452
5.29999971389771	1667.41162109375	4.39467374235392	2.03048787079751	0.0405365824699402	41.713656
5.40000009536743	1675.75158691406	4.47821477428079	2.06707324832678	0.0413414649665356	41.922296
5.5	1684.18334960938	4.56129433587193	2.12560966610909	0.0424390248954296	42.133236
5.59999990463257	1692.24243164063	4.6446043998003	2.17317068018019	0.0433902442455292	42.334848
5.70000028610229	1700.31237792969	4.72768396139145	2.21707322634757	0.0442682914435863	42.536736
5.80000019073486	1706.52465820313	4.8107635229826	2.26463424041867	0.0451463423669338	42.692148
5.90000009536743	1712.04907226563	4.89384308457375	2.31219502165914	0.0461707301437855	42.830352
6	1718.49267578125	4.97715314850211	2.36341473646462	0.0471951216459274	42.991552
6.09999990463257	1727.17578125	5.06023271009326	2.40731704980135	0.0480731725692749	43.208776
6.19999980926514	1732.47082519531	5.1430813036859	2.4658537004143	0.0492439046502113	43.341244
6.29999971389771	1735.001953125	5.22639136761427	2.52073165029287	0.0503414645791054	43.404564
6.40000009536743	1743.73681640625	5.30970189720392	2.56829266436398	0.0512926839292049	43.623084
6.5	1748.615234375	5.39278145879507	2.62682931497693	0.0524634160101414	43.745128
6.59999990463257	1752.94970703125	5.47586102038622	2.67804879695177	0.0534878075122833	43.853564
6.70000028610229	1758.74096679688	5.55917108431458	2.73292674683034	0.054512195289135	43.998444
6.80000019073486	1763.70690917969	5.64225064590573	2.78048776090145	0.0555365867912769	44.122676
6.90000009536743	1771.9873046875	5.7255607098341	2.83170724287629	0.0564878061413765	44.329828
7	1773.97399902344	5.80887123942375	2.87195132113993	0.0574390254914761	44.379528
7.09999990463257	1778.52661132813	5.89218130335212	2.93780490756035	0.0586829297244549	44.49342
7.19999980926514	1782.81335449219	5.97549136728048	2.98536592163146	0.0596341453492641	44.600664
7.29999971389771	1782.837890625	6.05880189687014	3.02926823496819	0.0604390278458595	44.601276
7.40000009536743	1791.61169433594	6.1421119607985	3.07317078113556	0.0613170713186264	44.820772
7.5	1791.47937011719	6.22542249038816	3.13170743174851	0.0624878033995628	44.81746
7.59999990463257	1793.732421875	6.30896352231503	3.18292691372335	0.0635853633284569	44.873824
7.70000028610229	1798.69116210938	6.39227358624339	3.23780486360192	0.0646097511053085	44.997876
7.80000019073486	1803.57995605469	6.47558365017176	3.29268304631114	0.0657804906368256	45.12018
7.90000009536743	1804.54870605469	6.55866321176291	3.34390252828598	0.0668048784136772	45.144416
8	1809.1162109375	6.64220424368978	3.39512201026082	0.0678292661905289	45.25868
8.10000038146973	1813.85400390625	6.72551477327943	3.44634149223566	0.0687804892659187	45.377208
8.19999980926514	1815.568359375	6.80882483720779	3.50853661075234	0.070024386048317	45.420096
8.30000019073486	1816.77453613281	6.89213536679745	3.56341456063092	0.071195125579834	45.450268
8.39999961853027	1820.05383300781	6.97544543072581	3.61097557470202	0.0721463412046433	45.532308
8.5	1823.67602539063	7.05875549465418	3.66219505667686	0.0731707289814949	45.622924
8.60000038146973	1825.60217285156	7.14183505624533	3.7134145386517	0.0741951242089272	45.671112
8.69999980926514	1829.927734375	7.22514558583498	3.76463425345719	0.0752195119857788	45.779324
8.80000019073486	1831.44763183594	7.30822468176484	3.8231706712395	0.0763170719146729	45.817348
8.89999961853027	1830.45288085938	7.39153521135449	3.87439015321434	0.0773414671421051	45.79246
9	1836.33911132813	7.47484527528286	3.92560986801982	0.0784390270709991	45.939716
9.10000038146973	1833.89038085938	7.55792483687401	3.98048758506775	0.0794634148478508	45.878456
9.19999980926514	1839.4375	7.64123490080237	4.03536576777697	0.0805609747767448	46.017228
9.30000019073486	1841.50512695313	7.72431446239352	4.08658524975181	0.0816585421562195	46.068956
9.39999961853027	1842.82885742188	7.80762499198318	4.13780473172665	0.0826829299330711	46.102072
9.5	1847.12719726563	7.89116602391005	4.18902421370149	0.0837073177099228	46.209604
9.60000038146973	1844.54919433594	7.97470659017563	4.24756109714508	0.0848048776388168	46.145108
9.69999980926514	1847.3603515625	8.05778615176678	4.30243881419301	0.0859756097197533	46.215436
9.80000019073486	1845.73657226563	8.14086571335793	4.35731699690223	0.0870731770992279	46.174812
9.89999961853027	1848.56384277344	8.22463724762201	4.41585388034582	0.0882439017295837	46.245544
10	1851.802734375	8.30794777721167	4.47073159739375	0.0893414691090584	46.326572
10.1000003814697	1850.91809082031	8.39148927479982	4.52926848083735	0.0904390215873718	46.30444
10.1999998092651	1851.7509765625	8.47502984106541	4.58780489861965	0.0916097611188889	46.325276
10.3000001907349	1853.58813476563	8.55810940265656	4.64634131640196	0.0928536653518677	46.371236
10.3999996185303	1854.13757324219	8.64165090024471	4.70121949911118	0.0938780531287193	46.38498
10.5	1856.97338867188	8.7251914665103	4.75609768182039	0.0950487777590752	46.455924
10.6000003814697	1856.94738769531	8.80850199609995	4.80731716379523	0.0960731655359268	46.455276
10.6999998092651	1859.90490722656	8.89204256236553	4.86585358157754	0.0972439050674438	46.529264
10.8000001907349	1859.6416015625	8.97535309195518	4.92439046502113	0.0984146371483803	46.522676
10.8999996185303	1858.46655273438	9.05866362154484	4.98658558353782	0.0995853617787361	46.49328
11	1860.0634765625	9.14197321981192	5.03780506551266	0.100609749555588	46.533228
11.1000003814697	1858.84204101563	9.22551471740007	5.0890245474875	0.10163414478302	46.502672
11.1999998092651	1858.87414550781	9.30859427899122	5.15121966600418	0.102878049015999	46.503476
11.3000001907349	1859.86193847656	9.39190480858088	5.21341478452086	0.104121945798397	46.528188
11.3999996185303	1859.98449707031	9.47521440684795	5.27195120230317	0.105292685329914	46.531252
11.5	1859.70483398438	9.5582939684391	5.32682938501239	0.106463417410851	46.524256
11.6000003814697	1861.44946289063	9.64160449802876	5.38902450352907	0.107707314193249	46.567904
11.6999998092651	1860.69299316406	9.72514506429434	5.45121962204576	0.108878046274185	46.54898
11.8000001907349	1862.52526855469	9.80845559388399	5.5024391040206	0.109902441501617	46.594816
11.8999996185303	1862.25256347656	9.89176612347364	5.5609755218029	0.111073173582554	46.587992
12	1862.71508789063	9.97507572174072	5.6195124052465	0.112317070364952	46.599564
12.1000003814697	1864.02526855469	10.0581552833319	5.68170752376318	0.113487802445889	46.63234
12.1999998092651	1861.13806152344	10.1414658129215	5.74024394154549	0.114731706678867	46.560112
12.3000001907349	1861.70544433594	10.2250073105097	5.80243906006217	0.115902438759804	46.574308
12.3999996185303	1861.5146484375	10.3083169087768	5.86463417857885	0.117219507694244	46.569532
12.5	1862.23767089844	10.3918584063649	5.92682929709554	0.118463411927223	46.58762
12.6000003814697	1863.68139648438	10.475168004632	5.98902441561222	0.11963415145874	46.62374
12.6999998092651	1862.07421875	10.5584785342216	6.0512195341289	0.120878055691719	46.583532
12.8000001907349	1862.57568359375	10.6420200318098	6.11341465264559	0.122121952474117	46.596076
12.8999996185303	1864.27819824219	10.7255605980754	6.17195107042789	0.123292684555054	46.638668
13	1859.19702148438	10.8086401596665	6.23414618894458	0.124536588788033	46.511552
13.1000003814697	1863.07409667969	10.8921816572547	6.29634130746126	0.125780493021011	46.608548
13.1999998092651	1859.27185058594	10.9757222235203	6.35487819090486	0.127097561955452	46.513424
13.3000001907349	1861.626953125	11.0588017851114	6.42073154449463	0.128268286585808	46.572344
13.3999996185303	1858.20288085938	11.1423432826996	6.48292666301131	0.129512190818787	46.486684
13.5	1858.80908203125	11.2258838489652	6.545121781528	0.130756095051765	46.501848
13.6000003814697	1857.64855957031	11.3091943785548	6.61463430151343	0.132146343588829	46.472816
13.6999998092651	1857.47717285156	11.3927349448204	6.68048765510321	0.13346341252327	46.468528
13.8000001907349	1856.53918457031	11.4760454744101	6.74268277361989	0.134707316756248	46.445064
13.8999996185303	1856.52514648438	11.5591250360012	6.80853659287095	0.136097550392151	46.444712
14	1853.11987304688	11.6424355655909	6.87073171138763	0.13734145462513	46.35952
14.1000003814697	1854.86401367188	11.7257451638579	6.93658553063869	0.138658538460732	46.403156
14.1999998092651	1854.23132324219	11.8088247254491	7.00243888422847	0.13990244269371	46.387328
14.3000001907349	1854.00219726563	11.8923662230372	7.07195140421391	0.141292676329613	46.381596
14.3999996185303	1852.65441894531	11.9754457846284	7.13780475780368	0.142609760165215	46.347876
14.5	1851.82641601563	12.058524414897	7.20731727778912	0.14407317340374	46.327164
14.6000003814697	1850.78833007813	12.1418349444866	7.27682933211327	0.145317077636719	46.301192
14.6999998092651	1848.80981445313	12.2251454740763	7.33902445062995	0.146707311272621	46.251696
14.8000001907349	1848.32507324219	12.3086860403419	7.39756086841226	0.147878050804138	46.239568
14.8999996185303	1848.31481933594	12.3919965699315	7.46707338839769	0.149195119738579	46.239312
15	1843.42883300781	12.4753070995212	7.52926850691438	0.150439023971558	46.11708
15.1000003814697	1841.32275390625	12.5586176291108	7.6024392619729	0.151829272508621	46.064392
15.1999998092651	1842.50439453125	12.6421581953764	7.66463438048959	0.153146341443062	46.093952
15.3000001907349	1839.93188476563	12.725468724966	7.73414643481374	0.154609754681587	46.029596
15.3999996185303	1837.36462402344	12.8085482865572	7.80731718987226	0.156073167920113	45.965372
15.5	1837.25122070313	12.8920888528228	7.88780488073826	0.1576097458601	45.962536
15.6000003814697	1833.1025390625	12.9753993824124	7.95731693506241	0.159000009298325	45.858748
15.6999998092651	1829.99096679688	13.0587099120021	8.03048815578222	0.16046342253685	45.780904
15.8000001907349	1825.70703125	13.1420195102692	8.11097584664822	0.162000000476837	45.673732
15.8999996185303	1816.86120605469	13.2253300398588	8.18780530244112	0.163536593317986	45.452436
16	1808.59729003906	13.3086405694485	8.26829299330711	0.165219515562058	45.2457
16.1000003814697	1797.63305664063	13.3919501677155	8.35975632071495	0.167048782110214	44.971408
16.2000007629395	132.698135375977	13.4752606973052	8.45487788319588	0.168878048658371	3.31971075
16.2199993133545	13.0956192016602	13.4918764233589	8.70365835726261	0.170560985803604	0.32761325