File: Tensile_tests/PA12_C7_XY_8 09-13-22 10 18 59 AM/DAQ- Time, … - (Timed).txt
File Path: C:\MTS TestSuite\Data Files\Chahine\DOE\PA12_C7_XY_8 09-13-22 10 18 59 AM\DAQ- Time, … - (Timed).txt
Test: MTS EM Tension (Extensometer)_Grand_Chahine 1
Test Run: PA12_C7_XY_8
Date: 9/13/2022 10:18:28 AM


Time 	Load 	Crosshead 	Extensometer 	Strain 	Stress
sec	N	mm	mm	mm/mm	N/mm²
0.109999902546406	47.2489814758301	0.0715406640665606	0.0146341462823329	0.000292682932922617	1.1235045
0.2099998742342	102.444236755371	0.153697037603706	0.04756097405334	0.00087804882787168	2.4359585
0.309999853372574	156.502136230469	0.23769962717779	0.0804878072813153	0.00153658539056778	3.721368
0.410000115633011	208.530853271484	0.321009865729138	0.109756096208002	0.00212195119820535	4.958527
0.510000109672546	258.019805908203	0.404781691031531	0.13902438513469	0.00278048776090145	6.1352945
0.61000007390976	313.241790771484	0.488091929582879	0.179268288775347	0.0035853658337146	7.448384
0.710000038146973	356.145782470703	0.571402197238058	0.219512192416005	0.00431707315146923	8.468572
0.810000002384186	403.218444824219	0.654712435789406	0.248780474066734	0.00490243919193745	9.587884
0.909999966621399	451.443115234375	0.737791939172894	0.285365851595998	0.00570731703191996	10.734588
1.00999999046326	499.520629882813	0.82087138434872	0.332926836563274	0.00651219487190247	11.877794
1.10999989509583	544.345336914063	0.903950887732208	0.369512184988707	0.00724390242248774	12.943653
1.20999991893768	590.954650878906	0.987030332908034	0.402439036406577	0.00797560997307301	14.051947
1.30999982357025	636.982971191406	1.07010989449918	0.446341466158628	0.00885365903377533	15.146427
1.41000008583069	678.969360351563	1.15342007484287	0.475609762361273	0.00951219536364079	16.144795
1.51000010967255	722.360717773438	1.23649963643402	0.512195110786706	0.0102439019829035	17.176572
1.61000001430511	762.789733886719	1.31957908160985	0.556097540538758	0.0110487807542086	18.137908
1.71000003814697	804.940734863281	1.40288926195353	0.589024391956627	0.0116341467946768	19.140192
1.80999994277954	842.816345214844	1.48596882354468	0.621951243374497	0.0123658534139395	20.040812
1.9099999666214	883.641723632813	1.56927900388837	0.662195147015154	0.0132439024746418	21.011574
2.00999999046326	919.742858886719	1.65258930064738	0.702439050655812	0.0139024388045073	21.87
2.10999989509583	959.880249023438	1.73589959740639	0.73536584386602	0.0146341463550925	22.824402
2.20999979972839	994.944458007813	1.81944062933326	0.771951221395284	0.015439024195075	23.658172
2.30999994277954	1031.9716796875	1.90298166126013	0.812195125035942	0.0161707326769829	24.53862
2.41000008583069	1065.4609375	1.98629195801914	0.845121976453811	0.0167560968548059	25.33494
2.50999999046326	1099.2607421875	2.06960225477815	0.881707295775414	0.0174878053367138	26.138646
2.6100001335144	1132.30090332031	2.15314328670502	0.925609783735126	0.0184390246868134	26.924288
2.71000003814697	1164.50207519531	2.23645335063338	0.958536576945335	0.0190975610166788	27.68998
2.80999994277954	1195.70080566406	2.31976364739239	1.00243906490505	0.0199756100773811	28.431834
2.90999984741211	1226.66442871094	2.40353541448712	1.03536585811526	0.0207073166966438	29.1681
3.00999999046326	1255.07641601563	2.48661497607827	1.07195123564452	0.0213658530265093	29.84369
3.10999989509583	1284.24426269531	2.56992527283728	1.10487802885473	0.0220243912190199	30.537256
3.20999979972839	1309.03686523438	2.65346630476415	1.14878045860678	0.0229024402797222	31.126784
3.30999994277954	1332.78967285156	2.73654563352466	1.18536583613604	0.0235609747469425	31.691586
3.41000008583069	1358.48193359375	2.81985593028367	1.22195121366531	0.0242926832288504	32.302508
3.50999999046326	1382.177734375	2.90339696221054	1.26219517551363	0.0251707322895527	32.865954
3.6100001335144	1402.04663085938	2.98647652380168	1.30243902094662	0.0259756091982126	33.338406
3.71000003814697	1421.15063476563	3.06932511739433	1.33902439847589	0.0266341473907232	33.792668
3.80999994277954	1444.73645019531	3.15263541415334	1.37926824390888	0.0275121964514256	34.3535
3.90999984741211	1462.7685546875	3.23571497574449	1.4195122057572	0.0283170714974403	34.782276
4.00999975204468	1483.79370117188	3.31879453733563	1.4597560511902	0.0290487799793482	35.28222
4.1100001335144	1501.87109375	3.40187386609614	1.49634142871946	0.0298536587506533	35.712068
4.21000003814697	1519.45007324219	3.48495342768729	1.54024385847151	0.0307317078113556	36.130068
4.30999994277954	1532.88720703125	3.56780202127993	1.58414628822356	0.0316097550094128	36.449584
4.41000032424927	1547.81555175781	3.65111231803894	1.62804883439094	0.0324878059327602	36.804556
4.51000022888184	1564.84631347656	3.73419187963009	1.67195126414299	0.0333658531308174	37.20952
4.6100001335144	1579.76794433594	3.8175021763891	1.71951216179878	0.034317072480917	37.564332
4.71000003814697	1593.86010742188	3.90081224031746	1.75975612364709	0.0351219512522221	37.89942
4.80999994277954	1608.20568847656	3.98389203473926	1.81097560562193	0.0361463390290737	38.240536
4.90999984741211	1617.76452636719	4.06697113066912	1.85121956747025	0.0368780493736267	38.467828
5.00999975204468	1633.29968261719	4.15051216259599	1.89146341290325	0.0376829281449318	38.837228
5.1100001335144	1644.77624511719	4.23382269218564	1.93902442697436	0.0387073159217834	39.110124
5.21000003814697	1654.55627441406	4.31713275611401	1.97926838882267	0.0395121946930885	39.342676
5.30999994277954	1666.58325195313	4.40044328570366	2.0231707021594	0.040390245616436	39.62866
5.41000032424927	1679.84338378906	4.48352238163352	2.07073171623051	0.0413414649665356	39.943964
5.51000022888184	1688.71313476563	4.56683291122317	2.11463426239789	0.0422195121645927	40.154872
5.6100001335144	1698.12438964844	4.65037394315004	2.15853657573462	0.0430975630879402	40.378656
5.71000003814697	1706.91369628906	4.73345350474119	2.20975605770946	0.0440487824380398	40.587652
5.80999994277954	1718.30090332031	4.81676356866956	2.25365860387683	0.044926829636097	40.85842
5.90999984741211	1726.78369140625	4.90007363259792	2.29390244930983	0.0458048805594444	41.060128
6.00999975204468	1735.10766601563	4.98338416218758	2.34512193128467	0.0469024404883385	41.25806
6.1100001335144	1745.96264648438	5.06692519411445	2.39268294535577	0.0477073155343533	41.516172
6.21000003814697	1752.12072753906	5.15023525804281	2.43292679078877	0.0485121980309486	41.662604
6.30999994277954	1761.99060058594	5.23331481963396	2.48414627276361	0.0496097579598427	41.897292
6.41000032424927	1770.73046875	5.31662534922361	2.53536575473845	0.0505609773099422	42.105112
6.51000022888184	1779.21472167969	5.40016638115048	2.57926830090582	0.0514390245079994	42.306852
6.6100001335144	1788.32092285156	5.48301497474313	2.6231708470732	0.052390243858099	42.523384
6.71000003814697	1794.17822265625	5.56632503867149	2.67439032904804	0.0534146316349506	42.66266
6.80999994277954	1798.75219726563	5.64963556826115	2.71829264238477	0.0542926825582981	42.771424
6.90999984741211	1808.33020019531	5.73271466419101	2.76951212435961	0.0552439019083977	42.999172
7.00999975204468	1814.16735839844	5.81602519378066	2.81341467052698	0.0561951249837875	43.137972
7.1100001335144	1823.89465332031	5.89933525770903	2.85731698386371	0.0570731684565544	43.369272
7.21000003814697	1827.36450195313	5.98241481930017	2.90121953003109	0.0579512193799019	43.451776
7.30999994277954	1834.00952148438	6.06549438089132	2.95975618064404	0.0590487793087959	43.609784
7.41000032424927	1839.95739746094	6.14903541281819	3.0073169618845	0.0600000023841858	43.751216
7.51000022888184	1847.78198242188	6.23211497440934	3.05121950805187	0.0609512217342854	43.937272
7.6100001335144	1853.78894042969	6.31565600633621	3.09512205421925	0.0619024410843849	44.080108
7.71000003814697	1857.52746582031	6.39896607026458	3.15000000409782	0.0628536567091942	44.169004
7.80999994277954	1863.86804199219	6.48227659985423	3.19024384953082	0.0637317076325417	44.319772
7.90999984741211	1870.86767578125	6.5655866637826	3.24146333150566	0.0646829307079315	44.486212
8.01000022888184	1873.76708984375	6.64912769570947	3.29268304631114	0.0657804906368256	44.555156
8.10999965667725	1879.08154296875	6.73243775963783	3.34390252828598	0.0667317062616348	44.681524
8.21000003814697	1883.06994628906	6.8159787915647	3.39146330952644	0.0677560940384865	44.776364
8.30999946594238	1889.6171875	6.89951982349157	3.44268302433193	0.0687804892659187	44.932044
8.40999984741211	1890.98132324219	6.98259938508272	3.49024380557239	0.069731704890728	44.964484
8.51000022888184	1898.10766601563	7.06614041700959	3.54146352037787	0.0706829279661179	45.133936
8.60999965667725	1899.65795898438	7.14968144893646	3.58902430161834	0.0717073157429695	45.1708
8.71000003814697	1909.71655273438	7.23299197852612	3.64024401642382	0.0727317035198212	45.409976
8.8100004196167	1912.16528320313	7.31653301045299	3.69146349839866	0.0737560987472534	45.468204
8.90999984741211	1917.29138183594	7.39984307438135	3.7426829803735	0.0747804865241051	45.590092
9.01000022888184	1921.82397460938	7.4829226359725	3.79024399444461	0.0756585374474525	45.697872
9.10999965667725	1923.65954589844	7.56623269990087	3.83414630778134	0.0766097605228424	45.74152
9.21000003814697	1927.16687011719	7.64954322949052	3.88902449049056	0.0777073130011559	45.824916
9.30999946594238	1930.49035644531	7.73262232542038	3.93658550456166	0.0786585360765457	45.903944
9.40999984741211	1934.4208984375	7.81616382300854	3.99146322160959	0.0796829238533974	45.997404
9.51000022888184	1939.48303222656	7.89947342127562	4.03902446851134	0.080707311630249	46.117776
9.60999965667725	1940.42504882813	7.98278395086527	4.09390265122056	0.0818048790097237	46.140176
9.71000003814697	1942.91613769531	8.06632544845343	4.1451221331954	0.0827560946345329	46.199408
9.8100004196167	1946.05090332031	8.14940501004457	4.19999985024333	0.0838536620140076	46.273948
9.90999984741211	1948.6943359375	8.23271460831165	4.25487803295255	0.0850243866443634	46.336804
10.0100002288818	1953.81494140625	8.31625610589981	4.30243881419301	0.0859756097197533	46.458564
10.1099996566772	1956.59509277344	8.39933566749096	4.35731699690223	0.0869999974966049	46.524672
10.210000038147	1960.2373046875	8.48264526575804	4.41219517961144	0.0880975648760796	46.61128
10.3099994659424	1961.93322753906	8.5661867633462	4.46707336232066	0.089195117354393	46.651604
10.4099998474121	1964.76318359375	8.64949729293585	4.51463414356112	0.0902195125818253	46.718896
10.5100002288818	1966.15441894531	8.73280689120293	4.56951232627034	0.0913170725107193	46.751976
10.6099996566772	1968.50927734375	8.81634838879108	4.62439004331827	0.092341460287571	46.807972
10.710000038147	1970.44128417969	8.89988895505667	4.67195129022002	0.0933658480644226	46.853912
10.8100004196167	1973.06408691406	8.98319948464632	4.72317077219486	0.0944634154438972	46.91628
10.9099998474121	1975.1552734375	9.0667400509119	4.78536589071155	0.0955609828233719	46.966004
11.0100002288818	1975.826171875	9.15005058050156	4.83292667195201	0.0965853706002235	46.981956
11.1099996566772	1977.80810546875	9.23336111009121	4.88414615392685	0.0975365862250328	47.029084
11.210000038147	1982.25988769531	9.3171326443553	4.94268303737044	0.098780483007431	47.13494
11.3099994659424	1981.03527832031	9.40044317394495	4.99390251934528	0.0998048782348633	47.10582
11.4099998474121	1985.04162597656	9.4837537035346	5.05243893712759	0.10097561776638	47.201084
11.5100002288818	1984.12768554688	9.56729426980019	5.10731711983681	0.102073170244694	47.179352
11.6099996566772	1986.130859375	9.65060479938984	5.16585353761911	0.103170730173588	47.226984
11.710000038147	1984.95703125	9.73391532897949	5.22073172032833	0.104268297553062	47.199072
11.8100004196167	1987.66723632813	9.81722492724657	5.28292683884501	0.105512201786041	47.263516
11.9099998474121	1989.83544921875	9.90053545683622	5.34146325662732	0.106682926416397	47.315076
12.0100002288818	1990.69287109375	9.98361501842737	5.40000014007092	0.107926830649376	47.335464
12.1099996566772	1993.17651367188	10.067155584693	5.45853655785322	0.109097555279732	47.39452
12.210000038147	1993.60888671875	10.1504661142826	5.51707297563553	0.110195122659206	47.4048
12.3099994659424	1993.23913574219	10.2335456758738	5.56463422253728	0.111219510436058	47.396008
12.4099998474121	1997.33508300781	10.3168562054634	5.61585370451212	0.11224389821291	47.493404
12.5100002288818	1997.95056152344	10.4001658037305	5.67073188722134	0.113341465592384	47.50804
12.6099996566772	1998.89392089844	10.4832453653216	5.72560960426927	0.114365853369236	47.530472
12.710000038147	2000.73034667969	10.5667868629098	5.78048778697848	0.115463420748711	47.574136
12.8100004196167	2001.6962890625	10.6500964611769	5.83902420476079	0.116707317531109	47.597104
12.9099998474121	1999.31665039063	10.7334069907665	5.90487802401185	0.118024386465549	47.54052
13.0100002288818	1998.283203125	10.8169484883547	5.96707314252853	0.119195125997067	47.515948
13.1099996566772	2001.19738769531	10.9002580866218	6.02195132523775	0.120365850627422	47.585244
13.210000038147	2001.64208984375	10.9835686162114	6.0914633795619	0.121682927012444	47.595816
13.3099994659424	2002.18798828125	11.0673401504755	6.15365849807858	0.12285365909338	47.608796
13.4099998474121	2000.15979003906	11.1504197120667	6.21219491586089	0.124024391174316	47.560572
13.5100002288818	2001.39794921875	11.2337302416563	6.27804873511195	0.125487804412842	47.590012
13.6099996566772	2004.16687011719	11.3172717392445	6.34024385362864	0.126731708645821	47.655852
13.710000038147	2004.20166015625	11.4005813375115	6.39878027141094	0.127902448177338	47.65668
13.8100004196167	2001.70166015625	11.4836608991027	6.46097538992763	0.129073172807693	47.597232
13.9099998474121	2004.58312988281	11.5672023966908	6.52682920917869	0.130317077040672	47.665752
14.0100002288818	2001.29211425781	11.650281958282	6.58536609262228	0.131560981273651	47.587496
14.1099996566772	2003.32543945313	11.7338225245476	6.64390251040459	0.132804870605469	47.635844
14.210000038147	2005.51293945313	11.8173640221357	6.70243892818689	0.133975610136986	47.68786
14.3099994659424	2002.69689941406	11.9004426524043	6.76097581163049	0.13507317006588	47.6209
14.4099998474121	2003.74328613281	11.983753181994	6.81585352867842	0.136243909597397	47.64578
14.5100002288818	2000.64575195313	12.0670637115836	6.88536604866385	0.137634143233299	47.572124
14.6099996566772	2000.48571777344	12.1499123051763	6.95121940225363	0.138878047466278	47.56832
14.710000038147	2002.68994140625	12.2332228347659	7.01341452077031	0.140121951699257	47.620732
14.8100004196167	2002.10375976563	12.3163023963571	7.07926834002137	0.141439020633698	47.606796
14.9099998474121	2002.51574707031	12.3993819579482	7.14512215927243	0.142829269170761	47.616592
15.0100002288818	2003.18212890625	12.4824605882168	7.21463421359658	0.14407317340374	47.632436
15.1099996566772	2004.72338867188	12.5657711178064	7.27682933211327	0.145463407039642	47.669084
15.210000038147	2001.91625976563	12.6486197113991	7.33902445062995	0.146780490875244	47.602336
15.3099994659424	2000.87426757813	12.7319302409887	7.40487826988101	0.148024395108223	47.57756
15.4099998474121	2001.63488769531	12.8152407705784	7.47073162347078	0.149268299341202	47.595644
15.5100002288818	1997.97290039063	12.8983203321695	7.54024367779493	0.150585368275642	47.508568
15.6099996566772	1997.96484375	12.9816299304366	7.60609749704599	0.151975616812706	47.50838
15.710000038147	1997.54760742188	13.0651714280248	7.67195131629705	0.153219521045685	47.498456
15.8100004196167	1995.17553710938	13.1482509896159	7.73048773407936	0.154536589980125	47.442052
15.9099998474121	1998.07751464844	13.2317915558815	7.80365848913789	0.155926823616028	47.511056
16.0100002288818	1994.7861328125	13.3153330534697	7.86951184272766	0.15724390745163	47.432792
16.1100006103516	1995.80639648438	13.3986426517367	7.93902482837439	0.158634155988693	47.457052
16.2099990844727	1994.63293457031	13.4821841493249	8.00853688269854	0.160024389624596	47.429152
16.3099994659424	1994.87145996094	13.5657247155905	8.08902457356453	0.161487817764282	47.434824
16.4099998474121	1992.38647460938	13.6490352451801	8.15121922641993	0.162804871797562	47.375732
16.5100002288818	1992.56079101563	13.7325767427683	8.21707304567099	0.164195120334625	47.37988
16.6100006103516	1991.91577148438	13.8161173090339	8.28658509999514	0.165658533573151	47.36454
16.7099990844727	1992.17553710938	13.899196870625	8.35609715431929	0.166975617408752	47.370716
16.8099994659424	1989.47521972656	13.9827383682132	8.43292661011219	0.168439015746117	47.306508
16.9099998474121	1986.9970703125	14.0662789344788	8.506097830832	0.170048773288727	47.247584
17.0100002288818	1986.80786132813	14.1493584960699	8.58292728662491	0.171439036726952	47.243084
17.1100006103516	1984.73205566406	14.2328990623355	8.64878017455339	0.172756090760231	47.193724
17.2099990844727	1983.94982910156	14.3159786239266	8.71829222887754	0.174219518899918	47.175124
17.3099994659424	1986.86865234375	14.3990581855178	8.78780521452427	0.175682917237282	47.244528
17.4099998474121	1985.52282714844	14.4825996831059	8.85731726884842	0.177073165774345	47.212528
17.5100002288818	1984.22985839844	14.5656792446971	8.93048755824566	0.178536593914032	47.181784
17.6100006103516	1981.77014160156	14.6487588062882	8.99634137749672	0.17978048324585	47.123296
17.7099990844727	1979.29797363281	14.7318383678794	9.06219519674778	0.18109755218029	47.064512
17.8099994659424	1977.61218261719	14.814916998148	9.13170725107193	0.182487800717354	47.024424
17.9099998474121	1973.98999023438	14.8982275277376	9.20121930539608	0.183804869651794	46.938296
18.0100002288818	1973.0634765625	14.9813070893288	9.27073135972023	0.185268297791481	46.916264
18.1100006103516	1971.65747070313	15.0643866509199	9.3512199819088	0.186878055334091	46.882832
18.2099990844727	1971.43395996094	15.1474662125111	9.42439027130604	0.188341453671455	46.877516
18.3099994659424	1969.43933105469	15.2310067787766	9.50487796217203	0.189951211214066	46.830088
18.4099998474121	1969.92248535156	15.3140863403678	9.57804918289185	0.191414639353752	46.841576
18.5100002288818	1968.75048828125	15.3971659019589	9.647561237216	0.192804872989655	46.813708
18.6100006103516	1964.27368164063	15.4807073995471	9.7243906930089	0.194341465830803	46.707256
18.7099990844727	1966.33117675781	15.5640169978142	9.80121921747923	0.195878058671951	46.75618
18.8099994659424	1966.11108398438	15.6473275274038	9.87439043819904	0.197341457009315	46.750948
18.9099998474121	1962.41882324219	15.730869024992	9.95121989399195	0.198951214551926	46.663152
19.0100002288818	1960.69934082031	15.8141795545816	10.0280484184623	0.200414642691612	46.622264
19.1100006103516	1958.41455078125	15.8974900841713	10.1012196391821	0.201878041028976	46.567936
19.2099990844727	1957.57653808594	15.9810297191143	10.1743899285793	0.203341469168663	46.548008
19.3099994659424	1952.25012207031	16.064340248704	10.258536785841	0.204951226711273	46.421356
19.4099998474121	1953.77172851563	16.1478817462921	10.3353662416339	0.20648780465126	46.457536
19.5100002288818	1951.79931640625	16.2316542118788	10.4085365310311	0.207951217889786	46.410636
19.6100006103516	1949.52526855469	16.3147319108248	10.485365986824	0.209634155035019	46.356564
19.7099990844727	1948.2177734375	16.3982734084129	10.5621954426169	0.211097568273544	46.325472
19.8099994659424	1947.68884277344	16.4818149060011	10.6317074969411	0.212560966610909	46.312896
19.9099998474121	1945.1669921875	16.5648944675922	10.7121951878071	0.214097559452057	46.252932
20.0100002288818	1940.83129882813	16.6482049971819	10.7963411137462	0.215707302093506	46.149836
20.1100006103516	1943.16552734375	16.7315155267715	10.8731705695391	0.217243894934654	46.20534
20.2099990844727	1937.50549316406	16.8145950883627	10.9536582604051	0.218926832079887	46.070752
20.3099994659424	1933.607421875	16.8976746499538	11.030487716198	0.220463410019875	45.978064
20.4099998474121	1932.07336425781	16.9809833168983	11.1073171719909	0.222000002861023	45.941584
20.5100002288818	1930.85437011719	17.0640628784895	11.1878048628569	0.223682940006256	45.9126
20.6100006103516	1928.12707519531	17.1471424400806	11.2682925537229	0.225292682647705	45.847748
20.7099990844727	1925.78356933594	17.2304529696703	11.3414637744427	0.226682931184769	45.792024
20.8099994659424	1924.3203125	17.3133015632629	11.4219514653087	0.228219509124756	45.757232
20.9099998474121	1921.94287109375	17.3963811248541	11.5024391561747	0.229902431368828	45.7007
21.0100002288818	1920.17456054688	17.4796916544437	11.5865850821137	0.231512188911438	45.658652
21.1100006103516	1917.59143066406	17.5627712160349	11.6670727729797	0.233195126056671	45.597228
21.2099990844727	1915.14929199219	17.645850777626	11.7475613951683	0.234804883599281	45.53916
21.3099994659424	1912.853515625	17.7293922752142	11.8353655561805	0.236560985445976	45.484568
21.4099998474121	1905.67980957031	17.8127028048038	11.9085367769003	0.23802438378334	45.313988
21.5100002288818	1903.03442382813	17.8957805037498	11.9853662326932	0.239560976624489	45.251088
21.6100006103516	1898.17077636719	17.979322001338	12.076829560101	0.241317078471184	45.135436
21.7099990844727	1891.24475097656	18.0626325309277	12.1609754860401	0.242926836013794	44.970748
21.8099994659424	1885.83605957031	18.1457120925188	12.2414631769061	0.244682937860489	44.842136
21.9099998474121	1875.56579589844	18.229253590107	12.3329265043139	0.246512204408646	44.597928
22.0100002288818	1861.42858886719	18.3123331516981	12.4353654682636	0.248487800359726	44.261768
22.1100006103516	1836.39978027344	18.3956436812878	12.5378044322133	0.25053659081459	43.66662
22.2000007629395	11.5281000137329	18.4708759188652	12.8963412716985	0.254780471324921	0.27411959375