File: Tensile_tests/PA12_C5_XZ_6 07-5-22 12 34 39 PM/DAQ- Time, … - (Timed).txt
File Path: C:\MTS TestSuite\Data Files\Chahine\DOE\PA12_C5_XZ_6 07-5-22 12 34 39 PM\DAQ- Time, … - (Timed).txt
Test: MTS EM Tension (Extensometer)_Grand_Chahine 1
Test Run: PA12_C5_XZ_6
Date: 7/5/2022 12:34:06 PM


Time 	Load 	Crosshead 	Extensometer 	Strain 	Stress
sec	N	mm	mm	mm/mm	N/mm²
0.0999999716877937	48.6552200317383	0.061617283790838	0.0182926833076635	0.00021951220696792	1.229981
0.200000241398811	104.027320861816	0.144927529618144	0.04756097405334	0.00087804882787168	2.6297615
0.300000220537186	156.537796020508	0.229160898015834	0.0841463406686671	0.00160975614562631	3.95720175
0.400000184774399	208.834365844727	0.31270191539079	0.113414636871312	0.00219512195326388	5.2792345
0.500000178813934	261.914184570313	0.396012183045968	0.142682925797999	0.00278048776090145	6.621067
0.600000143051147	312.114715576172	0.47978397924453	0.175609762663953	0.00343902455642819	7.890113
0.700000107288361	362.489654541016	0.562863482628018	0.219512192416005	0.00431707315146923	9.163568
0.800000071525574	410.364044189453	0.646173721179366	0.256097555393353	0.0050487807020545	10.37381
0.900000035762787	460.155914306641	0.729253224562854	0.300000014249235	0.00585365854203701	11.632524
1	506.341705322266	0.811871141195297	0.332926836563274	0.00658536562696099	12.80008
1.10000002384186	551.933532714844	0.895181379746646	0.369512184988707	0.00731707317754626	13.952619
1.20000028610229	600.078918457031	0.978491618297994	0.406097562517971	0.00804878026247025	15.169712
1.30000019073486	645.608581542969	1.06134032830596	0.43902438483201	0.00870731752365828	16.32068
1.40000021457672	689.319763183594	1.14465062506497	0.471951207146049	0.00936585385352373	17.425678
1.50000011920929	736.126892089844	1.22796080540866	0.508536584675312	0.010097561404109	18.60894
1.60000014305115	776.402404785156	1.31104036699981	0.541463436093181	0.0107560968026519	19.627086
1.70000004768372	818.902648925781	1.39435054734349	0.581707339733839	0.0114878043532372	20.701472
1.80000007152557	859.475158691406	1.4776608441025	0.614634132944047	0.0122195119038224	21.727126
1.89999997615814	899.852355957031	1.56097114086151	0.651219510473311	0.0129512194544077	22.747844
2	940.264221191406	1.64451217278838	0.695121940225363	0.01382926851511	23.769436
2.09999990463257	980.017578125	1.72782235313207	0.728048791643232	0.0144878048449755	24.774382
2.20000028610229	1018.87335205078	1.81113264989108	0.764634169172496	0.0151463411748409	25.756638
2.30000019073486	1055.43762207031	1.89467368181795	0.797560962382704	0.015951219946146	26.680966
2.40000009536743	1090.26013183594	1.97821483016014	0.834146339911968	0.0166097562760115	27.561262
2.50000023841858	1127.25964355469	2.06152489408851	0.870731717441231	0.0172682926058769	28.496592
2.60000014305115	1160.9892578125	2.14529689401388	0.907317094970495	0.0180731695145369	29.34926
2.70000004768372	1196.5205078125	2.22837622277439	0.943902414292097	0.0188048779964447	30.247474
2.79999995231628	1229.64270019531	2.3116865195334	0.976829323917627	0.0195365864783525	31.084788
2.90000009536743	1261.39697265625	2.39545828662813	1.01707316935062	0.0202682912349701	31.88752
3	1289.54174804688	2.47876858338714	1.05365854687989	0.0209999997168779	32.599008
3.09999990463257	1319.16687011719	2.56184814497828	1.09024392440915	0.021804878488183	33.347916
3.20000028610229	1345.60693359375	2.64538917690516	1.1341463541612	0.0225365869700909	34.016308
3.30000019073486	1374.20129394531	2.72869924083352	1.17073173169047	0.0233414620161057	34.73916
3.40000009536743	1398.54296875	2.81177880242467	1.20731710921973	0.0240731704980135	35.354508
3.50000023841858	1423.35778808594	2.89485836401582	1.24756095465273	0.0248780492693186	35.981812
3.60000014305115	1447.51159667969	2.97816866077483	1.28780491650105	0.0256829261779785	36.592412
3.70000004768372	1469.0771484375	3.06124798953533	1.32804876193404	0.0264878049492836	37.137576
3.79999995231628	1490.30163574219	3.14455828629434	1.36829272378236	0.0272926837205887	37.674124
3.90000009536743	1509.92309570313	3.22763784788549	1.41219515353441	0.0281707309186459	38.170144
4	1526.79260253906	3.31071717664599	1.45609758328646	0.0289756096899509	38.596596
4.09999990463257	1544.68762207031	3.39425820857286	1.50000001303852	0.0298536587506533	39.048976
4.20000028610229	1564.82165527344	3.47733777016401	1.54024385847151	0.0307317078113556	39.557952
4.30000019073486	1575.99938964844	3.56041733175516	1.58414628822356	0.0316097550094128	39.84052
4.40000009536743	1594.29614257813	3.64395836368203	1.63536588661373	0.0326341465115547	40.303056
4.5	1606.55249023438	3.72703769244254	1.67926831636578	0.0335121937096119	40.612888
4.59999990463257	1620.7607421875	3.81011725403368	1.72317074611783	0.0343902446329594	40.972068
4.70000028610229	1632.15234375	3.89365828596056	1.77439022809267	0.0353414639830589	41.26004
4.80000019073486	1644.30822753906	3.97696858271956	1.81829265784472	0.0362926833331585	41.567336
4.90000009536743	1658.44909667969	4.06050961464643	1.86219508759677	0.0370975621044636	41.924812
5	1668.03686523438	4.1438196785748	1.90609751734883	0.0379756093025208	42.167184
5.09999990463257	1680.33862304688	4.22713020816445	1.94634147919714	0.0388536565005779	42.478168
5.20000028610229	1690.36108398438	4.31067124009132	1.99024379253387	0.0397317074239254	42.731532
5.30000019073486	1696.87365722656	4.39421227201819	2.04878044314682	0.0408292710781097	42.896164
5.40000009536743	1704.74243164063	4.47752233594656	2.0926829893142	0.041780486702919	43.095084
5.5	1710.59851074219	4.56106336787343	2.14024400338531	0.0426585376262665	43.243124
5.59999990463257	1723.72412109375	4.6446043998003	2.19146348536015	0.0437560975551605	43.574932
5.70000028610229	1727.365234375	4.72791492938995	2.24634143523872	0.0447804890573025	43.66698
5.80000019073486	1736.15209960938	4.81122499331832	2.29390244930983	0.0458048805594444	43.889108
5.90000009536743	1744.3779296875	4.89476602524519	2.34146346338093	0.046756099909544	44.097052
6	1748.53356933594	4.97784558683634	2.38536577671766	0.0477073155343533	44.202104
6.09999990463257	1757.38110351563	5.06138661876321	2.43292679078877	0.0485121980309486	44.425764
6.20000028610229	1764.48352050781	5.14469668269157	2.47682933695614	0.0494634136557579	44.605312
6.30000019073486	1768.984375	5.22777624428272	2.52439035102725	0.0503414645791054	44.719092
6.40000009536743	1777.05285644531	5.31085580587387	2.56829266436398	0.0512926839292049	44.92306
6.5	1781.13342285156	5.39416586980224	2.61951214633882	0.0523170754313469	45.026212
6.59999990463257	1786.44860839844	5.47724543139338	2.67439032904804	0.0534146316349506	45.16058
6.70000028610229	1792.67077636719	5.56032499298453	2.72926827892661	0.054512195289135	45.317872
6.80000019073486	1796.02392578125	5.6436350569129	2.78048776090145	0.0555365867912769	45.402636
6.90000009536743	1801.9111328125	5.72648411616683	2.83170724287629	0.0565609745681286	45.551464
7	1806.40173339844	5.80956321209669	2.88292672485113	0.0575121939182281	45.664984
7.09999990463257	1810.40771484375	5.89287374168634	2.93414643965662	0.0585365854203701	45.766252
7.20000028610229	1817.29516601563	5.97595330327749	2.98902438953519	0.0596341453492641	45.940364
7.30000019073486	1819.30505371094	6.05926336720586	3.0365854036063	0.0606585368514061	45.991172
7.40000009536743	1825.076171875	6.14257343113422	3.08780488558114	0.0616829283535481	46.137064
7.5	1829.59692382813	6.22565299272537	3.13536589965224	0.0625609755516052	46.251348
7.59999990463257	1833.20361328125	6.30896352231503	3.18658538162708	0.0636585354804993	46.342524
7.70000028610229	1836.10778808594	6.3925045542419	3.24146333150566	0.0646829307079315	46.41594
7.80000019073486	1839.54907226563	6.47558365017176	3.29634151421487	0.0657804906368256	46.502932
7.90000009536743	1844.61022949219	6.55889417976141	3.36219510063529	0.066951222717762	46.630876
8	1845.45239257813	6.64243521168828	3.42073175124824	0.068341463804245	46.652168
8.10000038146973	1850.40576171875	6.72551477327943	3.47195123322308	0.0692926794290543	46.777384
8.19999980926514	1850.06823730469	6.80882483720779	3.52317071519792	0.0703902468085289	46.768852
8.30000019073486	1854.94787597656	6.89236586913466	3.57439019717276	0.0714146345853806	46.892208
8.40000057220459	1859.26770019531	6.97544543072581	3.6256096791476	0.0724390223622322	47.001412
8.5	1861.15539550781	7.05898646265268	3.68048786185682	0.0734634101390839	47.049132
8.60000038146973	1866.11499023438	7.14206602424383	3.73536581173539	0.0745609775185585	47.174508
8.69999980926514	1867.896484375	7.2253760881722	3.79024399444461	0.0756585374474525	47.219544
8.80000019073486	1870.28601074219	7.30868661776185	3.84512194432318	0.0767560973763466	47.279948
8.89999961853027	1872.64050292969	7.39222764968872	3.89634142629802	0.0778536573052406	47.339468
9	1874.3076171875	7.47530674561858	3.9512193761766	0.0789512246847153	47.381612
9.10000038146973	1876.88354492188	7.55884777754545	4.00243885815144	0.0799756124615669	47.446732
9.19999980926514	1879.75024414063	7.64215830713511	4.06097574159503	0.0810731649398804	47.5192
9.30000019073486	1881.08923339844	7.72500690072775	4.11219522356987	0.082170732319355	47.553048
9.40000057220459	1882.83813476563	7.80831696465611	4.17073164135218	0.0832682922482491	47.59726
9.5	1885.06726074219	7.89162702858448	4.22560982406139	0.0843658596277237	47.653612
9.60000038146973	1883.12756347656	7.97470659017563	4.27317060530186	0.0853902474045753	47.604576
9.69999980926514	1887.73999023438	8.05824808776379	4.32804878801107	0.0864877998828888	47.721176
9.80000019073486	1890.072265625	8.14132764935493	4.39024390652776	0.0877317041158676	47.780136
9.89999961853027	1890.94860839844	8.22440721094608	4.44512208923697	0.0887560918927193	47.802288
10	1891.77416992188	8.30771680921316	4.4999998062849	0.0899268314242363	47.82316
10.1000003814697	1894.06896972656	8.39102733880281	4.56219492480159	0.0910975635051727	47.881172
10.1999998092651	1893.3642578125	8.47433786839247	4.61341440677643	0.0921219512820244	47.863356
10.3000001907349	1896.60766601563	8.55764746665955	4.66829258948565	0.0932926833629608	47.945348
10.4000005722046	1896.24243164063	8.6411889642477	4.72682947292924	0.0944634154438972	47.936116
10.5	1897.67687988281	8.72426852583885	4.77804895490408	0.0954878032207489	47.972376
10.6000003814697	1898.61791992188	8.8075790554285	4.83658537268639	0.0965853706002235	47.996164
10.6999998092651	1896.91833496094	8.89111962169409	4.89512179046869	0.0977560952305794	47.9532
10.8000001907349	1899.17822265625	8.97443015128374	4.95365867391229	0.0989268273115158	48.010328
10.8999996185303	1900.86889648438	9.05797071754932	5.01219509169459	0.100097566843033	48.053068
11	1901.72436523438	9.14128124713898	5.0707315094769	0.101268291473389	48.074696
11.1000003814697	1906.52746582031	9.22459177672863	5.12560969218612	0.102365851402283	48.196116
11.1999998092651	1904.14514160156	9.30813234299421	5.1878048107028	0.103609755635262	48.135892
11.3000001907349	1905.0517578125	9.39167384058237	5.24634169414639	0.10485365986824	48.158808
11.4000005722046	1904.39013671875	9.47498343884945	5.3048781119287	0.106024384498596	48.142084
11.5	1906.40747070313	9.55852493643761	5.35975629463792	0.107048779726028	48.19308
11.6000003814697	1903.93347167969	9.64183546602726	5.4219514131546	0.10836585611105	48.13054
11.6999998092651	1904.95825195313	9.72491502761841	5.48414653167129	0.109536580741405	48.156448
11.8000001907349	1906.97094726563	9.80845559388399	5.54268294945359	0.110707320272923	48.207328
11.8999996185303	1906.10278320313	9.89153515547514	5.60487806797028	0.111951224505901	48.18538
12	1905.06506347656	9.97461471706629	5.66341448575258	0.1131951212883	48.159148
12.1000003814697	1906.53564453125	10.0581552833319	5.7182926684618	0.114292681217194	48.19632
12.1999998092651	1906.38610839844	10.1414658129215	5.77682908624411	0.115463420748711	48.19254
12.3000001907349	1906.14831542969	10.2245453745127	5.8353659696877	0.116560973227024	48.186532
12.4000005722046	1908.41735839844	10.3080859407783	5.89756108820438	0.117804870009422	48.243892
12.5	1906.626953125	10.3913964703679	5.96341444179416	0.119121953845024	48.198632
12.6000003814697	1908.18322753906	10.4747069999576	6.02195132523775	0.12029267847538	48.237972
12.6999998092651	1909.54809570313	10.5580175295472	6.07682904228568	0.121463418006897	48.272476
12.8000001907349	1907.92492675781	10.6413271278143	6.14268286153674	0.122707322239876	48.231444
12.8999996185303	1907.05041503906	10.7246376574039	6.20121974498034	0.123951219022274	48.209336
13	1905.927734375	10.8081791549921	6.26341486349702	0.125195115804672	48.180956
13.1000003814697	1907.43664550781	10.8912577852607	6.3256099820137	0.126365855336189	48.2191
13.1999998092651	1905.82458496094	10.9747992828488	6.38780510053039	0.127609759569168	48.178348
13.3000001907349	1907.185546875	11.0583398491144	6.44634151831269	0.128780484199524	48.212752
13.4000005722046	1908.65295410156	11.1414194107056	6.51219533756375	0.130170732736588	48.249848
13.5	1905.78820800781	11.2249609082937	6.57073175534606	0.131341457366943	48.177428
13.6000003814697	1906.65454101563	11.3085014745593	6.63658557459712	0.132585361599922	48.199328
13.6999998092651	1906.49768066406	11.3915810361505	6.70243892818689	0.133975610136986	48.195364
13.8000001907349	1906.74108886719	11.4751225337386	6.76829274743795	0.135219514369965	48.201516
13.8999996185303	1905.46423339844	11.5586631000042	6.83048786595464	0.13639023900032	48.169236
14	1907.42797851563	11.6419736295938	6.89999992027879	0.137780487537384	48.21888
14.1000003814697	1903.26440429688	11.7252841591835	6.96219503879547	0.139097556471825	48.113628
14.1999998092651	1901.46936035156	11.8088247254491	7.02804885804653	0.140414640307426	48.068248
14.3000001907349	1901.69885253906	11.8921352550387	7.09756091237068	0.141804873943329	48.074052
14.4000005722046	1901.94445800781	11.9754457846284	7.15975603088737	0.143121957778931	48.08026
14.5	1901.41577148438	12.0587553828955	7.22560985013843	0.144439026713371	48.066892
14.6000003814697	1902.07202148438	12.1418349444866	7.27682933211327	0.145390242338181	48.083484
14.6999998092651	1900.63757324219	12.2251454740763	7.34268315136433	0.146634146571159	48.04722
14.8000001907349	1898.44604492188	12.3086860403419	7.4085365049541	0.1479512155056	47.99182
14.8999996185303	1899.11853027344	12.391765601933	7.47439032420516	0.149341464042664	48.00882
15	1901.25598144531	12.4750761315227	7.53658544272184	0.150585368275642	48.062856
15.1000003814697	1900.38159179688	12.5583866611123	7.59878056123853	0.151829272508621	48.040752
15.1999998092651	1898.15856933594	12.6414662227035	7.66463438048959	0.153146341443062	47.984552
15.3000001907349	1898.36071777344	12.7247758209705	7.73048773407936	0.154463410377502	47.989664
15.4000005722046	1895.11315917969	12.8080863505602	7.80365848913789	0.155853658914566	47.907568
15.5	1893.84924316406	12.8913968801498	7.86951184272766	0.15724390745163	47.875616
15.6000003814697	1891.783203125	12.9747064784169	7.93536566197872	0.158560991287231	47.823388
15.6999998092651	1892.62915039063	13.0582479760051	8.00121948122978	0.159951224923134	47.844772
15.8000001907349	1893.18115234375	13.1413275375962	8.07073153555393	0.161341458559036	47.858728
15.8999996185303	1891.77600097656	13.2248681038618	8.14024358987808	0.162658542394638	47.823204
16	1893.04431152344	13.30840960145	8.20243917405605	0.163902431726456	47.855268
16.1000003814697	1890.4365234375	13.3914891630411	8.26463382691145	0.165146350860596	47.789344
16.2000007629395	1890.73913574219	13.4747987613082	8.33048764616251	0.166463419795036	47.796992
16.3000011444092	1891.22326660156	13.5583402588964	8.40731710195541	0.167999997735024	47.809232
16.3999996185303	1888.95446777344	13.6414198204875	8.47317092120647	0.169317066669464	47.75188
16.5	1885.46557617188	13.7247303500772	8.53902474045753	0.170634150505066	47.66368
16.6000003814697	1886.126953125	13.8082709163427	8.60853679478168	0.17209754884243	47.6804
16.7000007629395	1885.11340332031	13.8913504779339	8.67804884910584	0.173414632678032	47.654776
16.7999992370605	1881.76452636719	13.974891975522	8.75121913850307	0.174878060817719	47.57012
16.8999996185303	1882.96936035156	14.0584325417876	8.82439035922289	0.176341459155083	47.600576
17	1882.01916503906	14.1415121033788	8.88658501207829	0.177585363388062	47.576556
17.1000003814697	1881.36572265625	14.2245916649699	8.95243883132935	0.178902447223663	47.56004
17.2000007629395	1879.46313476563	14.3081322312355	9.01829265058041	0.180219501256943	47.51194
17.3000011444092	1880.16101074219	14.3909808248281	9.07682906836271	0.181463420391083	47.529584
17.3999996185303	1878.3447265625	14.4742913544178	9.15731675922871	0.183073163032532	47.483668
17.5	1879.39428710938	14.5573709160089	9.2378044500947	0.18460975587368	47.5102
17.6000003814697	1876.42553710938	14.6402195096016	9.30365826934576	0.185926839709282	47.435152
17.7000007629395	1875.96325683594	14.7235300391912	9.37317032366991	0.187243893742561	47.423468
17.7999992370605	1875.130859375	14.8066096007824	9.44999977946281	0.188853666186333	47.402424
17.8999996185303	1873.08569335938	14.889458194375	9.52317100018263	0.190317064523697	47.350724
18	1869.2255859375	14.9727687239647	9.59634128957987	0.191707313060761	47.25314
18.1000003814697	1869.68322753906	15.0560783222318	9.66951251029968	0.193317070603371	47.264712
18.2000007629395	1868.30297851563	15.1391578838229	9.73536539822817	0.194634139537811	47.22982
18.3000011444092	1867.134765625	15.2224684134126	9.80487838387489	0.195951223373413	47.200288
18.3999996185303	1867.03186035156	15.3057789430022	9.88170690834522	0.197414621710777	47.197684
18.5	1867.94665527344	15.3890885412693	9.95121989399195	0.198804885149002	47.220812
18.6000003814697	1865.80395507813	15.4726300388575	10.0280484184623	0.200341463088989	47.166644
18.7000007629395	1864.26477050781	15.556170605123	10.1012196391821	0.201804876327515	47.127736
18.7999992370605	1863.52404785156	15.6392510980368	10.1743899285793	0.20326828956604	47.109008
18.8999996185303	1861.98156738281	15.7227907329798	10.2439019829035	0.204731702804565	47.070016
19	1860.54638671875	15.8063322305679	10.3207314386964	0.206341460347176	47.033736
19.1000003814697	1858.50634765625	15.8898737281561	10.3975608944893	0.207804873585701	46.982164
19.2000007629395	1855.50061035156	15.9734152257442	10.4743903502822	0.209341466426849	46.90618
19.3000011444092	1855.63635253906	16.0569548606873	10.5512198060751	0.210804879665375	46.909612
19.3999996185303	1853.18920898438	16.1400344222784	10.6317074969411	0.212487801909447	46.847748
19.5	1852.6640625	16.2235759198666	10.708536952734	0.214024394750595	46.834472
19.6000003814697	1852.36499023438	16.3071174174547	10.7817072421312	0.215487793087959	46.826912
19.7000007629395	1851.19934082031	16.3901969790459	10.8512192964554	0.216878056526184	46.797448
19.7999992370605	1849.77197265625	16.473738476634	10.9207313507795	0.218341469764709	46.761364
19.8999996185303	1848.79797363281	16.5570471435785	10.9975608065724	0.219804883003235	46.73674
20	1848.08703613281	16.6401267051697	11.0707320272923	0.22126829624176	46.718768
20.1000003814697	1847.92297363281	16.7234372347593	11.1475605517626	0.222731694579124	46.71462
20.2000007629395	1843.90100097656	16.806747764349	11.2280491739511	0.224414631724358	46.612948
20.3000011444092	1841.86584472656	16.8895963579416	11.3085368648171	0.226024389266968	46.5615
20.3999996185303	1839.17749023438	16.9729068875313	11.3890245556831	0.227634146809578	46.49354
20.5	1838.20617675781	17.0559864491224	11.465854011476	0.229170739650726	46.468984
20.6000003814697	1835.63232421875	17.1390660107136	11.5426825359464	0.230707317590714	46.40392
20.7000007629395	1834.20043945313	17.2223765403032	11.6195119917393	0.232243910431862	46.367724
20.7999992370605	1834.13500976563	17.3054561018944	11.6999996826053	0.233780473470688	46.366068
20.8999996185303	1834.78552246094	17.388766631484	11.7768291383982	0.235390245914459	46.382512
21	1830.90100097656	17.4720752984285	11.8243899196386	0.23634147644043	46.284312
21.1000003814697	1828.22424316406	17.5551548600197	11.8975611403584	0.237804874777794	46.216648
21.2000007629395	1827.73278808594	17.6384653896093	11.9743905961514	0.239341467618942	46.204224
21.3000011444092	1826.24328613281	17.7220068871975	12.0585365220904	0.240951210260391	46.166568
21.3999996185303	1822.78308105469	17.8050864487886	12.1317077428102	0.24248780310154	46.079096
21.5	1821.00708007813	17.8886279463768	12.2085362672806	0.244024395942688	46.0342
21.6000003814697	1818.39880371094	17.9721675813198	12.2890239581466	0.245634153485298	45.968264
21.7000007629395	1815.82482910156	18.055247142911	12.3695125803351	0.247170746326447	45.903196
21.7999992370605	1811.27124023438	18.1390196084976	12.4463411048055	0.248780488967896	45.788084
21.8999996185303	1813.18920898438	18.2223301380873	12.5304879620671	0.250463426113129	45.836568
22	1811.93640136719	18.3056406676769	12.60731741786	0.252073168754578	45.804896
22.1000003814697	1809.86926269531	18.3891803026199	12.687805108726	0.253609746694565	45.75264
22.2000007629395	1806.72229003906	18.4729527682066	12.768292799592	0.255146354436874	45.673088
22.3000011444092	1806.2568359375	18.5562632977962	12.8524387255311	0.256829261779785	45.66132
22.3999996185303	1803.279296875	18.6398047953844	12.9329264163971	0.258439004421234	45.586052
22.5	1800.93786621094	18.7231153249741	13.00975587219	0.259975612163544	45.52686
22.6000003814697	1797.86755371094	18.8064239919186	13.090243563056	0.261658549308777	45.449244
22.7000007629395	1795.80529785156	18.8897345215082	13.1670730188489	0.263268291950226	45.397112
22.7999992370605	1792.17346191406	18.9730450510979	13.2548781111836	0.264951229095459	45.3053
22.8999996185303	1789.4375	19.056124612689	13.3280484005809	0.266414642333984	45.236136
23	1786.44287109375	19.1392041742802	13.4158534929156	0.268097549676895	45.160432
23.1000003814697	1783.23266601563	19.2227456718683	13.5036585852504	0.26985365152359	45.07928
23.2000007629395	1782.52722167969	19.305594265461	13.5804880410433	0.271463423967361	45.061448
23.3000011444092	1780.65747070313	19.3889047950506	13.6646339669824	0.27307316660881	45.01418
23.3999996185303	1776.36669921875	19.4722153246403	13.7414634227753	0.274756103754044	44.905712
23.5	1771.77062988281	19.5550639182329	13.8219511136413	0.276365846395493	44.789524
23.6000003814697	1769.79602050781	19.6383725851774	13.9060979709029	0.277975618839264	44.739608
23.7000007629395	1766.71948242188	19.7214521467686	13.9865856617689	0.279585361480713	44.661836
23.7999992370605	1758.09301757813	19.8045317083597	14.0743898227811	0.281268298625946	44.443764
23.8999996185303	1755.61608886719	19.8878422379494	14.1585366800427	0.282951235771179	44.381148
24	1750.27258300781	19.9713837355375	14.2390243709087	0.28463414311409	44.246064
24.1000003814697	1743.7763671875	20.0544632971287	14.3268294632435	0.286390244960785	44.081844
24.2000007629395	1735.78576660156	20.1377738267183	14.4073171541095	0.288073182106018	43.879844
24.3000011444092	1729.48205566406	20.221084356308	14.4951222464442	0.289756089448929	43.720492
24.3999996185303	1714.75109863281	20.3043948858976	14.5865855738521	0.291585355997086	43.3481
24.5	1694.70703125	20.3879345208406	14.6853663027287	0.293487817049026	42.841396
24.5499992370605	-12.1988725662231	20.4297062009573	14.9817075580359	0.29619511961937	-0.30838175