File: Tensile_tests/PA12_C7_XZ_6 09-13-22 10 30 26 AM/DAQ- Time, … - (Timed).txt
File Path: C:\MTS TestSuite\Data Files\Chahine\DOE\PA12_C7_XZ_6 09-13-22 10 30 26 AM\DAQ- Time, … - (Timed).txt
Test: MTS EM Tension (Extensometer)_Grand_Chahine 1
Test Run: PA12_C7_XZ_6
Date: 9/13/2022 10:29:58 AM


Time 	Load 	Crosshead 	Extensometer 	Strain 	Stress
sec	N	mm	mm	mm/mm	N/mm²
0.110000215470791	31.667444229126	0.0452321619377472	0.0109756101664971	0.000146341466461308	0.7916286875
0.210000187158585	81.3419570922852	0.127619307022542	0.0365853666153271	0.000731707317754626	2.0334015
0.310000151395798	131.846008300781	0.211852675420232	0.0621951185166836	0.00117073173169047	3.29591125
0.410000115633011	183.981811523438	0.295393692795187	0.0951219481066801	0.00182926829438657	4.599212
0.510000109672546	229.502578735352	0.379165518097579	0.124390237033367	0.00241463421843946	5.7371485
0.61000007390976	277.185333251953	0.462937314296141	0.157317073899321	0.00314634153619409	6.929131
0.710000038146973	325.277069091797	0.54624758195132	0.19390243687667	0.00380487786605954	8.131337
0.810000002384186	371.685302734375	0.629557820502669	0.234146340517327	0.00460975617170334	9.291459
0.909999966621399	421.766906738281	0.712868117261678	0.278048770269379	0.00548780476674438	10.543408
1.01000022888184	462.555877685547	0.795947562437505	0.318292673910037	0.00629268307238817	11.563059
1.11000025272369	507.511779785156	0.879257800988853	0.351219525327906	0.00687804911285639	12.686875
1.21000015735626	551.365417480469	0.962568097747862	0.376829266315326	0.00753658544272184	13.783136
1.31000018119812	591.590881347656	1.04564754292369	0.417073169955984	0.00834146328270435	14.7887
1.41000008583069	636.346801757813	1.12849625293165	0.453658547485247	0.00899999961256981	15.907517
1.51000010967255	673.729919433594	1.21180654969066	0.49024389591068	0.00973170716315508	16.842026
1.61000001430511	713.935424804688	1.29488599486649	0.519512221217155	0.0103902444243431	17.847092
1.71000003814697	754.98583984375	1.37796544004232	0.559756124857813	0.0110487807542086	18.873278
1.80999994277954	791.051879882813	1.46127573680133	0.589024391956627	0.0116341467946768	19.774864
1.9099999666214	833.275756835938	1.54435518197715	0.629268295597285	0.0125121958553791	20.830384
2.01000022888184	869.864074707031	1.6274347435683	0.669512199237943	0.0133170736953616	21.745026
2.1100001335144	905.860595703125	1.71074492391199	0.702439050655812	0.0140487812459469	22.644874
2.21000027656555	942.232666015625	1.79382436908782	0.74268295429647	0.0147073166444898	23.554108
2.31000018119812	975.774719238281	1.87713466584682	0.779268273618072	0.0155853657051921	24.3926
2.41000008583069	1006.830078125	1.9606756977737	0.81951217725873	0.0162439029663801	25.168928
2.50999999046326	1039.38525390625	2.0439859945327	0.852439028676599	0.0169756095856428	25.982748
2.6100001335144	1071.38317871094	2.12729629129171	0.892682932317257	0.0177804883569479	26.782638
2.71000003814697	1099.68493652344	2.21083732321858	0.92926830984652	0.0185121949762106	27.49013
2.80999994277954	1129.60229492188	2.29414761997759	0.962195103056729	0.0191707313060761	28.23801
2.90999984741211	1159.32983398438	2.3772269487381	0.998780480585992	0.0199024379253387	28.981144
3.01000022888184	1183.88427734375	2.46099871583283	1.0317072737962	0.0205609761178494	29.594962
3.1100001335144	1212.5	2.54407827742398	1.06829265132546	0.021292682737112	30.310302
3.21000027656555	1239.20397949219	2.62761930935085	1.10853661317378	0.0220975615084171	30.977854
3.31000018119812	1261.37426757813	2.71116034127772	1.14512199070305	0.0228292681276798	31.53207
3.41000008583069	1284.64440917969	2.79447063803673	1.17804878391325	0.0234878044575453	32.113782
3.50999999046326	1310.28393554688	2.87778093479574	1.22195121366531	0.0243658535182476	32.754724
3.6100001335144	1329.90295410156	2.96132196672261	1.26219517551363	0.0251707322895527	33.245164
3.71000003814697	1347.22534179688	3.04440129548311	1.29878043662757	0.0259756091982126	33.678192
3.80999994277954	1367.72045898438	3.12771159224212	1.34268298279494	0.0267073158174753	34.190532
3.90999984741211	1386.10534667969	3.21102188900113	1.38292682822794	0.0275853648781776	34.65012
4.01000022888184	1402.43139648438	3.29433218576014	1.42682925797999	0.0283902436494827	35.058244
4.1100001335144	1418.58972167969	3.37718077935278	1.47073168773204	0.0293414648622274	35.462172
4.21000003814697	1435.65344238281	3.46049107611179	1.51463411748409	0.0302195139229298	35.888736
4.30999994277954	1450.60021972656	3.54357063770294	1.56585371587425	0.0311707314103842	36.262376
4.41000032424927	1467.2431640625	3.62664996646345	1.60609756130725	0.0320487804710865	36.67842
4.51000022888184	1476.5908203125	3.70996026322246	1.6499999910593	0.032926831394434	36.912096
4.6100001335144	1493.24157714844	3.79280908964574	1.69390242081136	0.0338048785924912	37.328332
4.71000003814697	1504.99597167969	3.87588841840625	1.74146343488246	0.0346829295158386	37.622172
4.80999994277954	1518.34118652344	3.9591989479959	1.78170728031546	0.0355609767138958	37.955776
4.90999984741211	1528.95690917969	4.04227804392576	1.82560971006751	0.036439023911953	38.221152
5.01000022888184	1538.91149902344	4.12535760551691	1.87317072413862	0.0373902432620525	38.47
5.1100001335144	1551.68078613281	4.20866813510656	1.91341468598694	0.0381951220333576	38.789208
5.21000003814697	1560.14794921875	4.29174723103642	1.95731711573899	0.0390731729567051	39.000872
5.30999994277954	1571.04614257813	4.37505776062608	2.00487812981009	0.0400243885815144	39.273308
5.41000032424927	1580.685546875	4.45859879255295	2.04512197524309	0.0408292710781097	39.514272
5.51000022888184	1590.17810058594	4.5416783541441	2.0926829893142	0.041780486702919	39.751572
5.6100001335144	1601.82336425781	4.62498841807246	2.14390247128904	0.0427317060530186	40.04268
5.71000003814697	1609.86791992188	4.70829894766212	2.18780478462577	0.0436829254031181	40.24378
5.80999994277954	1621.23669433594	4.79137804359198	2.23536579869688	0.044634148478508	40.52798
5.90999984741211	1629.06896972656	4.87468857318163	2.28292681276798	0.0455853678286076	40.723772
6.01000022888184	1635.51965332031	4.9582296051085	2.32682935893536	0.0464634150266647	40.885028
6.1100001335144	1642.67700195313	5.04153966903687	2.37073167227209	0.0473414659500122	41.063948
6.21000003814697	1649.15478515625	5.12461923062801	2.41829268634319	0.0482926853001118	41.22588
6.30999994277954	1657.87219238281	5.20816026255488	2.46951216831803	0.0492439046502113	41.4438
6.41000032424927	1664.6083984375	5.29123982414603	2.51341471448541	0.0501951202750206	41.612192
6.51000022888184	1672.54113769531	5.3747808560729	2.56097549572587	0.0511463396251202	41.810496
6.6100001335144	1679.73767089844	5.45809092000127	2.60853650979698	0.0520975589752197	41.990396
6.71000003814697	1685.951171875	5.54117048159242	2.65975599177182	0.0530487820506096	42.145724
6.80999994277954	1693.23095703125	5.62448054552078	2.70731700584292	0.0540000014007092	42.327704
6.90999984741211	1699.55053710938	5.70802157744765	2.7512195520103	0.0549512207508087	42.485684
7.01000022888184	1703.41198730469	5.79087063670158	2.80243903398514	0.055902436375618	42.582212
7.1100001335144	1712.376953125	5.87418070062995	2.84634158015251	0.0567804872989655	42.80632
7.21000003814697	1714.400390625	5.9574912302196	2.89390236139297	0.0578048788011074	42.856904
7.30999994277954	1723.56066894531	6.04080129414797	2.94146337546408	0.058756098151207	43.085892
7.41000032424927	1729.18408203125	6.12388085573912	2.99268285743892	0.059853658080101	43.226468
7.51000022888184	1731.87512207031	6.20719091966748	3.04024387151003	0.0606585368514061	43.29374
7.6100001335144	1735.4873046875	6.29027048125863	3.08780488558114	0.0617560967803001	43.384036
7.71000003814697	1744.30920410156	6.373580545187	3.14268283545971	0.06270731985569	43.604568
7.80999994277954	1748.66931152344	6.45689107477665	3.18658538162708	0.0636585354804993	43.713564
7.90999984741211	1753.07275390625	6.54020113870502	3.23780486360192	0.0646097511053085	43.82364
8.01000022888184	1757.15905761719	6.62351166829467	3.28536587767303	0.0655609741806984	43.925792
8.11000061035156	1765.1923828125	6.70682173222303	3.32926819100976	0.0665121972560883	44.126612
8.21000003814697	1766.51916503906	6.78990129381418	3.38048790581524	0.0675365850329399	44.159776
8.3100004196167	1774.02575683594	6.87344232574105	3.43902432359755	0.068634144961834	44.347428
8.40999984741211	1774.892578125	6.95698335766792	3.48658533766866	0.0696585401892662	44.369096
8.51000022888184	1777.66064453125	7.04029342159629	3.53414635173976	0.0706097558140755	44.438296
8.60999965667725	1781.43395996094	7.12406542152166	3.58170736581087	0.0715609788894653	44.53262
8.71000003814697	1786.16076660156	7.20737548545003	3.63658531568944	0.072585366666317	44.65078
8.8100004196167	1788.62854003906	7.29068601503968	3.69146349839866	0.073682926595211	44.712472
8.90999984741211	1792.45385742188	7.37422704696655	3.73536581173539	0.0746341496706009	44.808096
9.01000022888184	1795.11071777344	7.45753711089492	3.7829268258065	0.0755853652954102	44.874516
9.11000061035156	1797.40893554688	7.54084764048457	3.83414630778134	0.0766097605228424	44.931964
9.21000003814697	1804.4970703125	7.62438867241144	3.88902449049056	0.0776341482996941	45.109156
9.3100004196167	1808.23645019531	7.70769873633981	3.93658550456166	0.0786585360765457	45.202636
9.40999984741211	1811.00500488281	7.79100880026817	3.99146322160959	0.0797560960054398	45.271844
9.51000022888184	1811.3408203125	7.87431932985783	4.04268270358443	0.080780491232872	45.280236
9.60999965667725	1816.54284667969	7.95739889144897	4.09756088629365	0.0818780511617661	45.41028
9.71000003814697	1818.54858398438	8.04070848971605	4.14878036826849	0.0829756110906601	45.46042
9.8100004196167	1822.10021972656	8.12424998730421	4.19999985024333	0.08392683416605	45.549204
9.90999984741211	1823.13940429688	8.20732954889536	4.25487803295255	0.0849512219429016	45.57518
10.0100002288818	1824.65307617188	8.29064007848501	4.30609751492739	0.0859756097197533	45.61302
10.1100006103516	1826.8935546875	8.3741806447506	4.3609756976366	0.0871463418006897	45.669028
10.210000038147	1830.05529785156	8.45749117434025	4.41585388034582	0.0882439017295837	45.748064
10.3100004196167	1832.27416992188	8.5405707359314	4.45975596085191	0.0891219526529312	45.803532
10.4099998474121	1832.91088867188	8.62411130219698	4.51463414356112	0.0902195125818253	45.819452
10.5100002288818	1837.23217773438	8.70719086378813	4.57317056134343	0.0913170725107193	45.927476
10.6099996566772	1840.27490234375	8.79050139337778	4.62073180824518	0.092341460287571	46.003536
10.710000038147	1839.12170410156	8.87427292764187	4.6756099909544	0.0934390276670456	45.974708
10.8100004196167	1841.40124511719	8.95758345723152	4.73414640873671	0.0945365875959396	46.031692
10.9099998474121	1843.86767578125	9.04089398682117	4.78536589071155	0.0955609828233719	46.093352
11.0100002288818	1844.05932617188	9.12443455308676	4.84024407342076	0.0966585353016853	46.09814
11.1100006103516	1847.67846679688	9.20797605067492	4.89512179046869	0.0977560952305794	46.188612
11.210000038147	1847.44470214844	9.29105468094349	4.94268303737044	0.098780483007431	46.182768
11.3100004196167	1848.36560058594	9.37459617853165	4.99024381861091	0.0997317135334015	46.205792
11.4099998474121	1850.6357421875	9.45813674479723	5.0487807020545	0.100902438163757	46.26254
11.5100002288818	1853.28442382813	9.54144727438688	5.10365841910243	0.10192683339119	46.328752
11.6099996566772	1853.68786621094	9.62498877197504	5.1475609652698	0.102804884314537	46.338836
11.710000038147	1857.09423828125	9.70829837024212	5.21707301959395	0.104268297553062	46.423992
11.8100004196167	1855.77526855469	9.79160889983177	5.28292683884501	0.105512201786041	46.39102
11.9099998474121	1857.86315917969	9.87538043409586	5.34146325662732	0.106756098568439	46.443212
12.0100002288818	1858.61584472656	9.95845999568701	5.39268273860216	0.107780486345291	46.462028
12.1100006103516	1860.65490722656	10.0417705252767	5.443902220577	0.108804881572723	46.513
12.210000038147	1858.0712890625	10.1253110915422	5.49878040328622	0.109756097197533	46.448416
12.3100004196167	1859.50561523438	10.2086216211319	5.54634165018797	0.110780484974384	46.484272
12.4099998474121	1858.65344238281	10.291701182723	5.59390243142843	0.111804872751236	46.462968
12.5100002288818	1860.67846679688	10.3750117123127	5.65243884921074	0.112902440130711	46.513588
12.6099996566772	1860.28051757813	10.4583222419024	5.71097573265433	0.114073164761066	46.50364
12.710000038147	1861.76928710938	10.5416318401694	5.76951215043664	0.115243904292583	46.540856
12.8100004196167	1864.76232910156	10.6249423697591	5.8353659696877	0.116634145379066	46.61568
12.9099998474121	1861.62512207031	10.7080219313502	5.89756108820438	0.117804870009422	46.537256
13.0100002288818	1865.51647949219	10.7913324609399	5.94878057017922	0.118902437388897	46.634532
13.1100006103516	1864.24572753906	10.8748730272055	6.014633923769	0.120146341621876	46.602764
13.210000038147	1863.50842285156	10.9579525887966	6.07682904228568	0.121390238404274	46.584332
13.3100004196167	1865.41296386719	11.0414931550622	6.13902462646365	0.122634142637253	46.631944
13.4099998474121	1863.73718261719	11.1250346526504	6.19390234351158	0.12380488216877	46.590052
13.5100002288818	1863.99182128906	11.2081142142415	6.25975616276264	0.12512195110321	46.596416
13.6099996566772	1863.13317871094	11.2916547805071	6.3256099820137	0.126365855336189	46.574952
13.710000038147	1860.8916015625	11.3751962780952	6.41341460868716	0.128195121884346	46.518916
13.8100004196167	1864.80578613281	11.4582758396864	6.46829279139638	0.129219502210617	46.616764
13.9099998474121	1861.58068847656	11.5415854379535	6.53414614498615	0.130536586046219	46.536144
14.0100002288818	1863.06884765625	11.6251269355416	6.58536609262228	0.131634145975113	46.573344
14.1100006103516	1865.07946777344	11.7082064971328	6.64390251040459	0.132804870605469	46.623608
14.210000038147	1865.14404296875	11.7917470633984	6.70609762892127	0.134048774838448	46.62522
14.3100004196167	1863.82861328125	11.875057592988	6.76829274743795	0.135292679071426	46.592336
14.4099998474121	1864.29614257813	11.9583681225777	6.83414656668901	0.136609762907028	46.604024
14.5100002288818	1865.53454589844	12.0419086888433	6.90365862101316	0.137926831841469	46.634984
14.6099996566772	1862.458984375	12.1252192184329	6.96951197460294	0.139243900775909	46.5581
14.710000038147	1861.44787597656	12.2082987800241	7.03170709311962	0.140487805008888	46.532824
14.8100004196167	1860.79138183594	12.2916093096137	7.10487784817815	0.141878053545952	46.516412
14.9099998474121	1858.27709960938	12.3749189078808	7.17073166742921	0.143268287181854	46.45356
15.0100002288818	1857.99597167969	12.4577675014734	7.23292678594589	0.144512191414833	46.446532
15.1100006103516	1859.37243652344	12.5410780310631	7.29512190446258	0.145902439951897	46.48094
15.210000038147	1858.53820800781	12.6243885606527	7.36463395878673	0.147219508886337	46.460088
15.3100004196167	1858.35681152344	12.7070061862469	7.43048777803779	0.148390248417854	46.455552
15.4099998474121	1858.12536621094	12.7903167158365	7.49634159728885	0.149780482053757	46.449768
15.5100002288818	1860.26916503906	12.8736272454262	7.56951235234737	0.151243895292282	46.503356
15.6099996566772	1858.24890136719	12.9567068070173	7.63536570593715	0.152487799525261	46.452856
15.710000038147	1858.65075683594	13.0400164052844	7.69390258938074	0.15373170375824	46.4629
15.8100004196167	1854.91833496094	13.1233269348741	7.76707334443927	0.155268296599388	46.369596
15.9099998474121	1853.12634277344	13.2064064964652	7.84390233457088	0.156731694936752	46.3248
16.0100002288818	1853.57763671875	13.2897170260549	7.90609791874886	0.157975614070892	46.33608
16.1100006103516	1850.91320800781	13.3730266243219	7.9792682081461	0.159365847706795	46.269476
16.2100009918213	1851.6708984375	13.4561061859131	8.04878026247025	0.160829275846481	46.288416
16.3099994659424	1852.57409667969	13.5396476835012	8.11463408172131	0.162146329879761	46.310996
16.4099998474121	1849.18054199219	13.6231882497668	8.18414613604546	0.163609758019447	46.226164
16.5100002288818	1851.61657714844	13.7064987793565	8.24999995529652	0.164853647351265	46.28706
16.6100006103516	1846.6318359375	13.7900393456221	8.32682941108942	0.166390240192413	46.162448
16.7099990844727	1848.24035644531	13.8735808432102	8.39999970048666	0.1678536683321	46.20266
16.8099994659424	1845.16284179688	13.9568913727999	8.47317092120647	0.169317066669464	46.125728
16.9099998474121	1844.84204101563	14.040662907064	8.54634121060371	0.170780494809151	46.117708
17.0100002288818	1843.86450195313	14.1239734366536	8.61585326492786	0.17209754884243	46.093272
17.1100006103516	1839.71423339844	14.2072830349207	8.67804884910584	0.17334146797657	45.98952
17.2100009918213	1841.37854003906	14.2905935645103	8.75487830489874	0.17495122551918	46.031128
17.3099994659424	1840.83947753906	14.3739040941	8.83170776069164	0.176487803459167	46.017652
17.4099998474121	1836.56408691406	14.4572136923671	8.89390241354704	0.177731692790985	45.910772
17.5100002288818	1836.2734375	14.5407551899552	8.96341446787119	0.17912195622921	45.903508
17.6100006103516	1834.25952148438	14.6238347515464	9.02926828712225	0.180512204766274	45.853164
17.7099990844727	1832.64294433594	14.707145281136	9.10243857651949	0.181756094098091	45.812752
17.8099994659424	1831.81262207031	14.7904548794031	9.17926803231239	0.183439031243324	45.791996
17.9099998474121	1832.81457519531	14.8735344409943	9.2560974881053	0.185048788785934	45.817044
18.0100002288818	1830.18481445313	14.9566140025854	9.32560954242945	0.186365857720375	45.751304
18.1100006103516	1824.486328125	15.0399245321751	9.40243899822235	0.187975615262985	45.608852
18.2100009918213	1825.703125	15.1230040937662	9.47926845401526	0.189439028501511	45.639268
18.3099994659424	1821.69689941406	15.2058526873589	9.55609790980816	0.190902441740036	45.53912
18.4099998474121	1819.09375	15.2893932536244	9.63658560067415	0.192585363984108	45.474048
18.5100002288818	1814.23474121094	15.3724728152156	9.71341505646706	0.194121956825256	45.35258
18.6100006103516	1808.25659179688	15.4555523768067	9.79390274733305	0.195585355162621	45.203136
18.7099990844727	1807.50769042969	15.5388629063964	9.86707303673029	0.197121948003769	45.184416
18.8099994659424	1800.71545410156	15.6219424679875	9.94756072759628	0.198804885149002	45.014624
18.9099998474121	1797.08459472656	15.7052520662546	10.0317075848579	0.200487807393074	44.923856
19.0100002288818	1790.48388671875	15.7885625958443	10.1121952757239	0.202097564935684	44.758852
19.1100006103516	1776.98986816406	15.8718731254339	10.2073168382049	0.204000011086464	44.421528
19.2100009918213	1748.8427734375	15.9551836550236	10.3097558021545	0.205975607037544	43.7179
19.2700004577637	10.1451578140259	16.0050317645073	10.7926828786731	0.212780475616455	0.2536105625