File: Tensile_tests/PA12_C1_XZ_7 05-16-22 15 52 31 PM/DAQ- Time, … - (Timed).txt
File Path: C:\MTS TestSuite\Data Files\Chahine\DOE\PA12_C1_XZ_7 05-16-22 15 52 31 PM\DAQ- Time, … - (Timed).txt
Test: MTS EM Tension (Extensometer)_Grand_Chahine 1
Test Run: PA12_C1_XZ_7
Date: 5/16/2022 3:51:59 PM


Time 	Load 	Crosshead 	Extensometer 	Strain 	Stress
sec	N	mm	mm	mm/mm	N/mm²
0.109999842941761	47.8897743225098	0.0660020305076614	0.0182926833076635	0.000292682932922617	1.189613
0.209999844431877	103.734336853027	0.14861996169202	0.04756097405334	0.000951219466514885	2.576828
0.309999853372574	158.635208129883	0.232391772442497	0.0768292666180059	0.00146341463550925	3.94060125
0.409999847412109	212.213363647461	0.316163583192974	0.106097562820651	0.00204878044314682	5.2715175
0.509999871253967	266.254455566406	0.399704615119845	0.13902438513469	0.00270731723867357	6.613933
0.60999983549118	319.132049560547	0.482784089399502	0.171951222000644	0.00336585356853902	7.9274465
0.709999859333038	370.217926025391	0.566094357054681	0.201219518203288	0.0039512193761766	9.196453
0.809999823570251	418.396362304688	0.649404595606029	0.234146340517327	0.00460975617170334	10.393236
0.909999847412109	467.192413330078	0.732253305613995	0.274390244157985	0.00548780476674438	11.605362
1.00999987125397	521.097778320313	0.815563544165343	0.307317066472024	0.00607317080721259	12.944406
1.10999989509583	566.529846191406	0.898643047548831	0.343902444001287	0.00680487789213657	14.072968
1.20999979972839	614.354614257813	0.981722492724657	0.38048779242672	0.00753658544272184	15.260966
1.30999982357025	660.261169433594	1.06503278948367	0.417073169955984	0.00826829299330711	16.401315
1.40999984741211	707.9970703125	1.14811223465949	0.453658547485247	0.00899999961256981	17.587106
1.50999987125397	754.401000976563	1.2314225314185	0.482926843687892	0.00958536565303802	18.73981
1.60999989509583	800.284423828125	1.31450197659433	0.5158536368981	0.0102439019829035	19.879584
1.70999979972839	845.726257324219	1.3980430085212	0.552439014427364	0.0109756095334888	21.008388
1.80999982357025	887.691589355469	1.48135330528021	0.589024391956627	0.011707317084074	22.050834
1.90999984741211	929.144653320313	1.5646634856239	0.625609769485891	0.0124390246346593	23.080554
2.00999975204468	972.652648925781	1.64820451755077	0.662195147015154	0.013170731253922	24.161322
2.10999989509583	1011.39312744141	1.73151481430978	0.695121940225363	0.01382926851511	25.12366
2.20999979972839	1054.25512695313	1.81505584623665	0.731707317754626	0.0145609760656953	26.18838
2.30999994277954	1093.88110351563	1.89836614299566	0.76829269528389	0.0152926836162806	27.172714
2.40999984741211	1134.01977539063	1.9819070585072	0.797560962382704	0.0158780477941036	28.169786
2.50999975204468	1171.49096679688	2.06544809043407	0.834146339911968	0.0166097562760115	29.100594
2.60999989509583	1208.22326660156	2.14875838719308	0.870731717441231	0.0173414647579193	30.013048
2.70999979972839	1246.79309082031	2.23206868395209	0.903658510651439	0.0179999992251396	30.971148
2.80999994277954	1282.74230957031	2.31560971587896	0.940243888180703	0.0187317077070475	31.86415
2.90999984741211	1317.78479003906	2.39915074780583	0.973170739598572	0.0193902440369129	32.734628
3.00999975204468	1350.54846191406	2.48223030939698	1.00975611712784	0.020195122808218	33.548498
3.10999989509583	1381.62719726563	2.56554037332535	1.04999996256083	0.0208536572754383	34.320512
3.20999979972839	1414.57958984375	2.64885067008436	1.0865853400901	0.0216585379093885	35.139072
3.30999994277954	1441.38696289063	2.73193023167551	1.13048776984215	0.0224634148180485	35.804984
3.40999984741211	1470.94580078125	2.81524052843452	1.17073173169047	0.0232682935893536	36.539244
3.50999975204468	1496.88208007813	2.89831985719502	1.20731710921973	0.0240731704980135	37.18352
3.60999989509583	1524.61108398438	2.98163015395403	1.24390248674899	0.0248048789799213	37.872328
3.70999979972839	1550.10302734375	3.06470971554518	1.28414633218199	0.0256097540259361	38.505564
3.80999994277954	1573.30541992188	3.14778927713633	1.32804876193404	0.0264878049492836	39.081924
3.90999984741211	1594.74609375	3.23086860589683	1.36829272378236	0.0272926837205887	39.614524
4.00999975204468	1617.13256835938	3.31417890265584	1.41219515353441	0.0281707309186459	40.17062
4.10999965667725	1637.83508300781	3.39725846424699	1.45243899896741	0.0289756096899509	40.684884
4.21000003814697	1653.85083007813	3.48033779300749	1.50000001303852	0.0299268290400505	41.082724
4.30999994277954	1671.77282714844	3.5636480897665	1.54390244279057	0.0307317078113556	41.52792
4.40999984741211	1687.77221679688	3.64695838652551	1.58414628822356	0.0316097550094128	41.925356
4.50999975204468	1701.62805175781	3.73026868328452	1.62804883439094	0.0324878059327602	42.269544
4.60999965667725	1713.09912109375	3.81357898004353	1.67926831636578	0.0334390252828598	42.554492
4.71000003814697	1723.54443359375	3.8968890439719	1.72682921402156	0.0343902446329594	42.81396
4.80999994277954	1735.09338378906	3.98043030872941	1.77439022809267	0.0353414639830589	43.100844
4.90999984741211	1747.7890625	4.06374037265778	1.82560971006751	0.0363658517599106	43.416212
5.00999975204468	1755.56262207031	4.14705090224743	1.87317072413862	0.0373902432620525	43.609312
5.10999965667725	1767.34838867188	4.2305919341743	1.92439020611346	0.0384146347641945	43.902076
5.21000003814697	1775.62976074219	4.31413296610117	1.97195122018456	0.0393658541142941	44.107792
5.30999994277954	1784.35583496094	4.39721206203103	2.01951223425567	0.0403170734643936	44.324552
5.40999984741211	1789.48266601563	4.4807530939579	2.07073171623051	0.0413414649665356	44.451908
5.50999975204468	1797.83264160156	4.56429412588477	2.12560966610909	0.0423658564686775	44.659328
5.60999965667725	1806.89819335938	4.64760465547442	2.17682938091457	0.0433902442455292	44.88452
5.71000003814697	1810.43872070313	4.73091471940279	2.22804886288941	0.0444146320223808	44.972468
5.80999994277954	1815.68933105469	4.81445575132966	2.27926834486425	0.0454390235245228	45.1029
5.90999984741211	1821.41687011719	4.89753531292081	2.32682935893536	0.0464634150266647	45.245172
6.00999975204468	1823.36254882813	4.98084537684917	2.38170730881393	0.0474878028035164	45.293504
6.10999965667725	1830.54235839844	5.06415590643883	2.4365852586925	0.0485853664577007	45.471856
6.21000003814697	1833.91784667969	5.14723546802998	2.49146344140172	0.0497560985386372	45.555708
6.30999994277954	1839.84814453125	5.23054553195834	2.54634139128029	0.0508536584675312	45.70302
6.40999984741211	1844.62829589844	5.31362509354949	2.59756087325513	0.0518048778176308	45.82176
6.50999975204468	1849.25634765625	5.39670465514064	2.64512188732624	0.0527561008930206	45.936724
6.60999965667725	1852.30187988281	5.47978421673179	2.69634136930108	0.0538536570966244	46.012376
6.71000003814697	1859.3759765625	5.56309428066015	2.7512195520103	0.0549512207508087	46.188104
6.80999994277954	1863.91259765625	5.6459428742528	2.80975620262325	0.0560487806797028	46.300796
6.90999984741211	1865.23864746094	5.72902243584394	2.85731698386371	0.0570731684565544	46.333736
7.00999975204468	1869.93103027344	5.81233249977231	2.91219516657293	0.0581707358360291	46.450296
7.10999965667725	1871.56701660156	5.89541206136346	2.97073181718588	0.0592682920396328	46.490936
7.21000003814697	1874.7265625	5.97872259095311	3.02926823496819	0.0603658519685268	46.56942
7.30999994277954	1877.80981445313	6.06203265488148	3.08048771694303	0.0614634156227112	46.646012
7.40999984741211	1879.39819335938	6.14511221647263	3.13536589965224	0.0626341477036476	46.685468
7.50999975204468	1883.21057128906	6.22819177806377	3.19024384953082	0.0637317076325417	46.780168
7.60999965667725	1887.55749511719	6.31150184199214	3.2524389680475	0.0649024397134781	46.888148
7.71000003814697	1889.68347167969	6.39481237158179	3.30365845002234	0.0659268274903297	46.94096
7.80999994277954	1893.970703125	6.47812243551016	3.35853663273156	0.0670243874192238	47.04746
7.90999984741211	1897.10729980469	6.56143249943852	3.41341458261013	0.0681219547986984	47.125372
8.01000022888184	1898.39953613281	6.64451206102967	3.46829276531935	0.0692195147275925	47.157472
8.10999965667725	1900.69604492188	6.72805309295654	3.52317071519792	0.0703170746564865	47.21452
8.21000003814697	1902.91418457031	6.8113636225462	3.57804889790714	0.0714146345853806	47.26962
8.30999946594238	1903.58374023438	6.89467368647456	3.62926837988198	0.0725121945142746	47.286252
8.40999984741211	1904.22827148438	6.97798375040293	3.68780479766428	0.073682926595211	47.302264
8.51000022888184	1905.78552246094	7.06129427999258	3.7426829803735	0.0747073143720627	47.340944
8.60999965667725	1908.46411132813	7.14460434392095	3.79390246234834	0.0758048817515373	47.407484
8.71000003814697	1911.58483886719	7.2279148735106	3.85243911296129	0.0769756063818932	47.485004
8.80999946594238	1913.37878417969	7.31145590543747	3.92195116728544	0.078219510614872	47.529568
8.90999984741211	1917.80847167969	7.39453500136733	3.97317064926028	0.0793170779943466	47.639604
9.01000022888184	1920.02124023438	7.4780760332942	4.0280488319695	0.0804146379232407	47.694572
9.10999965667725	1916.482421875	7.56138656288385	4.08292701467872	0.0816585421562195	47.606664
9.21000003814697	1922.87634277344	7.6442351564765	4.1451221331954	0.0827560946345329	47.765492
9.30999946594238	1920.51623535156	7.72777618840337	4.19634161517024	0.0837804824113846	47.706868
9.40999984741211	1919.29187011719	7.81085574999452	4.26219496876001	0.0850975587964058	47.676452
9.51000022888184	1922.60437011719	7.89416581392288	4.32073185220361	0.0862682908773422	47.758736
9.60999965667725	1921.24963378906	7.97747634351254	4.37926826998591	0.0874390304088593	47.725084
9.71000003814697	1921.37829589844	8.06055590510368	4.43414645269513	0.0886097550392151	47.72828
9.80999946594238	1926.77575683594	8.14363546669483	4.49268287047744	0.0897804796695709	47.862356
9.90999984741211	1924.65002441406	8.22694506496191	4.54756105318666	0.0908780470490456	47.809552
10.0100002288818	1929.13415527344	8.31025559455156	4.60975617170334	0.0920487865805626	47.92094
10.1099996566772	1930.21166992188	8.39356612414122	4.67195129022002	0.0932926833629608	47.947708
10.210000038147	1930.20434570313	8.4771066904068	4.72682947292924	0.0943902432918549	47.947524
10.3099994659424	1931.16076660156	8.56041721999645	4.78902459144592	0.0957073196768761	47.971284
10.4099998474121	1931.91076660156	8.64372774958611	4.84390230849385	0.0967317074537277	47.989912
10.5100002288818	1930.91772460938	8.72703734785318	4.90609742701054	0.0979756116867065	47.965248
10.6099996566772	1933.81982421875	8.81057884544134	4.96463431045413	0.0992195159196854	48.037336
10.710000038147	1931.39294433594	8.89388937503099	5.02317072823644	0.100463412702084	47.977052
10.8099994659424	1933.48657226563	8.97719897329807	5.08536584675312	0.101560980081558	48.029056
10.9099998474121	1932.78259277344	9.06074047088623	5.14390226453543	0.102731704711914	48.011572
11.0100002288818	1931.701171875	9.14405100047588	5.20609738305211	0.103975608944893	47.984708
11.1099996566772	1932.30969238281	9.22759156674147	5.26829250156879	0.105219513177872	47.999824
11.210000038147	1934.048828125	9.31113306432962	5.32682938501239	0.106390237808228	48.043024
11.3099994659424	1933.20922851563	9.3944426625967	5.39268273860216	0.107780486345291	48.022168
11.4099998474121	1936.52624511719	9.47798416018486	5.45121962204576	0.108951218426228	48.104564
11.5100002288818	1935.89733886719	9.56129375845194	5.51341474056244	0.110195122659206	48.088944
11.6099996566772	1936.61584472656	9.64460428804159	5.57560985907912	0.111365847289562	48.106792
11.710000038147	1934.10925292969	9.72791481763124	5.63048804178834	0.112463414669037	48.044524
11.8099994659424	1933.78112792969	9.81099437922239	5.68902445957065	0.113634154200554	48.036376
11.9099998474121	1932.27233886719	9.89430397748947	5.74756087735295	0.11480487883091	47.998896
12.0100002288818	1931.42749023438	9.97761450707912	5.80609776079655	0.116048783063889	47.977908
12.1099996566772	1931.11743164063	10.0609250366688	5.86463417857885	0.117146342992783	47.970208
12.210000038147	1932.08361816406	10.1442355662584	5.92682929709554	0.118463411927223	47.994208
12.3099994659424	1930.21740722656	10.2275451645255	5.9926831163466	0.119707316160202	47.947848
12.4099998474121	1933.33911132813	10.3110866621137	6.0512195341289	0.120878055691719	48.025396
12.5100002288818	1936.66687011719	10.3941662237048	6.11707335337996	0.122195117175579	48.10806
12.6099996566772	1933.40490722656	10.4777067899704	6.18292670696974	0.1235121935606	48.027028
12.710000038147	1933.88146972656	10.5610173195601	6.24512182548642	0.124756097793579	48.038868
12.8099994659424	1934.52941894531	10.6443278491497	6.30731694400311	0.126000002026558	48.054964
12.9099998474121	1932.9404296875	10.7276374474168	6.36951206251979	0.127243906259537	48.015492
13.0100002288818	1933.58386230469	10.8109479770064	6.43902458250523	0.128634139895439	48.031476
13.1099996566772	1930.6494140625	10.8944894745946	6.504877936095	0.129951223731041	47.95858
13.210000038147	1931.09252929688	10.9780300408602	6.56707305461168	0.13119512796402	47.969588
13.3099994659424	1929.72680664063	11.0611096024513	6.63292687386274	0.13251219689846	47.935664
13.4099998474121	1927.48999023438	11.1446501687169	6.69512199237943	0.133756101131439	47.8801
13.5100002288818	1927.017578125	11.2281916663051	6.76463404670358	0.135146349668503	47.868364
13.6099996566772	1928.27014160156	11.3115021958947	6.83048786595464	0.136536583304405	47.89948
13.710000038147	1927.20068359375	11.3950427621603	6.89268298447132	0.137780487537384	47.872912
13.8099994659424	1927.6083984375	11.4785842597485	6.95853680372238	0.139024391770363	47.88304
13.9099998474121	1926.08972167969	11.5618938580155	7.02439015731215	0.140341460704803	47.845316
14.0100002288818	1924.19714355469	11.6452043876052	7.08658527582884	0.141585364937782	47.798304
14.1099996566772	1925.07470703125	11.7287458851933	7.15609779581428	0.143048778176308	47.8201
14.210000038147	1924.71899414063	11.8120554834604	7.22560985013843	0.144292682409287	47.811264
14.3099994659424	1923.38879394531	11.8955969810486	7.28414626792073	0.145536586642265	47.778224
14.4099998474121	1921.59912109375	11.9786765426397	7.34634138643742	0.146853655576706	47.733764
14.5100002288818	1921.42993164063	12.0619861409068	7.41219520568848	0.148097559809685	47.729564
14.6099996566772	1918.65002441406	12.1452966704965	7.48902419582009	0.14956097304821	47.660508
14.710000038147	1918.42443847656	12.2286072000861	7.55853671580553	0.151024386286736	47.654904
14.8099994659424	1919.24987792969	12.3116867616773	7.63170747086406	0.152487799525261	47.675408
14.9099998474121	1916.91125488281	12.3949963599443	7.70121952518821	0.153878048062325	47.617316
15.0100002288818	1919.75634765625	12.478306889534	7.77439028024673	0.15534146130085	47.687992
15.1099996566772	1919.31665039063	12.5616174191237	7.84390233457088	0.156731694936752	47.677068
15.210000038147	1916.0693359375	12.6449279487133	7.92804919183254	0.158414632081985	47.596404
15.3099994659424	1915.40466308594	12.7282375469804	8.00121948122978	0.159878045320511	47.579892
15.4099998474121	1915.31604003906	12.81154807657	8.0743907019496	0.161268293857574	47.577692
15.5100002288818	1910.93603515625	12.8948586061597	8.13658535480499	0.162585362792015	47.468888
15.6099996566772	1910.07763671875	12.9783991724253	8.20243917405605	0.16397562623024	47.447564
15.710000038147	1908.05554199219	13.0614787340164	8.27560946345329	0.165292680263519	47.397336
15.8099994659424	1909.54821777344	13.1450202316046	8.33780504763126	0.16660974919796	47.434412
15.9099998474121	1905.91467285156	13.2285607978702	8.41463450342417	0.168146342039108	47.344156
16.0100002288818	1907.20690917969	13.3116403594613	8.4914630278945	0.169682934880257	47.376256
16.1100006103516	1906.57104492188	13.394950889051	8.56097601354122	0.171073168516159	47.36046
16.2099990844727	1905.69982910156	13.4784914553165	8.63048806786537	0.172463417053223	47.338816
16.3099994659424	1901.962890625	13.5615710169077	8.70000012218952	0.173780485987663	47.245988
16.4099998474121	1905.59729003906	13.6451125144959	8.77317041158676	0.175317078828812	47.336272
16.5100002288818	1902.57177734375	13.7284221127629	8.84268339723349	0.176707327365875	47.261116
16.6100006103516	1903.50610351563	13.8115016743541	8.91219545155764	0.178097561001778	47.284324
16.7099990844727	1900.98645019531	13.8950431719422	8.98170750588179	0.179560959339142	47.221732
16.8099994659424	1897.603515625	13.9785837382078	9.05121956020594	0.180878043174744	47.1377
16.9099998474121	1896.73986816406	14.061663299799	9.13170725107193	0.182414636015892	47.116244
17.0100002288818	1893.7607421875	14.1449738293886	9.20487847179174	0.18395122885704	47.042244
17.1100006103516	1892.89428710938	14.2282843589783	9.27804876118898	0.185341462492943	47.02072
17.2099990844727	1892.03442382813	14.3111329525709	9.34756081551313	0.186878055334091	46.99936
17.3099994659424	1892.36572265625	14.394442550838	9.42439027130604	0.188341453671455	47.007588
17.4099998474121	1891.81396484375	14.4775221124291	9.49756056070328	0.189878046512604	46.993884
17.5100002288818	1892.29211425781	14.5606016740203	9.57439001649618	0.19134147465229	47.00576
17.6100006103516	1888.8994140625	14.6436812356114	9.647561237216	0.192804872989655	46.921484
17.7099990844727	1886.908203125	14.7267607972026	9.72073152661324	0.194268301129341	46.87202
17.8099994659424	1888.82067871094	14.8098403587937	9.79756098240614	0.195731699466705	46.919528
17.9099998474121	1884.87072753906	14.8931508883834	9.87073127180338	0.197268292307854	46.821408
18.0100002288818	1881.1904296875	14.9764604866505	9.94756072759628	0.198804885149002	46.729988
18.1100006103516	1879.47644042969	15.0595400482416	10.0170727819204	0.200268298387527	46.687412
18.2099990844727	1880.80798339844	15.1428505778313	10.097561404109	0.201731711626053	46.720488
18.3099994659424	1877.91809082031	15.2261611074209	10.1743899285793	0.203341469168663	46.6487
18.4099998474121	1878.2705078125	15.309470705688	10.2475611492991	0.204878032207489	46.657456
18.5100002288818	1877.35363769531	15.3927812352777	10.3317070752382	0.206414625048637	46.63468
18.6100006103516	1873.77233886719	15.4763227328658	10.4121947661042	0.208024382591248	46.545716
18.7099990844727	1874.51940917969	15.5596323311329	10.4817077517509	0.209487810730934	46.564276
18.8099994659424	1873.5361328125	15.643173828721	10.5512198060751	0.210878044366837	46.539852
18.9099998474121	1872.02502441406	15.7267153263092	10.6317074969411	0.212560966610909	46.502312
19.0100002288818	1870.06640625	15.8102549612522	10.708536952734	0.214024394750595	46.45366
19.1100006103516	1865.68957519531	15.8937964588404	10.7817072421312	0.215487793087959	46.344936
19.2099990844727	1865.62487792969	15.97710698843	10.854878462851	0.216951221227646	46.343328
19.3099994659424	1863.49841308594	16.0604175180197	10.9317069873214	0.218487814068794	46.290508
19.4099998474121	1860.17529296875	16.1437280476093	11.0121946781874	0.220097571611404	46.20796
19.5100002288818	1858.00219726563	16.2272676825523	11.096341535449	0.221707314252853	46.153976
19.6100006103516	1855.96203613281	16.3103472441435	11.1695118248463	0.223317071795464	46.1033
19.7099990844727	1856.52612304688	16.3938887417316	11.2536586821079	0.224926829338074	46.117312
19.8099994659424	1853.7548828125	16.4771992713213	11.3304881379008	0.226463407278061	46.048472
19.9099998474121	1852.88757324219	16.5602788329124	11.4109758287668	0.228073164820671	46.026928
20.0100002288818	1851.61730957031	16.6435893625021	11.4914635196328	0.229682922363281	45.995372
20.1100006103516	1847.84362792969	16.7266689240932	11.5682929754257	0.231146350502968	45.901632
20.2099990844727	1847.64807128906	16.8097484856844	11.645121499896	0.232756108045578	45.896772
20.3099994659424	1844.37658691406	16.8928280472755	11.7292683571577	0.234439015388489	45.815508
20.4099998474121	1840.41137695313	16.9761385768652	11.8097560480237	0.236048772931099	45.717008
20.5100002288818	1836.46240234375	17.0589871704578	11.8902437388897	0.23765854537487	45.618916
20.6100006103516	1834.94653320313	17.1422958374023	11.9707314297557	0.239341467618942	45.58126
20.7099990844727	1833.20373535156	17.225606366992	12.0548782870173	0.240951210260391	45.537968
20.8099994659424	1829.89270019531	17.3086859285831	12.1317077428102	0.242414638400078	45.45572
20.9099998474121	1828.65441894531	17.3919964581728	12.2158536687493	0.24409756064415	45.42496
21.0100002288818	1824.35278320313	17.4750760197639	12.2999995946884	0.245853662490845	45.318104
21.1100006103516	1824.66455078125	17.5583865493536	12.3841464519501	0.247536584734917	45.325848
21.2099990844727	1822.06481933594	17.6416970789433	12.4646341428161	0.249146342277527	45.261268
21.3099994659424	1818.7763671875	17.7250076085329	12.5487800687552	0.25082927942276	45.179584
21.4099998474121	1814.478515625	17.8083162754774	12.6292686909437	0.252439022064209	45.07282
21.5100002288818	1810.37878417969	17.8918577730656	12.7134146168828	0.254121959209442	44.97098
21.6100006103516	1804.34936523438	17.9749373346567	12.8012197092175	0.255804896354675	44.821208
21.7099990844727	1796.98498535156	18.0584788322449	12.8853656351566	0.257560968399048	44.638272
21.8099994659424	1792.416015625	18.142020329833	12.9658533260226	0.259170740842819	44.524772
21.9099998474121	1786.81201171875	18.2253308594227	13.0500001832843	0.26085364818573	44.385568
22.0100002288818	1782.04760742188	18.3088704943657	13.1341461092234	0.262536585330963	44.267216
22.1100006103516	1775.67175292969	18.3924119919539	13.2219512015581	0.264292687177658	44.108836
22.2099990844727	1768.16711425781	18.4757225215435	13.313414528966	0.266121953725815	43.922416
22.3099994659424	1763.90747070313	18.5592640191317	13.4048778563738	0.26787805557251	43.816604
22.4099998474121	1752.48059082031	18.6425745487213	13.4963411837816	0.269707322120667	43.532752
22.5100002288818	1736.65783691406	18.7258832156658	13.5914636775851	0.271682918071747	43.139704
22.6100006103516	1709.06799316406	18.8091937452555	13.701219111681	0.273731708526611	42.454356
22.7000007629395	-4.26045942306519	18.883965909481	14.1000002622604	0.282219529151917	-0.1058325703125