File: Tensile_tests/Benchmark/PA12_XY_8 05-16-22 10 37 10 AM/DAQ- Time, … - (Timed).txt
File Path: C:\MTS TestSuite\Data Files\Chahine\DOE\PA12_XY_8 05-16-22 10 37 10 AM\DAQ- Time, … - (Timed).txt
Test: MTS EM Tension (Extensometer)_Grand_Chahine 1
Test Run: PA12_XY_8
Date: 5/16/2022 10:36:38 AM


Time 	Load 	Crosshead 	Extensometer 	Strain 	Stress
sec	N	mm	mm	mm/mm	N/mm²
0.100000001490116	26.9314670562744	0.0376165407942608	0.0109756101664971	7.31707332306542E-05	0.6463810625
0.200000002980232	85.3984451293945	0.120696022349875	0.0439024406659883	0.000804878072813153	2.049644625
0.300000011920929	148.928314208984	0.204467825824395	0.0695121925673448	0.0013170731253922	3.5744225
0.400000005960464	206.730895996094	0.288008857751265	0.0951219481066801	0.00190243893302977	4.96174
0.5	267.577697753906	0.371549889678136	0.124390237033367	0.00248780474066734	6.4221215
0.600000023841858	325.219543457031	0.454860157333314	0.164634140674025	0.00321951229125261	7.8055815
0.699999988079071	382.787994384766	0.538170395884663	0.226829273742624	0.00446341466158628	9.187279
0.800000011920929	439.294555664063	0.621711427811533	0.274390244157985	0.00541463447734714	10.543491
0.899999976158142	493.767242431641	0.705021666362882	0.310975621687248	0.00614634156227112	11.850888
1	550.149597167969	0.788331963121891	0.340243888786063	0.00673170713707805	13.204118
1.10000002384186	604.417846679688	0.871642201673239	0.373170740203932	0.00739024393260479	14.506609
1.20000004768372	656.154174804688	0.954952440224588	0.402439036406577	0.00797560997307301	15.74833
1.29999995231628	707.156921386719	1.03849347215146	0.435365858720616	0.00863414630293846	16.972446
1.39999997615814	761.34521484375	1.12203450407833	0.468292681034654	0.00929268263280392	18.273016
1.5	812.737365722656	1.20534480083734	0.501219532452524	0.00995121896266937	19.506478
1.60000002384186	861.16259765625	1.28888583276421	0.526829273439944	0.0104634147137403	20.66873
1.70000004768372	910.868408203125	1.37242686469108	0.567073177080601	0.0112682934850454	21.861716
1.79999995231628	959.068603515625	1.45573704503477	0.596341444179416	0.0118536585941911	23.018568
1.89999997615814	1008.16363525391	1.53927807696164	0.625609769485891	0.0125121958553791	24.196896
2	1054.66748046875	1.62258837372065	0.658536562696099	0.0130975609645247	25.313032
2.09999990463257	1102.58752441406	1.70589867047966	0.698780466336757	0.0139024388045073	26.46316
2.20000004768372	1151.115234375	1.78920885082334	0.73536584386602	0.0145609760656953	27.62787
2.29999995231628	1193.12829589844	1.87251914758235	0.764634169172496	0.0152195114642382	28.636224
2.40000009536743	1241.40014648438	1.95559859275818	0.797560962382704	0.0158780477941036	29.794796
2.5	1283.75891113281	2.03890888951719	0.830487813800573	0.0165365859866142	30.811446
2.59999990463257	1330.40893554688	2.1222191862762	0.863414607010782	0.0171219520270824	31.931092
2.70000004768372	1373.37878417969	2.2052985150367	0.896341458428651	0.0178536586463451	32.96241
2.79999995231628	1413.25219726563	2.28837807662785	0.925609783735126	0.0184390246868134	33.919408
2.90000009536743	1454.00634765625	2.37168837338686	0.958536576945335	0.0191707313060761	34.897548
3	1494.72253417969	2.4545369669795	0.991463428363204	0.0197560973465443	35.874776
3.09999990463257	1532.958984375	2.53784726373851	1.02804880589247	0.020487803965807	36.792488
3.20000004768372	1569.11791992188	2.62092682532966	1.06463418342173	0.0211463421583176	37.660336
3.29999995231628	1610.34399414063	2.70400638692081	1.10121956095099	0.0219512190669775	38.6498
3.40000009536743	1645.83435058594	2.78731645084918	1.13780482206494	0.022609755396843	39.501604
3.5	1682.20031738281	2.87039601244032	1.1743901995942	0.023414634168148	40.374424
3.59999990463257	1717.17602539063	2.95347557403147	1.20365852490067	0.0240000002086163	41.213872
3.70000004768372	1747.21899414063	3.03701660595834	1.24390248674899	0.0248048789799213	41.934932
3.79999995231628	1776.00366210938	3.12032666988671	1.28048774786294	0.025536585599184	42.625792
3.90000009536743	1804.8916015625	3.20363696664572	1.3170731253922	0.0262682922184467	43.319132
4	1831.60266113281	3.28717799857259	1.35365850292146	0.0270000007003546	43.960224
4.09999990463257	1859.30407714844	3.37071903049946	1.39390246476978	0.0278048776090145	44.625084
4.19999980926514	1882.48767089844	3.45379859209061	1.44146336242557	0.0287560969591141	45.181512
4.30000019073486	1902.66381835938	3.53733962401748	1.48902437649667	0.0297073181718588	45.66576
4.40000009536743	1925.23620605469	3.62064992077649	1.52926833834499	0.0305121950805187	46.207516
4.5	1946.56872558594	3.7039602175355	1.57317076809704	0.0313902422785759	46.71952
4.59999990463257	1961.93505859375	3.78750124946237	1.62073166575283	0.0323414653539658	47.088324
4.69999980926514	1977.49780273438	3.87104228138924	1.66463409550488	0.0332195125520229	47.461844
4.80000019073486	1993.97985839844	3.95412184298038	1.70853664167225	0.0340243875980377	47.857432
4.90000009536743	2005.2451171875	4.03766287490726	1.75609753932804	0.0349756106734276	48.127808
5	2015.51000976563	4.12120390683413	1.80731702130288	0.0360731706023216	48.374176
5.09999990463257	2026.07592773438	4.20428300276399	1.86219508759677	0.0371707305312157	48.627768
5.19999980926514	2034.84716796875	4.28759353235364	1.90975610166788	0.0381219498813152	48.838284
5.30000019073486	2047.17431640625	4.37113456428051	1.96097558364272	0.0391463413834572	49.134148
5.40000009536743	2052.7548828125	4.45398315787315	2.00853659771383	0.040097564458847	49.268088
5.5	2056.8466796875	4.53729368746281	2.0634145475924	0.0411219522356987	49.366296
5.59999990463257	2064.17919921875	4.62037278339267	2.11829273030162	0.0422195121645927	49.542284
5.69999980926514	2070.1962890625	4.7032218426466	2.17682938091457	0.0434634126722813	49.6867
5.80000019073486	2079.31518554688	4.78653190657496	2.22804886288941	0.0444878041744232	49.90556
5.90000009536743	2083.03515625	4.86984197050333	2.28292681276798	0.0455853678286076	49.994844
6	2089.15356445313	4.95246006175876	2.34146346338093	0.0466829240322113	50.141692
6.09999990463257	2091.56323242188	5.03577012568712	2.40000011399388	0.047853659838438	50.199524
6.19999980926514	2093.60766601563	5.11908065527678	2.45121959596872	0.0489512160420418	50.248592
6.30000019073486	2099.744140625	5.20216021686792	2.5060975458473	0.0500487834215164	50.395876
6.40000009536743	2103.22729492188	5.28547028079629	2.56463419646025	0.0511463396251202	50.479476
6.5	2105.95776367188	5.36854984238744	2.61951214633882	0.0522439032793045	50.545008
6.59999990463257	2108.30688476563	5.45162940397859	2.67804879695177	0.0534878075122833	50.601388
6.69999980926514	2112.24438476563	5.53493946790695	2.73658544756472	0.0546585358679295	50.695892
6.80000019073486	2115.3037109375	5.6182499974966	2.79146339744329	0.0557560995221138	50.76932
6.90000009536743	2119.12451171875	5.70156006142497	2.84634158015251	0.0567804872989655	50.861024
7	2121.66284179688	5.78487012535334	2.90487799793482	0.0580243915319443	50.921944
7.09999990463257	2127.53198242188	5.86794968694448	2.95975618064404	0.0590487793087959	51.062812
7.19999980926514	2130.01953125	5.95126021653414	3.02195129916072	0.0602926835417748	51.122512
7.30000019073486	2134.30419921875	6.03480124846101	3.08048771694303	0.0615365840494633	51.225348
7.40000009536743	2131.68530273438	6.11811131238937	3.14268283545971	0.06270731985569	51.162492
7.5	2134.9619140625	6.20142137631774	3.19390255026519	0.063804879784584	51.241136
7.59999990463257	2135.998046875	6.28473190590739	3.2524389680475	0.0649024397134781	51.266004
7.69999980926514	2138.92724609375	6.36804196983576	3.31463408656418	0.0661463439464569	51.336308
7.80000019073486	2139.19018554688	6.45135249942541	3.38048790581524	0.0674634128808975	51.34262
7.90000009536743	2140.43579101563	6.53466256335378	3.44268302433193	0.068634144961834	51.372512
8	2141.3125	6.61797309294343	3.4975609742105	0.0698048770427704	51.393556
8.10000038146973	2145.09936523438	6.7012831568718	3.55609762482345	0.0709756091237068	51.484444
8.19999980926514	2148.6923828125	6.78459322080016	3.61463404260576	0.0722195133566856	51.57068
8.30000019073486	2150.06079101563	6.86790375038981	3.67317069321871	0.0733170732855797	51.603524
8.39999961853027	2149.44189453125	6.95098331198096	3.73170734383166	0.0744878053665161	51.588668
8.5	2150.32592773438	7.03429337590933	3.79390246234834	0.0756585374474525	51.609888
8.60000038146973	2151.4892578125	7.11737293750048	3.85243911296129	0.0769756063818932	51.637808
8.69999980926514	2154.044921875	7.20068300142884	3.9109755307436	0.0780731737613678	51.699148
8.80000019073486	2153.48022460938	7.2839935310185	3.96219501271844	0.0790975615382195	51.685592
8.89999961853027	2153.68603515625	7.36730359494686	4.02439013123512	0.0804146379232407	51.690532
9	2155.36547851563	7.45038315653801	4.08292701467872	0.0815853625535965	51.73084
9.10000038146973	2156.92602539063	7.53346271812916	4.1451221331954	0.0827560946345329	51.768296
9.19999980926514	2154.31811523438	7.61677278205752	4.21097548678517	0.0840731710195541	51.705704
9.30000019073486	2157.89379882813	7.70008331164718	4.27317060530186	0.085317075252533	51.791524
9.39999961853027	2160.7666015625	7.78362434357405	4.33902442455292	0.0866341516375542	51.860472
9.5	2160.18408203125	7.86693394184113	4.39024390652776	0.0876585394144058	51.846492
9.60000038146973	2160.50268554688	7.95024447143078	4.45243902504444	0.0889756083488464	51.85414
9.69999980926514	2161.5615234375	8.03355500102043	4.51463414356112	0.0902195125818253	51.879552
9.80000019073486	2162.05346679688	8.11686553061008	4.57682926207781	0.0914634093642235	51.89136
9.89999961853027	2160.39868164063	8.20040609687567	4.63536567986012	0.0926341488957405	51.851644
10	2162.1171875	8.28394759446383	4.70121949911118	0.0938048809766769	51.892888
10.1000003814697	2161.40600585938	8.36748816072941	4.77073155343533	0.0951951146125793	51.87582
10.1999998092651	2159.85009765625	8.45079869031906	4.82926843687892	0.0964390188455582	51.838476
10.3000001907349	2159.09741210938	8.53433925658464	4.89512179046869	0.0977560952305794	51.820412
10.3999996185303	2160.6201171875	8.6176497861743	4.95731690898538	0.0990731716156006	51.856956
10.5	2158.037109375	8.70096031576395	5.02682942897081	0.100390240550041	51.794964
10.6000003814697	2162.12133789063	8.78473185002804	5.0890245474875	0.101707316935062	51.892988
10.6999998092651	2161.8134765625	8.86781141161919	5.15121966600418	0.102951221168041	51.8856
10.8000001907349	2160.35473632813	8.95112194120884	5.22439042106271	0.104341462254524	51.850588
10.8999996185303	2160.9677734375	9.03443153947592	5.28292683884501	0.105512201786041	51.8653
11	2162.88598632813	9.11751110106707	5.34146325662732	0.106756098568439	51.91134
11.1000003814697	2160.74658203125	9.20082163065672	5.403658375144	0.108000002801418	51.859992
11.1999998092651	2160.62426757813	9.2843621969223	5.47317089512944	0.109317071735859	51.857056
11.3000001907349	2159.13891601563	9.36767272651196	5.53536601364613	0.11063414812088	51.821408
11.3999996185303	2159.51416015625	9.45098325610161	5.59390243142843	0.111878052353859	51.830412
11.5	2158.23950195313	9.53429378569126	5.66341448575258	0.113121949136257	51.79982
11.6000003814697	2156.48461914063	9.61760338395834	5.72926830500364	0.114439025521278	51.7577
11.6999998092651	2156.95483398438	9.70091391354799	5.7951221242547	0.115682929754257	51.768988
11.8000001907349	2160.55688476563	9.78445447981358	5.85731724277139	0.116999998688698	51.85544
11.8999996185303	2155.35180664063	9.86753404140472	5.92317059636116	0.118317075073719	51.730512
12	2156.62036132813	9.95084457099438	5.98902441561222	0.11963415145874	51.76096
12.1000003814697	2158.23510742188	10.0343860685825	6.05487823486328	0.120951220393181	51.799716
12.1999998092651	2154.53198242188	10.1176956668496	6.12073158845305	0.122268289327621	51.710836
12.3000001907349	2154.06713867188	10.2012371644378	6.17560977116227	0.123365856707096	51.69968
12.3999996185303	2151.4609375	10.2845467627048	6.2487805262208	0.124756097793579	51.637128
12.5	2152.06225585938	10.3678572922945	6.30731694400311	0.126000002026558	51.65156
12.6000003814697	2147.41284179688	10.4513987898827	6.37317076325417	0.127317070960999	51.539968
12.6999998092651	2148.46459960938	10.5349393561482	6.43902458250523	0.128634139895439	51.565212
12.8000001907349	2148.31616210938	10.6180189177394	6.50853663682938	0.130024388432503	51.561652
12.8999996185303	2144.89038085938	10.7015604153275	6.57804869115353	0.131414636969566	51.479428
13	2145.50512695313	10.7851009815931	6.64390251040459	0.132731705904007	51.494184
13.1000003814697	2147.6015625	10.8684115111828	6.71341456472874	0.134121954441071	51.5445
13.1999998092651	2145.73950195313	10.9519520774484	6.7792683839798	0.135439023375511	51.499808
13.3000001907349	2144.07153320313	11.035262607038	6.84878043830395	0.136756092309952	51.459776
13.3999996185303	2146.40795898438	11.1185731366277	6.91463425755501	0.138219505548477	51.515852
13.5	2141.34423828125	11.2018827348948	6.98048761114478	0.139536589384079	51.394316
13.6000003814697	2142.06909179688	11.2854242324829	7.05000013113022	0.14085365831852	51.411716
13.6999998092651	2141.60668945313	11.3685037940741	7.1121952496469	0.142097562551498	51.400616
13.8000001907349	2136.568359375	11.4520443603396	7.18536600470543	0.143560975790024	51.279692
13.8999996185303	2137.88891601563	11.5351239219308	7.24756112322211	0.144878044724464	51.311388
14	2135.42407226563	11.6184344515204	7.31341447681189	0.146121948957443	51.252228
14.1000003814697	2131.97021484375	11.7017449811101	7.37560959532857	0.147365853190422	51.169332
14.1999998092651	2131.90185546875	11.7848245427012	7.44146341457963	0.148682922124863	51.167692
14.3000001907349	2133.23974609375	11.8681341409683	7.51097546890378	0.150073170661926	51.1998
14.3999996185303	2131.37670898438	11.951444670558	7.58414622396231	0.151536583900452	51.155088
14.5	2130.33984375	12.0347552001476	7.66097567975521	0.1530731767416	51.1302
14.6000003814697	2128.43774414063	12.1180647984147	7.7414633706212	0.154609754681587	51.084548
14.6999998092651	2127.51489257813	12.2016062960029	7.81097542494535	0.156073167920113	51.0624
14.8000001907349	2124.6845703125	12.2849168255925	7.8804874792695	0.157536581158638	50.994468
14.8999996185303	2124.11010742188	12.3682264238596	7.95365869998932	0.158926829695702	50.98068
15	2122.05786132813	12.4517679214478	8.01951251924038	0.160243898630142	50.931424
15.1000003814697	2121.267578125	12.5353084877133	8.10000021010637	0.161853656172752	50.91246
15.1999998092651	2120.69091796875	12.6183880493045	8.16951226443052	0.163243889808655	50.898616
15.3000001907349	2117.42138671875	12.7019295468926	8.24268255382776	0.164634138345718	50.820148
15.3999996185303	2116.04052734375	12.7850091084838	8.31585377454758	0.166170731186867	50.787004
15.5	2119.33251953125	12.8683187067509	8.39268323034048	0.167707324028015	50.866016
15.6000003814697	2116.39916992188	12.951860204339	8.46585351973772	0.169170737266541	50.795612
15.6999998092651	2115.42236328125	13.0349397659302	8.53536557406187	0.170560985803604	50.772168
15.8000001907349	2113.42578125	13.1182493641973	8.60487762838602	0.171951219439507	50.724248
15.8999996185303	2112.37084960938	13.2017908617854	8.67439061403275	0.173414632678032	50.698928
16	2110.11669921875	13.2851013913751	8.75121913850307	0.174878060817719	50.644828
16.1000003814697	2107.92407226563	13.3681809529662	8.82439035922289	0.176268294453621	50.5922
16.2000007629395	2106.99926757813	13.4514905512333	8.89390241354704	0.177658528089523	50.570004
16.2999992370605	2103.82739257813	13.5345701128244	8.97073186933994	0.179268285632133	50.493876
16.3999996185303	2103.27954101563	13.6176496744156	9.02926828712225	0.180512204766274	50.480728
16.5	2101.2333984375	13.7009602040052	9.11341421306133	0.182048767805099	50.43162
16.6000003814697	2099.51684570313	13.7842707335949	9.20487847179174	0.184024393558502	50.39042
16.7000007629395	2100.90356445313	13.8671193271875	9.27439052611589	0.185341462492943	50.423704
16.7999992370605	2099.513671875	13.9504289254546	9.34756081551313	0.186804890632629	50.390344
16.8999996185303	2095.49462890625	14.0335084870458	9.42073203623295	0.188195124268532	50.293884
17	2096.48510742188	14.1165880486369	9.49390232563019	0.189731702208519	50.317656
17.1000003814697	2095.0810546875	14.1998985782266	9.57439001649618	0.19134147465229	50.283956
17.2000007629395	2093.74877929688	14.2832091078162	9.65121947228909	0.192878037691116	50.25198
17.2999992370605	2090.56982421875	14.3662877380848	9.72073152661324	0.194341465830803	50.175684
17.3999996185303	2088.92578125	14.4495982676744	9.80121921747923	0.195878058671951	50.136224
17.5	2087.419921875	14.5329087972641	9.87439043819904	0.197341457009315	50.100084
17.6000003814697	2085.56494140625	14.6162193268538	9.95121989399195	0.198878049850464	50.05556
17.7000007629395	2080.47875976563	14.6997598931193	10.035365819931	0.200487807393074	49.933488
17.7999992370605	2083.31567382813	14.783070422709	10.1121952757239	0.202097564935684	50.001576
17.8999996185303	2082.08715820313	14.8666109889746	10.1853655651212	0.20356097817421	49.972092
18	2080.37744140625	14.9501524865627	10.2621950209141	0.20517073571682	49.931056
18.1000003814697	2078.94116210938	15.0334630161524	10.3426827117801	0.206707328557968	49.896584
18.2000007629395	2077.39770507813	15.117003582418	10.4304878041148	0.208463400602341	49.85954
18.2999992370605	2073.80297851563	15.2005450800061	10.5036580935121	0.209926828742027	49.773264
18.3999996185303	2073.65942382813	15.2838546782732	10.580487549305	0.211390241980553	49.769816
18.5	2068.27856445313	15.3671652078629	10.6536587700248	0.212853670120239	49.640672
18.6000003814697	2068.43603515625	15.4507057741284	10.7304882258177	0.214463412761688	49.644452
18.7000007629395	2066.31713867188	15.5340163037181	10.8109759166837	0.216073170304298	49.593596
18.7999992370605	2064.01977539063	15.6173268333077	10.887804441154	0.217682927846909	49.538456
18.8999996185303	2059.43872070313	15.7006364315748	10.9682930633426	0.219292670488358	49.428508
19	2055.92016601563	15.783715993166	11.0451215878129	0.220756098628044	49.344056
19.1000003814697	2057.44604492188	15.8670265227556	11.1182928085327	0.22221951186657	49.38068
19.2000007629395	2057.89575195313	15.9503370523453	11.2024387344718	0.22382926940918	49.391472
19.2999992370605	2052.30859375	16.0334166139364	11.2829264253378	0.225439012050629	49.257376
19.3999996185303	2053.59155273438	16.1164961755276	11.3634150475264	0.227121949195862	49.288168
19.5	2052.54125976563	16.1998067051172	11.4475609734654	0.228804871439934	49.26296
19.6000003814697	2050.57470703125	16.2828862667084	11.5280486643314	0.230487808585167	49.21576
19.7000007629395	2048.27416992188	16.3659658282995	11.6085363551974	0.232024401426315	49.160548
19.7999992370605	2043.04125976563	16.449274495244	11.6853658109903	0.233560964465141	49.034952
19.8999996185303	2041.69299316406	16.5323540568352	11.7548778653145	0.234951227903366	49.002592
20	2038.92175292969	16.6154336184263	11.8317073211074	0.236487805843353	48.93608
20.1000003814697	2037.10339355469	16.698744148016	11.9158532470465	0.238097548484802	48.892436
20.2000007629395	2035.93566894531	16.7818237096071	12.0036583393812	0.239926844835281	48.864412
20.2999992370605	2031.96020507813	16.8651342391968	12.0841460302472	0.241609752178192	48.768996
20.3999996185303	2034.05676269531	16.9486757367849	12.1609754860401	0.243146345019341	48.819316
20.5	2029.69409179688	17.0317552983761	12.2487805783749	0.244756102561951	48.714608
20.6000003814697	2027.3935546875	17.1152949333191	12.3292682692409	0.246439009904861	48.659392
20.7000007629395	2026.99975585938	17.1988364309072	12.4097559601069	0.24797560274601	48.64994
20.7999992370605	2023.64953613281	17.2819159924984	12.4902436509728	0.24958536028862	48.569532
20.8999996185303	2019.63720703125	17.3654574900866	12.5707313418388	0.251195102930069	48.473232
21	2018.29370117188	17.4489989876747	12.6512199640274	0.252878040075302	48.440988
21.1000003814697	2015.37121582031	17.5320785492659	12.7353658899665	0.254634141921997	48.370844
21.2000007629395	2011.20031738281	17.6156181842089	12.8195118159056	0.25631707906723	48.27074
21.2999992370605	2009.37243652344	17.699159681797	12.9036586731672	0.257926821708679	48.226868
21.3999996185303	2004.24609375	17.7824702113867	12.9878045991063	0.259463429450989	48.103832
21.5	2002.3994140625	17.8660117089748	13.0682922899723	0.2611463367939	48.059508
21.6000003814697	2001.42749023438	17.9493222385645	13.1487809121609	0.262829273939133	48.03618
21.7000007629395	1997.30126953125	18.0324018001556	13.2329268381	0.264585375785828	47.937148
21.7999992370605	1996.24792480469	18.1159414350986	13.313414528966	0.266121953725815	47.911868
21.8999996185303	1988.64916992188	18.1992519646883	13.3975613862276	0.26787805557251	47.729488
22	1987.24487304688	18.2823315262794	13.4817073121667	0.269487798213959	47.695784
22.1000003814697	1980.408203125	18.3656420558691	13.5658532381058	0.271170735359192	47.5317
22.2000007629395	1977.40954589844	18.4487216174603	13.6500000953674	0.272707313299179	47.459728
22.2999992370605	1972.38793945313	18.5318011790514	13.7378051877022	0.274536579847336	47.339204
22.3999996185303	1964.83508300781	18.6151117086411	13.8182928785682	0.276146352291107	47.157928
22.5	1959.60437011719	18.6981912702322	13.9060979709029	0.277975618839264	47.032388
22.6000003814697	1953.05151367188	18.7810398638248	13.9865856617689	0.279585361480713	46.875112
22.7000007629395	1942.83312988281	18.8643503934145	14.0780489891768	0.281341463327408	46.62986
22.7999992370605	-4.39826726913452	18.9474299550056	14.3341459333897	0.284560978412628	-0.105562640625