File: Tensile_tests/PA12vp_C2_XZ_5 05-24-22 14 16 13 PM/DAQ- Time, … - (Timed).txt
File Path: C:\MTS TestSuite\Data Files\Chahine\DOE\PA12vp_C2_XZ_5 05-24-22 14 16 13 PM\DAQ- Time, … - (Timed).txt
Test: MTS EM Tension (Extensometer)_Grand_Chahine 1
Test Run: PA12vp_C2_XZ_5
Date: 5/24/2022 2:15:39 PM


Time 	Load 	Crosshead 	Extensometer 	Strain 	Stress
sec	N	mm	mm	mm/mm	N/mm²
0.110000155866146	48.6927261352539	0.0639250429230742	0.0109756101664971	0.00021951220696792	1.24997375
0.210000157356262	102.898262023926	0.146773745655082	0.0402439036406577	0.000804878072813153	2.64146475
0.310000151395798	158.960464477539	0.230545556405559	0.0731707332306542	0.00139024388045073	4.08061775
0.410000145435333	209.516342163086	0.314317352604121	0.102439022157341	0.00204878044314682	5.37842
0.510000169277191	262.484252929688	0.397858384530991	0.13902438513469	0.00278048776090145	6.73814
0.610000133514404	313.070983886719	0.48116865218617	0.179268288775347	0.00351219531148672	8.0367345
0.710000157356262	363.875	0.56470965500921	0.215853651752695	0.0042439023964107	9.340906
0.81000018119812	412.727203369141	0.648019951768219	0.252439029281959	0.00497560948133469	10.594974
0.910000145435333	462.076721191406	0.731099396944046	0.292682932922617	0.0057804873213172	11.861808
1.01000010967255	512.710571289063	0.814409693703055	0.332926836563274	0.00658536562696099	13.161611
1.1100001335144	561.564331054688	0.897489138878882	0.365853658877313	0.00724390242248774	14.415719
1.21000015735626	606.50537109375	0.980337848886848	0.402439036406577	0.00797560997307301	15.569384
1.31000018119812	654.91943359375	1.06341729406267	0.435365858720616	0.00863414630293846	16.812204
1.41000020503998	699.269653320313	1.14672759082168	0.471951207146049	0.00929268263280392	17.950704
1.51000010967255	745.388305664063	1.22980703599751	0.504878058563918	0.0100243911147118	19.1346
1.6100001335144	792.183288574219	1.31311733275652	0.541463436093181	0.0107560968026519	20.335856
1.71000015735626	833.615539550781	1.39619677793235	0.57439022930339	0.0114878043532372	21.39945
1.81000018119812	876.908508300781	1.47950707469136	0.614634132944047	0.0122195119038224	22.510808
1.91000020503998	918.97412109375	1.56258651986718	0.647560984361917	0.0128780491650105	23.590658
2.01000022888184	957.123657226563	1.64589681662619	0.673170725349337	0.0133902439847589	24.569982
2.1100001335144	1000.9560546875	1.72920699696988	0.706097576767206	0.0140487812459469	25.695188
2.21000003814697	1041.18615722656	1.81274802889675	0.74268295429647	0.0147073166444898	26.72792
2.31000018119812	1080.25842285156	1.89628906082362	0.779268273618072	0.0155121944844723	27.730932
2.41000008583069	1115.583984375	1.97959947399795	0.812195125035942	0.0161707326769829	28.637762
2.51000022888184	1153.4208984375	2.06314050592482	0.848780502565205	0.0169756095856428	29.60906
2.6100001335144	1189.47253417969	2.14668153785169	0.885365880094469	0.0176341459155083	30.534528
2.71000003814697	1225.00085449219	2.22999160178006	0.921951199416071	0.0182926822453737	31.446562
2.81000018119812	1259.09130859375	2.31353263370693	0.954878050833941	0.0190243907272816	32.321686
2.91000008583069	1292.353515625	2.39684293046594	0.998780480585992	0.0199024379253387	33.17555
3.01000022888184	1326.39184570313	2.48038396239281	1.03536585811526	0.0206341445446014	34.049336
3.1100001335144	1354.97875976563	2.56369425915182	1.07195123564452	0.0213658530265093	34.78318
3.21000003814697	1384.02758789063	2.64700455591083	1.10853661317378	0.0220975615084171	35.52888
3.31000018119812	1414.37353515625	2.7305455878377	1.14146340638399	0.0228292681276798	36.30788
3.41000008583069	1441.12341308594	2.81362514942884	1.1743901995942	0.0234878044575453	36.994568
3.51000022888184	1467.09484863281	2.89716618135571	1.22560979798436	0.0244390238076448	37.661272
3.6100001335144	1494.66833496094	2.98024551011622	1.27317069564015	0.0253170728683472	38.3691
3.71000003814697	1516.23840332031	3.06332507170737	1.31341465748847	0.0261951219290495	38.92282
3.81000018119812	1539.09399414063	3.14663536846638	1.35000003501773	0.0270000007003546	39.509536
3.91000008583069	1561.90563964844	3.22994543239474	1.39024388045073	0.0277317091822624	40.095128
4.01000022888184	1584.54187011719	3.31302499398589	1.42682925797999	0.0284634158015251	40.676212
4.1100001335144	1602.322265625	3.39610455557704	1.48170732427388	0.0294878054410219	41.132648
4.21000003814697	1620.92761230469	3.47918388433754	1.52560975402594	0.0304390229284763	41.61026
4.30999994277954	1632.2587890625	3.56249418109655	1.56951218377799	0.0313170738518238	41.901136
4.41000032424927	1650.04370117188	3.6455737426877	1.61707319784909	0.032195121049881	42.357688
4.51000022888184	1665.42785644531	3.72888403944671	1.64634152315557	0.032926831394434	42.752608
4.6100001335144	1680.294921875	3.81219433620572	1.68658536858857	0.0336585342884064	43.134256
4.71000003814697	1693.78649902344	3.89550440013409	1.73414638265967	0.0346097573637962	43.480592
4.80999994277954	1705.30407714844	3.97858396172524	1.78170728031546	0.0354878045618534	43.776256
4.91000032424927	1719.29907226563	4.0618940256536	1.84390239883214	0.0368048772215843	44.135516
5.01000022888184	1729.4072265625	4.14520455524325	1.8951219972223	0.0378292687237263	44.395
5.1100001335144	1739.54956054688	4.22874558717012	1.94268289487809	0.0387073159217834	44.65536
5.21000003814697	1750.36608886719	4.31228661909699	1.99024379253387	0.0396585389971733	44.933028
5.30999994277954	1760.44470214844	4.39536618068814	2.04146350733936	0.040682926774025	45.191752
5.41000032424927	1765.72778320313	4.47890721261501	2.08536582067609	0.0416341461241245	45.327372
5.51000022888184	1779.01037597656	4.56221727654338	2.1329268347472	0.0425853654742241	45.668344
5.6100001335144	1787.19018554688	4.64552734047174	2.18414631672204	0.043609756976366	45.878324
5.71000003814697	1793.31921386719	4.72906837239861	2.23536579869688	0.0445609763264656	46.035664
5.80999994277954	1799.50610351563	4.81260940432549	2.28292681276798	0.0456585362553597	46.194484
5.91000032424927	1808.96472167969	4.89615043625236	2.3378049954772	0.0466097556054592	46.437292
6.01000022888184	1814.70825195313	4.9792299978435	2.38902447745204	0.0476341471076012	46.584732
6.1100001335144	1819.19763183594	5.06277102977037	2.44024395942688	0.0486585348844528	46.699976
6.21000003814697	1830.15490722656	5.14608155936003	2.48780497349799	0.0496829263865948	46.98126
6.30999994277954	1832.30261230469	5.22939162328839	2.53536575473845	0.0506341457366943	47.036392
6.41000032424927	1841.80261230469	5.31270215287805	2.59024393744767	0.0517317093908787	47.280264
6.51000022888184	1846.87670898438	5.39578124880791	2.64146341942251	0.0526829250156879	47.410516
6.6100001335144	1849.33483886719	5.47886081039906	2.69268290139735	0.0537804886698723	47.47362
6.71000003814697	1855.66528320313	5.56217133998871	2.74390238337219	0.0548048764467239	47.636124
6.80999994277954	1860.85168457031	5.64525043591857	2.7987805660814	0.055902436375618	47.769264
6.91000032424927	1867.42810058594	5.72832999750972	2.85000004805624	0.0568536594510078	47.938084
7.01000022888184	1868.22985839844	5.81140955910087	2.89756106212735	0.0578780472278595	47.958668
7.1100001335144	1873.34802246094	5.89448912069201	2.94878054410219	0.0589024350047112	48.090052
7.21000003814697	1879.037109375	5.97756868228316	3.00000002607703	0.059853658080101	48.236096
7.30999994277954	1881.39318847656	6.06087874621153	3.05853667668998	0.0610243901610374	48.296576
7.41000032424927	1886.69543457031	6.14395830780268	3.10975615866482	0.0620487779378891	48.432688
7.51000022888184	1890.73693847656	6.22703786939383	3.1646341085434	0.0632195100188255	48.536436
7.6100001335144	1896.90832519531	6.31034793332219	3.21951229125261	0.0641707330942154	48.69486
7.71000003814697	1900.05993652344	6.39342749491334	3.27073177322745	0.0652682930231094	48.775764
7.80999994277954	1903.95056152344	6.47650705650449	3.32195125520229	0.0663658529520035	48.87564
7.91000032424927	1903.82153320313	6.56004808843136	3.37317073717713	0.0673902481794357	48.872328
8.01000022888184	1909.11071777344	6.64312765002251	3.42804868705571	0.0684878081083298	49.008104
8.11000061035156	1911.75134277344	6.72643771395087	3.47560970112681	0.0693658590316772	49.075892
8.21000003814697	1913.75708007813	6.80974777787924	3.53048788383603	0.0705365836620331	49.12738
8.3100004196167	1916.88635253906	6.89328880980611	3.58170736581087	0.0715609788894653	49.207712
8.40999984741211	1921.60290527344	6.97636837139726	3.64024401642382	0.0726585388183594	49.328788
8.51000022888184	1921.21569824219	7.05990940332413	3.68780479766428	0.073682926595211	49.318848
8.61000061035156	1929.15161132813	7.14298896491528	3.74634144827724	0.0747804865241051	49.522568
8.71000003814697	1927.8486328125	7.22652999684215	3.80121963098645	0.0759512186050415	49.48912
8.8100004196167	1931.15148925781	7.3098405264318	3.85975604876876	0.0770487785339355	49.573904
8.90999984741211	1933.12585449219	7.39315059036016	3.91463423147798	0.0781463459134102	49.624588
9.01000022888184	1935.63452148438	7.47623015195131	3.97317064926028	0.0793170779943466	49.688988
9.11000061035156	1937.83862304688	7.55977118387818	4.0280488319695	0.0804878026247025	49.745568
9.21000003814697	1939.16442871094	7.64308124780655	4.08658524975181	0.0815853625535965	49.779604
9.3100004196167	1940.77770996094	7.7263917773962	4.14146343246102	0.0826829299330711	49.821016
9.40999984741211	1941.89086914063	7.80970184132457	4.19268291443586	0.0837804824113846	49.849592
9.51000022888184	1946.43347167969	7.89278093725443	4.25121933221817	0.0849512219429016	49.966204
9.61000061035156	1947.29968261719	7.97586049884558	4.31341445073485	0.0861219465732574	49.98844
9.71000003814697	1947.5341796875	8.05917102843523	4.36829263344407	0.0872195139527321	49.99446
9.8100004196167	1949.8330078125	8.14248155802488	4.42682905122638	0.0883902460336685	50.053472
9.90999984741211	1952.07543945313	8.22579115629196	4.48536593466997	0.0896341428160667	50.111036
10.0100002288818	1953.31665039063	8.30887071788311	4.54024411737919	0.0906585305929184	50.1429
10.1100006103516	1952.70642089844	8.39218124747276	4.5987805351615	0.0919024348258972	50.127236
10.210000038147	1955.38134765625	8.47526080906391	4.65000001713634	0.0929268300533295	50.1959
10.3100004196167	1958.03247070313	8.55857133865356	4.71219513565302	0.0941707268357277	50.263956
10.4099998474121	1958.09265136719	8.64188093692064	4.7743902541697	0.0954146310687065	50.265504
10.5100002288818	1956.50219726563	8.7251914665103	4.83292667195201	0.0965121984481812	50.224676
10.6100006103516	1960.3740234375	8.80873296409845	4.89512179046869	0.0977560952305794	50.324068
10.710000038147	1961.07629394531	8.89181159436703	4.94999997317791	0.098853662610054	50.342096
10.8100004196167	1961.5107421875	8.97535309195518	5.00487815588713	0.10002438724041	50.353248
10.9099998474121	1960.08801269531	9.05866362154484	5.06707327440381	0.101195119321346	50.316724
11.0100002288818	1959.79968261719	9.14197321981192	5.12560969218612	0.102439016103745	50.309324
11.1100006103516	1962.39880371094	9.22551471740007	5.18414657562971	0.103609755635262	50.376044
11.210000038147	1962.40380859375	9.30905528366566	5.24999992921948	0.10485365986824	50.376172
11.3100004196167	1964.67932128906	9.39236581325531	5.31219504773617	0.106097564101219	50.434588
11.4099998474121	1965.63610839844	9.47567634284496	5.37439016625285	0.107341468334198	50.459148
11.5100002288818	1966.07556152344	9.55921690911055	5.44024398550391	0.108658537268639	50.470428
11.6100006103516	1966.71569824219	9.6425274387002	5.49878040328622	0.109902441501617	50.48686
11.710000038147	1964.86999511719	9.72606893628836	5.55731728672981	0.111073173582554	50.43948
11.8100004196167	1966.42321777344	9.80937853455544	5.6195124052465	0.11224389821291	50.479352
11.9099998474121	1967.74768066406	9.89292003214359	5.6780488230288	0.113487802445889	50.513352
12.0100002288818	1967.28869628906	9.97599959373474	5.74024394154549	0.114731706678867	50.501572
12.1100006103516	1965.1455078125	10.0593091920018	5.80609776079655	0.115902438759804	50.446552
12.210000038147	1965.89477539063	10.1426197215915	5.86463417857885	0.117146342992783	50.465788
12.3100004196167	1966.83862304688	10.2256992831826	5.92317059636116	0.118317075073719	50.490016
12.4099998474121	1964.93359375	10.3092398494482	5.98902441561222	0.11963415145874	50.441112
12.5100002288818	1967.404296875	10.3923194110394	6.05853646993637	0.121024392545223	50.50454
12.6100006103516	1966.65246582031	10.475629940629	6.11707335337996	0.122268289327621	50.48524
12.710000038147	1966.13891601563	10.5589404702187	6.17926847189665	0.123439021408558	50.472056
12.8100004196167	1965.0322265625	10.6424810364842	6.24512182548642	0.124756097793579	50.443644
12.9099998474121	1963.40234375	10.7257915660739	6.30731694400311	0.126000002026558	50.401804
13.0100002288818	1962.82678222656	10.8091020956635	6.37682946398854	0.127317070960999	50.387032
13.1100006103516	1963.6572265625	10.8924116939306	6.44268281757832	0.128780484199524	50.408348
13.210000038147	1961.40869140625	10.9757222235203	6.50853663682938	0.130024388432503	50.350628
13.3100004196167	1959.81652832031	11.0590327531099	6.57804869115353	0.131414636969566	50.309756
13.4099998474121	1958.58569335938	11.1425733193755	6.64390251040459	0.132658541202545	50.27816
13.5100002288818	1960.22839355469	11.2261148169637	6.71341456472874	0.134121954441071	50.320328
13.6100006103516	1959.0078125	11.3094253465533	6.78292661905289	0.135439023375511	50.288996
13.710000038147	1959.60913085938	11.3929659128189	6.84512173756957	0.136756092309952	50.304432
13.8100004196167	1959.408203125	11.4762764424086	6.91097555682063	0.138073176145554	50.299272
13.9099998474121	1959.86535644531	11.5595860406756	6.97682937607169	0.139390245079994	50.311008
14.0100002288818	1958.02514648438	11.6428965702653	7.03902449458838	0.140707314014435	50.263768
14.1100006103516	1955.85876464844	11.7264380678535	7.10853654891253	0.142024397850037	50.208156
14.210000038147	1954.37438964844	11.8097476661205	7.17804860323668	0.143341451883316	50.170052
14.3100004196167	1953.3544921875	11.8932891637087	7.24390242248774	0.144658535718918	50.143872
14.4099998474121	1953.42517089844	11.9768297299743	7.31341447681189	0.146048784255981	50.145684
14.5100002288818	1951.49975585938	12.0601402595639	7.38658523187041	0.147585362195969	50.09626
14.6100006103516	1950.65368652344	12.1434507891536	7.45609775185585	0.148975610733032	50.07454
14.710000038147	1949.39331054688	12.2267603874207	7.52560980618	0.150365859270096	50.042184
14.8100004196167	1947.32995605469	12.3100709170103	7.59512186050415	0.151829272508621	49.989216
14.9099998474121	1947.31433105469	12.3931504786015	7.66829261556268	0.153219521045685	49.988816
15.0100002288818	1947.57983398438	12.4766919761896	7.73780466988683	0.154536589980125	49.995632
15.1100006103516	1944.43835449219	12.5597706064582	7.81097542494535	0.156073167920113	49.914988
15.210000038147	1944.72216796875	12.6430811360478	7.88414664566517	0.157536581158638	49.922272
15.3100004196167	1941.986328125	12.7263916656375	7.95731693506241	0.158926829695702	49.852044
15.4099998474121	1942.32946777344	12.8094712272286	8.02682898938656	0.16046342253685	49.860852
15.5100002288818	1938.15051269531	12.8927817568183	8.09634104371071	0.161853656172752	49.753576
15.6100006103516	1936.22180175781	12.9760913550854	8.17317049950361	0.163390249013901	49.704064
15.710000038147	1934.82104492188	13.059401884675	8.24634172022343	0.164707317948341	49.668104
15.8100004196167	1933.81848144531	13.1429424509406	8.31585377454758	0.166170731186867	49.642368
15.9099998474121	1932.81103515625	13.2262529805303	8.39268323034048	0.167634159326553	49.616508
16.0100002288818	1931.67114257813	13.3095635101199	8.46951175481081	0.169243901968002	49.587244
16.1100006103516	1930.27429199219	13.3928740397096	8.54634121060371	0.170707315206528	49.551388
16.2100009918213	1928.62072753906	13.4764146059752	8.61951243132353	0.172243893146515	49.50894
16.3099994659424	1924.64794921875	13.5594941675663	8.69268272072077	0.173780485987663	49.406956
16.4099998474121	1924.70581054688	13.6430347338319	8.76951217651367	0.175243899226189	49.40844
16.5100002288818	1920.76098632813	13.72657623142	8.84634163230658	0.176707327365875	49.307176
16.6100006103516	1919.33911132813	13.8096557930112	8.91585368663073	0.178097561001778	49.270676
16.7100009918213	1914.63317871094	13.8929663226008	8.98536574095488	0.179560959339142	49.149868
16.8099994659424	1910.02465820313	13.9765068888664	9.05853696167469	0.181024387478828	49.031568
16.9099998474121	1908.39855957031	14.0598174184561	9.14268288761377	0.1827073097229	48.989824
17.0100002288818	1901.6796875	14.1433579847217	9.22317057847977	0.184390246868134	48.817344
17.1100006103516	1896.32409667969	14.2266685143113	9.30731743574142	0.186000004410744	48.679864
17.2100009918213	4.73964548110962	14.3097480759025	9.51219536364079	0.188048779964447	0.1216697578125