File: Tensile_tests/PA12vp_C2_XY_3 05-24-22 13 55 06 PM/DAQ- Time, … - (Timed).txt
File Path: C:\MTS TestSuite\Data Files\Chahine\DOE\PA12vp_C2_XY_3 05-24-22 13 55 06 PM\DAQ- Time, … - (Timed).txt
Test: MTS EM Tension (Extensometer)_Grand_Chahine 1
Test Run: PA12vp_C2_XY_3
Date: 5/24/2022 1:54:37 PM


Time 	Load 	Crosshead 	Extensometer 	Strain 	Stress
sec	N	mm	mm	mm/mm	N/mm²
0.100000001490116	48.7748336791992	0.0620788341620937	0.0146341462823329	0.00021951220696792	1.256856625
0.200000002980232	107.288642883301	0.145158308441751	0.04756097405334	0.00087804882787168	2.7646725
0.300000011920929	161.681823730469	0.229160898015834	0.0804878072813153	0.00146341463550925	4.16630575
0.400000005960464	219.355728149414	0.312932708766311	0.109756096208002	0.00212195119820535	5.6524785
0.5	273.952972412109	0.396473740693182	0.146341466461308	0.00285365851595998	7.05937
0.600000023841858	325.266387939453	0.47978397924453	0.179268288775347	0.00351219531148672	8.381642
0.699999988079071	378.989105224609	0.56309427600354	0.215853651752695	0.0042439023964107	9.765999
0.800000011920929	432.153137207031	0.646404514554888	0.256097555393353	0.0050487807020545	11.135958
0.899999976158142	481.884552001953	0.729253224562854	0.292682932922617	0.00570731703191996	12.417465
1	531.411682128906	0.81233266973868	0.32926828134805	0.00651219487190247	13.693707
1.10000002384186	582.278137207031	0.895642966497689	0.365853658877313	0.00724390242248774	15.004461
1.20000004768372	631.332458496094	0.978722469881177	0.402439036406577	0.00797560997307301	16.26852
1.29999995231628	682.201965332031	1.06203265022486	0.43902438483201	0.00863414630293846	17.579354
1.39999997615814	729.868469238281	1.14511221181601	0.471951207146049	0.00936585385352373	18.80765
1.5	775.4814453125	1.22819165699184	0.508536584675312	0.010097561404109	19.98303
1.60000002384186	820.81201171875	1.31150183733553	0.541463436093181	0.0107560968026519	21.151132
1.70000004768372	865.50341796875	1.39458139892668	0.578048755414784	0.0114878043532372	22.302766
1.79999995231628	909.803649902344	1.47812243085355	0.614634132944047	0.0121463416144252	23.444318
1.89999997615814	953.107543945313	1.56166346278042	0.647560984361917	0.0128780491650105	24.560196
2	996.388244628906	1.6449736431241	0.68414636189118	0.013682927004993	25.675478
2.09999990463257	1036.00024414063	1.72828393988311	0.720731681212783	0.0143414633348584	26.69622
2.20000004768372	1077.59619140625	1.81182497180998	0.757317058742046	0.0150731708854437	27.768088
2.29999995231628	1118.67553710938	1.89536600373685	0.79390243627131	0.0158048775047064	28.826644
2.40000009536743	1158.01831054688	1.97867630049586	0.826829287689179	0.0165365859866142	29.84045
2.5	1195.85083007813	2.06244806759059	0.863414607010782	0.0171951223164797	30.815338
2.59999990463257	1235.43884277344	2.1457583643496	0.899999984540045	0.0179268289357424	31.835464
2.70000004768372	1269.8857421875	2.22906866110861	0.936585362069309	0.0186585374176502	32.72311
2.79999995231628	1305.68566894531	2.31260969303548	0.969512213487178	0.0193170737475157	33.645624
2.90000009536743	1340.66442871094	2.39591998979449	1.00243906490505	0.0199756100773811	34.546976
3	1377.18383789063	2.47923005372286	1.04268291033804	0.0207073166966438	35.488028
3.09999990463257	1406.67150878906	2.56254035048187	1.07560970354825	0.0214390251785517	36.24788
3.20000004768372	1439.24401855469	2.64585064724088	1.11219508107752	0.0221707317978144	37.087228
3.29999995231628	1469.31018066406	2.72893020883203	1.15243904292583	0.0229756087064743	37.861988
3.40000009536743	1496.55358886719	2.81224027276039	1.19268288835883	0.0237073171883821	38.564012
3.5	1523.64697265625	2.8955505695194	1.23658531811088	0.0246585365384817	39.262168
3.59999990463257	1552.41540527344	2.97863013111055	1.2768292799592	0.0254634134471416	40.003488
3.70000004768372	1576.26708984375	3.06194042786956	1.3170731253922	0.0262682922184467	40.618112
3.79999995231628	1598.77416992188	3.14501975663006	1.36097555514425	0.0271463412791491	41.198088
3.90000009536743	1623.34582519531	3.22809931822121	1.40121951699257	0.0278780497610569	41.831264
4	1643.62683105469	3.31140961498022	1.43414631020278	0.0286829266697168	42.353876
4.09999990463257	1661.54858398438	3.39448917657137	1.4743902720511	0.0294146332889795	42.815692
4.19999980926514	1679.87341308594	3.47756850533187	1.5073170652613	0.030073169618845	43.287896
4.30000019073486	1697.56982421875	3.56087880209088	1.55121949501336	0.0308780483901501	43.743908
4.40000009536743	1714.75	3.64418909884989	1.58780487254262	0.0317560955882072	44.186616
4.5	1731.05224609375	3.7272684276104	1.62439025007188	0.0324146337807179	44.6067
4.59999990463257	1744.51135253906	3.81057872436941	1.67195126414299	0.0333658531308174	44.953524
4.69999980926514	1757.92602539063	3.89388902112842	1.71585369389504	0.0342439040541649	45.2992
4.80000019073486	1773.87890625	3.97743005305529	1.76341459155083	0.0351951234042645	45.71028
4.90000009536743	1784.76965332031	4.06097108498216	1.81463418994099	0.0361463390290737	45.99092
5	1795.98559570313	4.14428114891052	1.86219508759677	0.0371707305312157	46.27994
5.09999990463257	1807.92578125	4.22759167850018	1.90975610166788	0.0380487814545631	46.58762
5.19999980926514	1820.318359375	4.31090174242854	1.95365864783525	0.0389999970793724	46.90696
5.30000019073486	1829.13647460938	4.39444277435541	1.99756096117198	0.0398780480027199	47.134188
5.40000009536743	1838.29833984375	4.47775330394506	2.04878044314682	0.0408292710781097	47.370276
5.5	1849.40222167969	4.56129433587193	2.09634145721793	0.0418536588549614	47.656408
5.59999990463257	1856.859375	4.64483536779881	2.14390247128904	0.0428048819303513	47.848568
5.69999980926514	1864.2587890625	4.72814543172717	2.19512195326388	0.0437560975551605	48.03924
5.80000019073486	1871.97900390625	4.81145596131682	2.23536579869688	0.044634148478508	48.23818
5.90000009536743	1880.41040039063	4.89476602524519	2.29024398140609	0.0456585362553597	48.455444
6	1887.92272949219	4.97807608917356	2.34512193128467	0.0468292683362961	48.649024
6.09999990463257	1896.02661132813	5.06138661876321	2.41097551770508	0.0480731725692749	48.857852
6.19999980926514	1901.99621582031	5.14469668269157	2.46951216831803	0.0492439046502113	49.01168
6.30000019073486	1907.94360351563	5.22777624428272	2.51707318238914	0.0501951202750206	49.164936
6.40000009536743	1916.46179199219	5.31085580587387	2.56829266436398	0.0512926839292049	49.384436
6.5	1923.79528808594	5.39393536746502	2.6231708470732	0.052390243858099	49.573408
6.59999990463257	1928.31860351563	5.47701446339488	2.67439032904804	0.0533414632081985	49.689968
6.69999980926514	1934.45581054688	5.56032499298453	2.7219511102885	0.0543658509850502	49.848116
6.80000019073486	1938.92224121094	5.64340455457568	2.77317082509398	0.0553902424871922	49.963208
6.90000009536743	1944.10595703125	5.72648411616683	2.82439030706882	0.0564146339893341	50.096784
7	1949.96655273438	5.80956321209669	2.87560978904366	0.0573658533394337	50.247804
7.09999990463257	1953.66296386719	5.89264277368784	2.92682927101851	0.0583902411162853	50.343056
7.19999980926514	1961.29760742188	5.97595330327749	2.97804875299335	0.0594146363437176	50.539788
7.30000019073486	1965.13342285156	6.05903239920735	3.03292693570256	0.0605121962726116	50.638632
7.40000009536743	1971.74768066406	6.14234292879701	3.0841464176774	0.0616097524762154	50.809072
7.5	1973.76123046875	6.22542249038816	3.13902436755598	0.0626341477036476	50.86096
7.59999990463257	1981.63049316406	6.30873255431652	3.18658538162708	0.0636585354804993	51.06374
7.69999980926514	1984.75378417969	6.39204261824489	3.23780486360192	0.0646829307079315	51.14422
7.80000019073486	1988.20349121094	6.47535314783454	3.28902434557676	0.0657073184847832	51.233116
7.90000009536743	1991.71142578125	6.55866321176291	3.34390252828598	0.0667317062616348	51.323508
8	1994.72863769531	6.64197374135256	3.39512201026082	0.0677560940384865	51.40126
8.10000038146973	1997.32397460938	6.72505330294371	3.44634149223566	0.0688536614179611	51.468136
8.19999980926514	2001.21594238281	6.80859433487058	3.50121944211423	0.0698780491948128	51.568428
8.30000019073486	2002.8037109375	6.89190439879894	3.54878045618534	0.0709024369716644	51.60934
8.39999961853027	2006.42370605469	6.97521446272731	3.60365863889456	0.0719999969005585	51.702624
8.5	2011.7705078125	7.05852499231696	3.65853658877313	0.0730975642800331	51.840404
8.60000038146973	2013.23278808594	7.14183505624533	3.70975607074797	0.0741219520568848	51.878084
8.69999980926514	2018.92150878906	7.22514558583498	3.76829272136092	0.0752195119857788	52.024672
8.80000019073486	2022.58276367188	7.30845564976335	3.8231706712395	0.0763170719146729	52.11902
8.89999961853027	2025.06640625	7.39176571369171	3.87439015321434	0.0774146318435669	52.18302
9	2027.23278808594	7.47507624328136	3.92926810309291	0.0785121992230415	52.238844
9.10000038146973	2029.23205566406	7.55838630720973	3.98414628580213	0.079609751701355	52.29036
9.19999980926514	2030.20092773438	7.64169683679938	4.03902446851134	0.080707311630249	52.315328
9.30000019073486	2034.83972167969	7.72477593272924	4.09756088629365	0.0818048790097237	52.434864
9.39999961853027	2035.73559570313	7.80785549432039	4.15609776973724	0.0829756110906601	52.457948
9.5	2035.10217285156	7.89116602391005	4.20365855097771	0.0839999988675117	52.441624
9.60000038146973	2041.6015625	7.9744765534997	4.26585366949439	0.0851707309484482	52.609104
9.69999980926514	2042.07641601563	8.05778615176678	4.32073185220361	0.0862682908773422	52.62134
9.80000019073486	2042.83203125	8.14086571335793	4.37195133417845	0.0873658508062363	52.640812
9.89999961853027	2045.62451171875	8.22417624294758	4.42682905122638	0.0884634181857109	52.712772
10	2046.9912109375	8.30725580453873	4.48536593466997	0.0896341428160667	52.747988
10.1000003814697	2047.84057617188	8.39056540280581	4.53658541664481	0.0906585305929184	52.769876
10.1999998092651	2048.31567382813	8.47410690039396	4.5987805351615	0.0918292701244354	52.78212
10.3000001907349	2050.79663085938	8.55741742998362	4.6573169529438	0.0930000022053719	52.846048
10.3999996185303	2052.61010742188	8.64072702825069	4.7158538363874	0.0941707268357277	52.89278
10.5	2052.43041992188	8.72403755784035	4.77073155343533	0.0952682942152023	52.888148
10.6000003814697	2054.68627929688	8.80734808743	4.83292667195201	0.0965121984481812	52.94628
10.6999998092651	2052.09741210938	8.89065861701965	4.88780485466123	0.097682923078537	52.879568
10.8000001907349	2052.97631835938	8.97443015128374	4.94634127244353	0.098780483007431	52.902216
10.8999996185303	2056.26440429688	9.05774068087339	5.00121945515275	0.0999512150883675	52.986944
11	2058.25805664063	9.14105027914047	5.06341457366943	0.101195119321346	53.03832
11.1000003814697	2058.90258789063	9.22459177672863	5.12195099145174	0.102219514548779	53.054928
11.1999998092651	2062.29077148438	9.30790137499571	5.17682917416096	0.103390246629715	53.142236
11.3000001907349	2062.60522460938	9.39144287258387	5.23536605760455	0.104634150862694	53.15034
11.3999996185303	2062.12060546875	9.47498343884945	5.29024377465248	0.105731710791588	53.137852
11.5	2061.11181640625	9.5582939684391	5.35243889316916	0.106902435421944	53.111856
11.6000003814697	2061.06005859375	9.64160449802876	5.41829271242023	0.108146339654922	53.110524
11.6999998092651	2060.5166015625	9.7246840596199	5.47682913020253	0.109390243887901	53.09652
11.8000001907349	2063.0068359375	9.80799365788698	5.54268294945359	0.11063414812088	53.160688
11.8999996185303	2061.81713867188	9.89130418747664	5.59756113216281	0.111878052353859	53.130032
12	2058.65747070313	9.97461471706629	5.65975625067949	0.113048776984215	53.048612
12.1000003814697	2061.57006835938	10.0579252466559	5.7182926684618	0.114292681217194	53.123664
12.1999998092651	2062.04809570313	10.141234844923	5.77682908624411	0.115463420748711	53.135984
12.3000001907349	2063.02124023438	10.2245453745127	5.83902420476079	0.116707317531109	53.16106
12.3999996185303	2061.61669921875	10.3078559041023	5.89756108820438	0.117878049612045	53.124868
12.5	2060.33154296875	10.3911655023694	5.96341444179416	0.119195125997067	53.091752
12.6000003814697	2062.09399414063	10.4744760319591	6.02926826104522	0.120439022779465	53.137164
12.6999998092651	2064.09423828125	10.5577865615487	6.0914633795619	0.121682927012444	53.188708
12.8000001907349	2062.45776367188	10.6410970911384	6.15731719881296	0.123073168098927	53.14654
12.8999996185303	2062.61401367188	10.7244066894054	6.21219491586089	0.124170735478401	53.150564
13	2061.21337890625	10.8079481869936	6.27439003437757	0.125341460108757	53.114472
13.1000003814697	2061.9501953125	10.8912577852607	6.33658515289426	0.126585364341736	53.13346
13.1999998092651	2061.4384765625	10.9747992828488	6.40243897214532	0.127902448177338	53.120276
13.3000001907349	2061.32470703125	11.0581098124385	6.46829279139638	0.129146337509155	53.117344
13.3999996185303	2060.9775390625	11.1416503787041	6.53414614498615	0.130463406443596	53.108396
13.5	2060.6962890625	11.2249609082937	6.59634126350284	0.131853654980659	53.101148
13.6000003814697	2061.42163085938	11.3082714378834	6.66951201856136	0.1331707239151	53.11984
13.6999998092651	2060.23095703125	11.391812004149	6.7390245385468	0.134634137153625	53.08916
13.8000001907349	2059.82763671875	11.4751225337386	6.80487789213657	0.135951220989227	53.078764
13.8999996185303	2056.82104492188	11.5586631000042	6.86707301065326	0.137195125222206	53.001288
14	2057.60205078125	11.6419736295938	6.93292682990432	0.138439029455185	53.021416
14.1000003814697	2056.69409179688	11.7252841591835	6.99878064915538	0.139829263091087	52.99802
14.1999998092651	2055.13525390625	11.8088247254491	7.06463400274515	0.141219511628151	52.957848
14.3000001907349	2053.607421875	11.8921352550387	7.12682912126184	0.142390251159668	52.91848
14.3999996185303	2051.16088867188	11.9754457846284	7.18536600470543	0.143634140491486	52.855436
14.5	2052.501953125	12.0587553828955	7.2512193582952	0.144878044724464	52.889992
14.6000003814697	2049.94165039063	12.1420659124851	7.31707317754626	0.146268293261528	52.824016
14.6999998092651	2050.40771484375	12.2253764420748	7.38658523187041	0.147585362195969	52.836028
14.8000001907349	2052.12231445313	12.3086860403419	7.45975598692894	0.149048775434494	52.880212
14.8999996185303	2050.4765625	12.391765601933	7.52926850691438	0.150439023971558	52.8378
15	2049.89965820313	12.4750761315227	7.59512186050415	0.151756092905998	52.822936
15.1000003814697	2048.96484375	12.5583866611123	7.66829261556268	0.153219521045685	52.798848
15.1999998092651	2048.53295898438	12.6416962593794	7.73780466988683	0.15468293428421	52.787716
15.3000001907349	2045.63562011719	12.7247758209705	7.80731718987226	0.15599998831749	52.713056
15.3999996185303	2045.71545410156	12.8083173185587	7.87317100912333	0.157317072153091	52.715116
15.5	2043.29968261719	12.8916278481483	7.94268306344748	0.158707320690155	52.652864
15.6000003814697	2041.6240234375	12.9749374464154	8.01219511777163	0.160024389624596	52.609684
15.6999998092651	2039.83154296875	13.0584789440036	8.07804893702269	0.161341458559036	52.563496
15.8000001907349	2042.52014160156	13.1415585055947	8.15121922641993	0.162878051400185	52.632776
15.8999996185303	2040.76037597656	13.2250990718603	8.22804868221283	0.164487808942795	52.587428
16	2038.20129394531	13.3086405694485	8.29756073653698	0.165804892778397	52.521484
16.1000003814697	2037.93493652344	13.3917201310396	8.37073195725679	0.167268291115761	52.514624
16.2000007629395	2035.79406738281	13.4750297293067	8.44390224665403	0.168658524751663	52.459456
16.2999992370605	2034.25830078125	13.5583402588964	8.52073170244694	0.170195117592812	52.41988
16.3999996185303	2032.01831054688	13.641650788486	8.59024375677109	0.171658545732498	52.36216
16.5	2032.59191894531	13.7251913547516	8.6634149774909	0.173121958971024	52.37694
16.6000003814697	2028.68420410156	13.8085018843412	8.72926786541939	0.174512192606926	52.276244
16.7000007629395	2029.26782226563	13.8920424506068	8.8024390861392	0.175902426242828	52.291284
16.7999992370605	2025.65979003906	13.9753529801965	8.87195114046335	0.177292674779892	52.198308
16.8999996185303	2023.47998046875	14.0586635097861	8.94512236118317	0.178682938218117	52.14214
17	2026.109375	14.1417430713773	9.00365877896547	0.179999992251396	52.209896
17.1000003814697	2023.09045410156	14.2250526696444	9.07682906836271	0.181390255689621	52.1321
17.2000007629395	2020.18249511719	14.308363199234	9.15365852415562	0.182853654026985	52.057168
17.2999992370605	2021.49694824219	14.3914427608252	9.22682881355286	0.184317082166672	52.09104
17.3999996185303	2019.99072265625	14.4745223224163	9.30000003427267	0.185853660106659	52.052224
17.5	2017.19323730469	14.5576018840075	9.37317032366991	0.187390238046646	51.98014
17.6000003814697	2015.60693359375	14.6406814455986	9.44268330931664	0.18878048658371	51.93926
17.7000007629395	2012.76208496094	14.7237610071898	9.51951183378696	0.190170720219612	51.865956
17.7999992370605	2009.84228515625	14.8068405687809	9.59634128957987	0.191780492663383	51.790716
17.8999996185303	2009.07543945313	14.890150167048	9.67682898044586	0.193317070603371	51.770956
18	2005.27893066406	14.9734606966376	9.75000020116568	0.194853663444519	51.673124
18.1000003814697	2001.96130371094	15.0565402582288	9.84146352857351	0.196682929992676	51.587632
18.2000007629395	2001.4443359375	15.1398507878184	9.91463381797075	0.198219507932663	51.574312
18.2999992370605	1999.38061523438	15.2231603860855	9.99146327376366	0.199756100773811	51.521132
18.3999996185303	1999.06091308594	15.3064709156752	10.0719509646297	0.20129269361496	51.512896
18.5	1997.34252929688	15.3897814452648	10.1487804204226	0.202829256653786	51.468616
18.6000003814697	1994.09094238281	15.4733220115304	10.2256098762155	0.204292684793472	51.384824
18.7000007629395	1991.89758300781	15.5566325411201	10.3060975670815	0.205975607037544	51.328308
18.7999992370605	1987.41430664063	15.6399421393871	10.3865852579474	0.207512199878693	51.21278
18.8999996185303	1987.02380371094	15.7234836369753	10.4670729488134	0.209268301725388	51.202716
19	1984.24462890625	15.8070251345634	10.5439024046063	0.210804879665375	51.1311
19.1000003814697	1980.15002441406	15.8905666321516	10.6243900954723	0.212341472506523	51.025588
19.2000007629395	1976.36376953125	15.9741062670946	10.7048777863383	0.213878035545349	50.928024
19.2999992370605	1970.88049316406	16.0576477646828	10.7817072421312	0.215414628386498	50.786728
19.3999996185303	1966.92663574219	16.1407273262739	10.8621949329972	0.217097565531731	50.68484
19.5	1963.64453125	16.2242688238621	10.9426826238632	0.218707323074341	50.600268
19.6000003814697	1957.57104492188	16.3073483854532	11.0268294811249	0.220463410019875	50.44376
19.7000007629395	1947.86022949219	16.3908880203962	11.110975407064	0.222073182463646	50.193528
19.7999992370605	1936.67785644531	16.4741985499859	11.1987804993987	0.223902449011803	49.905376
19.8999996185303	1922.69116210938	16.5575090795755	11.2939020618796	0.225658535957336	49.544956
20	1890.947265625	16.6405886411667	11.400000192225	0.227780491113663	48.726964
20.0699996948242	1.45352685451508	16.6989751160145	11.6780484095216	0.230853646993637	0.0374552734375