File: Tensile_tests/PA12_C6_XY_7 08-30-22 12 05 17 PM/DAQ- Time, … - (Timed).txt
File Path: C:\MTS TestSuite\Data Files\Chahine\DOE\PA12_C6_XY_7 08-30-22 12 05 17 PM\DAQ- Time, … - (Timed).txt
Test: MTS EM Tension (Extensometer)_Grand_Chahine 1
Test Run: PA12_C6_XY_7
Date: 8/30/2022 12:04:52 PM


Time 	Load 	Crosshead 	Extensometer 	Strain 	Stress
sec	N	mm	mm	mm/mm	N/mm²
0.0999999716877937	26.9768352508545	0.0422320699726697	0.0109756101664971	0.000146341466461308	0.6484441875
0.199999943375587	87.6512985229492	0.125080769066699	0.0439024406659883	0.00087804882787168	2.10688075
0.299999892711639	145.22444152832	0.208852579817176	0.0804878072813153	0.00153658539056778	3.49077075
0.399999886751175	200.269378662109	0.292393611744046	0.109756096208002	0.00212195119820535	4.81389
0.499999850988388	254.325347900391	0.375703879399225	0.142682925797999	0.00278048776090145	6.1132375
0.599999785423279	310.255310058594	0.459014117950574	0.179268288775347	0.00351219531148672	7.45763
0.699999809265137	361.747314453125	0.542324385605752	0.208536584977992	0.00417073164135218	8.695347
0.79999977350235	416.440765380859	0.625634624157101	0.248780474066734	0.00490243919193745	10.010018
0.899999737739563	463.857391357422	0.708714127540588	0.296341459034011	0.0057804873213172	11.149775
1	514.903625488281	0.791793572716415	0.32926828134805	0.00651219487190247	12.376777
1.10000002384186	563.974975585938	0.875334604643285	0.362195132765919	0.00724390242248774	13.556309
1.19999992847443	615.271057128906	0.958414108026773	0.398780481191352	0.00790243875235319	14.789316
1.29999995231628	663.847595214844	1.04195508174598	0.435365858720616	0.00863414630293846	15.956954
1.39999985694885	708.589050292969	1.12549611367285	0.475609762361273	0.00936585385352373	17.032408
1.49999988079071	758.321716308594	1.20880641043186	0.508536584675312	0.010097561404109	18.227836
1.59999978542328	806.756225585938	1.29211670719087	0.54878048831597	0.0109024392440915	19.39206
1.69999980926514	849.7841796875	1.37565773911774	0.585365865845233	0.0115609746426344	20.426326
1.79999971389771	895.918518066406	1.45896791946143	0.618292659055442	0.0122926831245422	21.53526
1.89999973773956	941.1005859375	1.54273980297148	0.651219510473311	0.0129512194544077	22.621306
2	982.420166015625	1.62604998331517	0.68414636189118	0.0136097557842731	23.614506
2.09999990463257	1026.17077636719	1.70936028007418	0.717073155101389	0.0142682921141386	24.666144
2.20000004768372	1066.56726074219	1.79290131200105	0.750000006519258	0.0149268293753266	25.637158
2.29999995231628	1107.876953125	1.87621160876006	0.786585384048522	0.0156585369259119	26.630122
2.39999985694885	1146.71801757813	1.95929105393589	0.823170761577785	0.0163902435451746	27.563746
2.49999976158142	1182.57995605469	2.04306282103062	0.859756080899388	0.0171219520270824	28.425762
2.59999990463257	1221.73059082031	2.12614238262177	0.892682932317257	0.0177804883569479	29.36683
2.69999980926514	1259.32202148438	2.20922171138227	0.925609783735126	0.0184390246868134	30.270418
2.79999971389771	1294.99194335938	2.29253200814128	0.958536576945335	0.0190975610166788	31.127818
2.89999961853027	1328.65307617188	2.37561156973243	0.995121896266937	0.0198292694985867	31.936934
3	1362.42639160156	2.45869113132358	1.0317072737962	0.0205609761178494	32.748746
3.09999990463257	1394.64855957031	2.54200119525194	1.06463418342173	0.0212195124477148	33.523272
3.20000004768372	1423.66101074219	2.62508075684309	1.10487802885473	0.0220243912190199	34.220648
3.29999995231628	1454.98229980469	2.70816031843424	1.14146340638399	0.0227560959756374	34.97352
3.39999985694885	1480.63818359375	2.79123964719474	1.18170736823231	0.0235609747469425	35.590212
3.49999976158142	1509.7041015625	2.87454994395375	1.21829262934625	0.0242926832288504	36.288872
3.59999990463257	1533.09362792969	2.9576295055449	1.25853659119457	0.0250975601375103	36.851088
3.69999980926514	1557.12707519531	3.04093980230391	1.29878043662757	0.0259024389088154	37.42878
3.79999971389771	1580.92761230469	3.12401913106442	1.34634145069867	0.0267804879695177	38.000876
3.89999961853027	1605.68139648438	3.20732942782342	1.38658541254699	0.02765853703022	38.595884
4	1626.85974121094	3.29063972458243	1.42682925797999	0.0284634158015251	39.104948
4.09999990463257	1646.20227050781	3.3741807565093	1.4743902720511	0.0294146332889795	39.569888
4.19999980926514	1665.89990234375	3.45749105326831	1.51463411748409	0.0302195139229298	40.04336
4.29999971389771	1681.57043457031	3.54080135002732	1.55853654723614	0.0310975611209869	40.420036
4.40000009536743	1699.01538085938	3.62434238195419	1.6024389769882	0.0319756120443344	40.83936
4.5	1715.88464355469	3.70765244588256	1.64634152315557	0.0328536592423916	41.244848
4.59999990463257	1728.07995605469	3.79119347780943	1.69390242081136	0.0337317064404488	41.537988
4.69999980926514	1741.34985351563	3.87450377456844	1.73780485056341	0.0346097573637962	41.856956
4.79999971389771	1755.15161132813	3.95804503932595	1.78536586463451	0.0355609767138958	42.188712
4.89999961853027	1766.29077148438	4.04158607125282	1.83292687870562	0.0365121960639954	42.456464
5	1778.82006835938	4.12489613518119	1.87682930845767	0.0374634154140949	42.757632
5.09999990463257	1789.27282714844	4.20820619910955	1.92804879043251	0.0384146347641945	43.008884
5.19999980926514	1800.27770996094	4.29174723103642	1.97195122018456	0.0393658541142941	43.273408
5.29999971389771	1810.9892578125	4.37482679262757	2.02682917006314	0.0404634140431881	43.530884
5.40000009536743	1819.3642578125	4.45836782455444	2.08170735277236	0.04148780554533	43.732196
5.5	1829.61376953125	4.5416783541441	2.12560966610909	0.0424390248954296	43.978564
5.59999990463257	1835.35095214844	4.62475791573524	2.17317068018019	0.0433902442455292	44.116468
5.69999980926514	1847.35815429688	4.70806797966361	2.22439016215503	0.0444146320223808	44.405088
5.79999971389771	1856.06140136719	4.79114754125476	2.27195117622614	0.0452926829457283	44.614288
5.89999961853027	1861.54943847656	4.87422710284591	2.31951219029725	0.0463170744478703	44.746204
6	1870.18273925781	4.95753716677427	2.37073167227209	0.0473414659500122	44.953724
6.09999990463257	1875.90393066406	5.04061672836542	2.41829268634319	0.0482926853001118	45.091244
6.19999980926514	1882.45544433594	5.12369628995657	2.4658537004143	0.0492439046502113	45.248724
6.29999971389771	1889.17541503906	5.20677538588643	2.52073165029287	0.0501951202750206	45.410252
6.40000009536743	1896.85949707031	5.28985494747758	2.56829266436398	0.0512926839292049	45.594952
6.5	1903.92687988281	5.37293450906873	2.61585367843509	0.0522439032793045	45.764832
6.59999990463257	1908.48901367188	5.45624503865838	2.66341469250619	0.0531951189041138	45.874492
6.69999980926514	1916.89038085938	5.53955510258675	2.7109757065773	0.0541463419795036	46.076436
6.79999971389771	1919.3583984375	5.62263466417789	2.76219518855214	0.0550975613296032	46.13576
6.89999961853027	1925.88391113281	5.70594472810626	2.81341467052698	0.0561219491064548	46.292616
7	1929.71520996094	5.78925525769591	2.86829262040555	0.0572195127606392	46.384708
7.09999990463257	1935.60119628906	5.87233435362577	2.91585363447666	0.0581707358360291	46.526192
7.19999980926514	1939.98510742188	5.95587538555264	2.96341464854777	0.0591951236128807	46.631568
7.29999971389771	1945.162109375	6.0391859151423	3.02195129916072	0.0603658519685268	46.756008
7.40000009536743	1949.44250488281	6.12249597907066	3.07682924903929	0.0613902471959591	46.858896
7.5	1950.75671386719	6.20580650866032	3.12804873101413	0.0624146349728107	46.890484
7.59999990463257	1956.58959960938	6.28911657258868	3.17926821298897	0.0635121911764145	47.030692
7.69999980926514	1964.15893554688	6.37242663651705	3.23048769496381	0.0644634142518044	47.212636
7.79999971389771	1967.212890625	6.4557371661067	3.28536587767303	0.0655609741806984	47.286044
7.89999961853027	1969.39099121094	6.53904723003507	3.3402438275516	0.066658541560173	47.3384
8	1976.86340332031	6.62235775962472	3.39146330952644	0.0677560940384865	47.518012
8.10000038146973	1975.67468261719	6.70566782355309	3.44268302433193	0.0687804892659187	47.48944
8.19999980926514	1980.27160644531	6.78920885547996	3.50121944211423	0.0698780491948128	47.599936
8.30000019073486	1984.38903808594	6.8722884170711	3.55975609272718	0.0711219534277916	47.698908
8.39999961853027	1989.62121582031	6.95582944899797	3.61097557470202	0.0721463412046433	47.824672
8.5	1991.93383789063	7.03913951292634	3.6548781208694	0.0730243921279907	47.880264
8.59999942779541	1993.38818359375	7.12221907451749	3.70609760284424	0.0740487799048424	47.91522
8.69999980926514	1992.77197265625	7.20529863610864	3.76463425345719	0.0751463398337364	47.900408
8.80000019073486	1997.755859375	7.288608700037	3.81585373543203	0.0762438997626305	48.020208
8.89999961853027	1999.28149414063	7.37191922962666	3.86707321740687	0.0772682949900627	48.05688
9	2003.69116210938	7.45522929355502	3.92560986801982	0.0783658474683762	48.162876
9.10000038146973	2006.21752929688	7.53830885514617	3.97682934999466	0.079390250146389	48.2236
9.19999980926514	2009.14196777344	7.62138841673732	4.0280488319695	0.0804878026247025	48.293896
9.30000019073486	2011.13171386719	7.70469848066568	4.08658524975181	0.0815853625535965	48.341724
9.39999961853027	2011.64636230469	7.78800901025534	4.13780473172665	0.0826097577810287	48.354096
9.5	2014.23547363281	7.87131953984499	4.18902421370149	0.0836341455578804	48.416328
9.59999942779541	2015.70385742188	7.95462913811207	4.2439023964107	0.0848048776388168	48.451624
9.69999980926514	2019.28137207031	8.03817063570023	4.29878057911992	0.0859024375677109	48.537616
9.80000019073486	2020.75415039063	8.12125019729137	4.35365876182914	0.0869999974966049	48.57302
9.89999961853027	2021.05920410156	8.20479076355696	4.41219517961144	0.0880975648760796	48.580352
10	2025.23706054688	8.28810129314661	4.46707336232066	0.089195117354393	48.680776
10.1000003814697	2026.02807617188	8.37141182273626	4.52195107936859	0.09036585688591	48.699788
10.1999998092651	2026.48193359375	8.45495238900185	4.58048796281219	0.0915365815162659	48.710696
10.3000001907349	2029.01184082031	8.53849388659	4.63902438059449	0.0926341488957405	48.771508
10.3999996185303	2033.76623535156	8.62180348485708	4.69390256330371	0.0938048809766769	48.885792
10.5	2034.19323730469	8.70511401444674	4.74878028035164	0.0948292687535286	48.896056
10.5999994277954	2030.73901367188	8.78865458071232	4.80365846306086	0.096000000834465	48.813024
10.6999998092651	2033.49194335938	8.87196511030197	4.86219534650445	0.0970975607633591	48.879196
10.8000001907349	2033.88000488281	8.95573664456606	4.91341482847929	0.0981951206922531	48.888524
10.8999996185303	2033.74621582031	9.03904717415571	4.9719512462616	0.0993658527731895	48.885308
11	2036.88061523438	9.12212673574686	5.0304876640439	0.100463412702084	48.960652
11.1000003814697	2033.63488769531	9.20543726533651	5.0890245474875	0.10163414478302	48.882632
11.1999998092651	2036.09912109375	9.28874779492617	5.14390226453543	0.102804884314537	48.941868
11.3000001907349	2034.75305175781	9.37182642519474	5.20609738305211	0.104048781096935	48.909512
11.3999996185303	2035.70849609375	9.4553679227829	5.2646342664957	0.105146333575249	48.932476
11.5	2041.94653320313	9.53867845237255	5.33048762008548	0.106390237808228	49.08242
11.5999994277954	2040.50415039063	9.6217580139637	5.38536580279469	0.107560977339745	49.047752
11.6999998092651	2039.62280273438	9.70529858022928	5.44024398550391	0.108658537268639	49.026564
11.8000001907349	2040.87377929688	9.78860910981894	5.49878040328622	0.109902441501617	49.056636
11.8999996185303	2042.68176269531	9.87168867141008	5.55731728672981	0.111000001430511	49.100096
12	2040.19372558594	9.95522923767567	5.61219500377774	0.112170733511448	49.040288
12.1000003814697	2039.77062988281	10.0385397672653	5.67439012229443	0.113341465592384	49.03012
12.1999998092651	2041.77453613281	10.121850296855	5.73292700573802	0.11451219022274	49.078288
12.3000001907349	2040.32922363281	10.2051598951221	5.7951221242547	0.115756094455719	49.043548
12.3999996185303	2040.00598144531	10.2884704247117	5.85365854203701	0.116999998688698	49.035776
12.5	2043.22314453125	10.3717809543014	5.91219495981932	0.118097558617592	49.113108
12.5999994277954	2039.20983886719	10.4553215205669	5.974390078336	0.119414635002613	49.01664
12.6999998092651	2041.95861816406	10.5386320501566	6.03292696177959	0.120512187480927	49.082712
12.8000001907349	2041.24633789063	10.6219425797462	6.09512208029628	0.121756091713905	49.065592
12.8999996185303	2041.20092773438	10.7054831460118	6.15731719881296	0.122999995946884	49.0645
13	2039.26940917969	10.7887936756015	6.22682925313711	0.124390244483948	49.018072
13.1000003814697	2039.01965332031	10.8723342418671	6.28536567091942	0.125560969114304	49.012068
13.1999998092651	2042.08850097656	10.9558757394552	6.3475607894361	0.126804873347282	49.085836
13.3000001907349	2039.72033691406	11.0391862690449	6.4060976728797	0.128048777580261	49.028912
13.3999996185303	2039.64294433594	11.1227268353105	6.46829279139638	0.12929268181324	49.027048
13.5	2038.49548339844	11.2060373649001	6.53048790991306	0.130536586046219	48.999468
13.5999994277954	2035.37414550781	11.2893469631672	6.59268302842975	0.131780490279198	48.92444
13.6999998092651	2038.42504882813	11.3728884607553	6.65487814694643	0.133024394512177	48.997776
13.8000001907349	2035.74060058594	11.4559680223465	6.7207315005362	0.134195119142532	48.933248
13.8999996185303	2036.19348144531	11.5390475839376	6.7792683839798	0.135439023375511	48.944136
14	2036.21313476563	11.6225881502032	6.8378048017621	0.136609762907028	48.944608
14.1000003814697	2036.73010253906	11.7058986797929	6.8963416852057	0.137853652238846	48.957032
14.1999998092651	2036.30725097656	11.788978241384	6.96585373952985	0.139170736074448	48.946868
14.3000001907349	2033.79089355469	11.8722887709737	7.03170709311962	0.140560984611511	48.886384
14.3999996185303	2032.90356445313	11.9555983692408	7.09756091237068	0.141731709241867	48.865056
14.5	2031.97399902344	12.0389088988304	7.16341473162174	0.143048778176308	48.842712
14.5999994277954	2031.134765625	12.1222194284201	7.23292678594589	0.144439026713371	48.82254
14.6999998092651	2030.43420410156	12.2055290266871	7.29878060519695	0.145829260349274	48.8057
14.8000001907349	2026.83642578125	12.2886085882783	7.36097572371364	0.147073164582253	48.71922
14.8999996185303	2028.79931640625	12.3721500858665	7.41951214149594	0.148317068815231	48.7664
15	2029.71374511719	12.455690652132	7.48902419582009	0.149707317352295	48.78838
15.1000003814697	2025.49108886719	12.5387702137232	7.55487801507115	0.150951221585274	48.68688
15.1999998092651	2024.15502929688	12.6220807433128	7.61707313358784	0.15212194621563	48.654764
15.3000001907349	2024.02734375	12.7056213095784	7.67926825210452	0.153439030051231	48.651696
15.3999996185303	2022.88012695313	12.7889318391681	7.73780466988683	0.154609754681587	48.62412
15.5	2023.16528320313	12.8722423687577	7.80365848913789	0.15599998831749	48.630976
15.5999994277954	2022.490234375	12.9557829350233	7.86951184272766	0.157317072153091	48.614748
15.6999998092651	2022.06237792969	13.0388624966145	7.93536566197872	0.158634155988693	48.604464
15.8000001907349	2016.45581054688	13.1221730262041	7.99756124615669	0.159878045320511	48.4697
15.8999996185303	2020.12829589844	13.2057135924697	8.07073153555393	0.161268293857574	48.557976
16	2015.19445800781	13.2887931540608	8.14390275627375	0.162658542394638	48.43938
16.1000003814697	2015.87866210938	13.372334651649	8.2134148105979	0.164121955633163	48.455828
16.2000007629395	2015.71069335938	13.4556451812387	8.28292686492205	0.165512189269066	48.451788
16.2999992370605	2014.36145019531	13.5387238115072	8.34878068417311	0.166902422904968	48.419356
16.3999996185303	2014.50415039063	13.6220343410969	8.41829273849726	0.16821950674057	48.422788
16.5	2010.99401855469	13.7053448706865	8.48780479282141	0.169609755277634	48.338412
16.6000003814697	2008.30212402344	13.7884244322777	8.55731684714556	0.171000003814697	48.273708
16.6999988555908	2006.55932617188	13.8717349618673	8.62682890146971	0.172463417053223	48.231816
16.7999992370605	2002.65698242188	13.9548135921359	8.70365835726261	0.173853650689125	48.138016
16.8999996185303	2003.32373046875	14.0378931537271	8.77317041158676	0.175317078828812	48.154044
17	1999.5517578125	14.1209727153182	8.83902423083782	0.176634162664413	48.063376
17.1000003814697	1997.44409179688	14.2040522769094	8.91219545155764	0.178170725703239	48.012712
17.2000007629395	1992.85656738281	14.2871318385005	8.98902397602797	0.179634153842926	47.902444
17.2999992370605	1992.45947265625	14.3704423680902	9.05853696167469	0.181024387478828	47.892896
17.3999996185303	1989.32971191406	14.4537519663572	9.12804901599884	0.182487800717354	47.817668
17.5	1985.86389160156	14.5366014912724	9.21585410833359	0.184170737862587	47.73436
17.6000003814697	1985.51403808594	14.6199110895395	9.28536616265774	0.185560971498489	47.725948
17.6999988555908	1982.25927734375	14.7032216191292	9.36219468712807	0.187024399638176	47.647716
17.7999992370605	1975.75512695313	14.7865321487188	9.45365894585848	0.188853666186333	47.491372
17.8999996185303	1972.18151855469	14.8700727149844	9.53414663672447	0.190536588430405	47.405476
18	1963.76623535156	14.9536142125726	9.6109751611948	0.192073166370392	47.203196
18.1000003814697	1953.97216796875	15.0366937741637	9.69512201845646	0.193829268217087	46.967776
18.2000007629395	1941.48095703125	15.1202343404293	9.7865853458643	0.195585355162621	46.667524
18.2999992370605	1912.90588378906	15.2037758380175	9.88902430981398	0.197560966014862	45.98066
18.3799991607666	-6.33464384078979	15.2707006782293	10.2804880589247	0.201878041028976	-0.1522663125