File: Tensile_tests/PA12_C2_XY_1 05-24-22 11 57 57 AM/DAQ- Time, … - (Timed).txt
File Path: C:\MTS TestSuite\Data Files\Chahine\DOE\PA12_C2_XY_1 05-24-22 11 57 57 AM\DAQ- Time, … - (Timed).txt
Test: MTS EM Tension (Extensometer)_Grand_Chahine 1
Test Run: PA12_C2_XY_1
Date: 5/24/2022 11:57:22 AM


Time 	Load 	Crosshead 	Extensometer 	Strain 	Stress
sec	N	mm	mm	mm/mm	N/mm²
0.190000161528587	85.1044998168945	0.109618755232077	0.0329268295899965	0.000585365865845233	2.0393495
0.290000140666962	142.152893066406	0.193159794434905	0.0585365851293318	0.00117073173169047	3.4063935
0.39000016450882	201.740478515625	0.276700826361775	0.0878048813319765	0.00175609765574336	4.834284
0.490000158548355	258.690368652344	0.360241858288646	0.120731710921973	0.00234146346338093	6.198968
0.590000152587891	312.116485595703	0.443782890215516	0.153658533236012	0.00300000002607703	7.479212
0.690000176429749	368.969329833984	0.527323922142386	0.19024389621336	0.00373170734383166	8.84157
0.790000140666962	420.547210693359	0.610864954069257	0.226829273742624	0.00446341466158628	10.077525
0.89000016450882	474.304931640625	0.693944457452744	0.267073162831366	0.00519512221217155	11.365715
0.990000128746033	529.100769042969	0.777254696004093	0.296341459034011	0.00585365854203701	12.678782
1.09000015258789	578.278015136719	0.860564934555441	0.321951229125261	0.00636585336178541	13.85721
1.19000017642975	627.068542480469	0.94387517310679	0.3548780514393	0.00702439062297344	15.026372
1.29000020027161	679.139282226563	1.02695461828262	0.387804873753339	0.0076829269528389	16.274137
1.39000010490417	728.659973144531	1.11049565020949	0.424390251282603	0.00834146328270435	17.460796
1.49000012874603	775.993469238281	1.19357521180063	0.453658547485247	0.00907317083328962	18.595044
1.59000015258789	824.523376464844	1.27688539214432	0.493902422022074	0.00980487838387489	19.75796
1.69000017642975	872.189270019531	1.35996495373547	0.530487799551338	0.0105365850031376	20.900172
1.79000020027161	916.272583007813	1.4430443989113	0.563414650969207	0.0111951222643256	21.956536
1.89000010490417	959.777648925781	1.52612384408712	0.596341444179416	0.0118536585941911	22.999042
1.99000012874603	1005.65380859375	1.60943414084613	0.629268295597285	0.0125121958553791	24.098368
2.09000015258789	1051.63110351563	1.69251358602196	0.665853673126549	0.0132439024746418	25.200116
2.19000005722046	1091.79077148438	1.77582388278097	0.698780466336757	0.0139024388045073	26.162458
2.29000020027161	1134.99084472656	1.8589033279568	0.728048791643232	0.0144878048449755	27.197656
2.39000010490417	1175.20141601563	1.94198277313262	0.764634169172496	0.0152195114642382	28.161218
2.49000024795532	1217.54846191406	2.02529318630695	0.801219488494098	0.015951219946146	29.175976
2.59000015258789	1258.3310546875	2.10860325023532	0.834146339911968	0.0166097562760115	30.153244
2.69000005722046	1297.31213378906	2.19191354699433	0.867073191329837	0.0173414647579193	31.087344
2.79000020027161	1336.66491699219	2.2754545789212	0.903658510651439	0.0179999992251396	32.03035
2.89000010490417	1373.72229003906	2.35899561084807	0.936585362069309	0.0186585374176502	32.918352
2.99000024795532	1409.73291015625	2.44230590760708	0.973170739598572	0.0193902440369129	33.781268
3.09000015258789	1444.95874023438	2.52561620436609	1.00975611712784	0.0201219506561756	34.62538
3.19000005722046	1479.15869140625	2.60915723629296	1.0463414946571	0.0208536572754383	35.444912
3.29000020027161	1510.65686035156	2.69269826821983	1.0865853400901	0.0216585379093885	36.1997
3.39000010490417	1544.3603515625	2.7762393001467	1.12317071761936	0.022317074239254	37.007332
3.49000024795532	1573.51452636719	2.85954959690571	1.15975609514862	0.0231219492852688	37.705948
3.59000015258789	1604.42797851563	2.94309062883258	1.20000005699694	0.023926829919219	38.446724
3.69000005722046	1630.98828125	3.02640092559159	1.24024390242994	0.024731706827879	39.083188
3.79000020027161	1657.58959960938	3.10971098951995	1.2768292799592	0.0254634134471416	39.720632
3.89000010490417	1682.39709472656	3.19302128627896	1.31341465748847	0.0261951219290495	40.315092
3.99000024795532	1705.41528320313	3.27656231820583	1.35365850292146	0.0270000007003546	40.866672
4.09000015258789	1726.60949707031	3.35987261496484	1.39390246476978	0.0278048776090145	41.374548
4.19000005722046	1750.400390625	3.44318291172385	1.43780489452183	0.0286829266697168	41.944644
4.28999996185303	1768.14184570313	3.52626224048436	1.47804873995483	0.0294878054410219	42.36978
4.39000034332275	1784.27416992188	3.60957253724337	1.51829270180315	0.0303658545017242	42.75636
4.49000024795532	1804.13244628906	3.69288283400238	1.5621951315552	0.0311707314103842	43.23222
4.59000015258789	1819.46643066406	3.77596239559352	1.6024389769882	0.0319756120443344	43.599668
4.69000005722046	1832.25866699219	3.85904172435403	1.6499999910593	0.032926831394434	43.906208
4.78999996185303	1848.52905273438	3.94212128594518	1.69390242081136	0.0338048785924912	44.296092
4.89000034332275	1859.60888671875	4.02543134987354	1.7451219027862	0.0348292700946331	44.561596
4.99000024795532	1873.19348144531	4.10851091146469	1.7926829168573	0.0357073172926903	44.887124
5.09000015258789	1884.08410644531	4.19182144105434	1.83658534660935	0.0366585366427898	45.148092
5.19000005722046	1895.85046386719	4.27513150498271	1.88048777636141	0.0376097559928894	45.430048
5.28999996185303	1901.71105957031	4.35821106657386	1.93170737475157	0.0384878031909466	45.570484
5.39000034332275	1913.17297363281	4.44152113050222	1.97926838882267	0.0394390225410461	45.845148
5.49000024795532	1922.71459960938	4.52483166009188	2.01951223425567	0.0403170734643936	46.073792
5.59000015258789	1928.75451660156	4.60814172402024	2.07073171623051	0.0413414649665356	46.218524
5.69000005722046	1937.00573730469	4.69168275594711	2.11463426239789	0.0422195121645927	46.416248
5.78999996185303	1943.92041015625	4.77499328553677	2.16585374437273	0.0432438999414444	46.581944
5.89000034332275	1951.53356933594	4.85830334946513	2.22439016215503	0.0443414635956287	46.764376
5.99000024795532	1957.47131347656	4.9416134133935	2.27195117622614	0.0453658550977707	46.906664
6.09000015258789	1963.83874511719	5.02515444532037	2.32317065820098	0.0463902428746223	47.059244
6.19000005722046	1971.51086425781	5.10846497491002	2.3780488409102	0.0474146343767643	47.243092
6.28999996185303	1977.60827636719	5.19200600683689	2.4256098549813	0.0483658537268639	47.389204
6.39000034332275	1982.68579101563	5.27554703876376	2.47317063622177	0.0493902415037155	47.510876
6.49000024795532	1988.37121582031	5.35908807069063	2.53170728683472	0.0504878088831902	47.647112
6.59000015258789	1994.06970214844	5.44216763228178	2.58292676880956	0.0515121966600418	47.783664
6.69000005722046	1997.37097167969	5.52570866420865	2.63048778288066	0.0524634160101414	47.862772
6.78999996185303	2004.71545410156	5.60878776013851	2.6817072648555	0.0535609759390354	48.038768
6.89000034332275	2007.10119628906	5.69209828972816	2.73292674683034	0.0545853674411774	48.095936
6.99000024795532	2010.94274902344	5.77540835365653	2.78780492953956	0.055609755218029	48.187992
7.09000015258789	2016.265625	5.85871888324618	2.83536594361067	0.0566341429948807	48.315544
7.19000005722046	2018.43176269531	5.94179797917604	2.89024389348924	0.0576585344970226	48.367452
7.28999996185303	2023.16479492188	6.02487754076719	2.94146337546408	0.058756098151207	48.480868
7.39000034332275	2027.34753417969	6.10818807035685	2.99268285743892	0.0597073175013065	48.5811
7.49000024795532	2032.86437988281	6.19126763194799	3.04390233941376	0.0607317090034485	48.713296
7.59000015258789	2035.32141113281	6.27434672787786	3.09878052212298	0.0619024410843849	48.772176
7.69000005722046	2039.77331542969	6.357426289469	3.15365847200155	0.063000001013279	48.878856
7.78999996185303	2042.06262207031	6.44050585106015	3.20487795397639	0.0640243887901306	48.933716
7.89000034332275	2044.30993652344	6.5235854126513	3.26707307249308	0.065195120871067	48.987568
7.99000024795532	2048.91040039063	6.60666497424245	3.31829278729856	0.0662195086479187	49.097808
8.09000015258789	2051.12890625	6.68997503817081	3.3695122692734	0.0673170685768127	49.150968
8.19000053405762	2053.8486328125	6.77305459976196	3.42439021915197	0.0684146359562874	49.21614
8.28999996185303	2053.42114257813	6.85636466369033	3.47560970112681	0.069439023733139	49.205896
8.39000034332275	2058.10400390625	6.93944422528148	3.52682918310165	0.0705365836620331	49.318112
8.48999977111816	2060.73095703125	7.02275475487113	3.5853658337146	0.0715609788894653	49.38106
8.59000015258789	2063.19580078125	7.1060648187995	3.64390248432755	0.0728048831224442	49.440128
8.69000053405762	2067.63134765625	7.18937488272786	3.69512196630239	0.0737560987472534	49.546416
8.78999996185303	2068.23193359375	7.27268541231751	3.74999991618097	0.0749268308281899	49.560808
8.89000034332275	2070.845703125	7.35599547624588	3.80487809889019	0.0760243907570839	49.62344
8.98999977111816	2073.2333984375	7.43930600583553	3.85975604876876	0.0771219506859779	49.680656
9.09000015258789	2074.47192382813	7.5226160697639	3.91463423147798	0.078219510614872	49.710336
9.19000053405762	2075.39306640625	7.60592613369226	3.96951241418719	0.0793170779943466	49.732408
9.28999996185303	2075.90283203125	7.68923666328192	4.0280488319695	0.0804878026247025	49.744624
9.39000034332275	2078.8388671875	7.77254672721028	4.08658524975181	0.0816585421562195	49.81498
9.48999977111816	2079.67919921875	7.85585679113865	4.14146343246102	0.0826829299330711	49.835116
9.59000015258789	2079.71630859375	7.9391673207283	4.19634161517024	0.0837804824113846	49.836004
9.69000053405762	2083.51708984375	8.02247785031796	4.25487803295255	0.0849512219429016	49.927084
9.78999996185303	2083.61083984375	8.10578744858503	4.30975621566176	0.0861219465732574	49.929328
9.89000034332275	2086.3544921875	8.18909797817469	4.36463393270969	0.0871463418006897	49.995076
9.98999977111816	2088.01684570313	8.27240850776434	4.41951211541891	0.0882439017295837	50.034912
10.0900001525879	2087.2841796875	8.35571903735399	4.47439029812813	0.0893414691090584	50.017352
10.1900005340576	2087.697265625	8.43879766762257	4.52195107936859	0.09036585688591	50.027252
10.289999961853	2089.498046875	8.52210819721222	4.58048796281219	0.0915365815162659	50.070404
10.3900003433228	2088.33544921875	8.60518775880337	4.63170744478703	0.0925609767436981	50.042544
10.4899997711182	2088.07250976563	8.68849828839302	4.69024386256933	0.0936585366725922	50.036244
10.5900001525879	2090.2080078125	8.77180881798267	4.74512204527855	0.0948292687535286	50.087416
10.6900005340576	2090.35766601563	8.85488744825125	4.80000022798777	0.0959268286824226	50.091004
10.789999961853	2088.05249023438	8.9381979778409	4.85853664577007	0.0970243960618973	50.035764
10.8900003433228	2090.96118164063	9.02127753943205	4.91707306355238	0.0982683002948761	50.105464
10.9899997711182	2091.91455078125	9.1045880690217	4.9719512462616	0.0993658527731895	50.128312
11.0900001525879	2091.44409179688	9.18812863528728	5.03414636477828	0.100463412702084	50.117036
11.1900005340576	2094.07763671875	9.27143916487694	5.09268278256059	0.101707316935062	50.180144
11.289999961853	2095.73608398438	9.35474969446659	5.15121966600418	0.102951221168041	50.219884
11.3900003433228	2093.10546875	9.43782925605774	5.20609738305211	0.104048781096935	50.156848
11.4899997711182	2093.99633789063	9.52136982232332	5.26829250156879	0.105219513177872	50.178196
11.5900001525879	2094.23901367188	9.60468035191298	5.32682938501239	0.106390237808228	50.184012
11.6900005340576	2091.669921875	9.68822091817856	5.38170710206032	0.107560977339745	50.122448
11.789999961853	2092.01831054688	9.77176241576672	5.443902220577	0.1087317019701	50.130796
11.8900003433228	2091.12768554688	9.85507201403379	5.50609733909369	0.110048785805702	50.109456
11.9899997711182	2090.53735351563	9.93861351162195	5.56463422253728	0.111146345734596	50.095308
12.0900001525879	2088.98681640625	10.0219240412116	5.62317064031959	0.112390249967575	50.058152
12.1900005340576	2089.0400390625	10.1052336394787	5.68170752376318	0.113560974597931	50.059428
12.289999961853	2088.31665039063	10.1887751370668	5.73658524081111	0.114585369825363	50.042096
12.3900003433228	2090.50219726563	10.2720856666565	5.79878035932779	0.115829266607761	50.094468
12.4899997711182	2089.2236328125	10.3553952649236	5.85731724277139	0.116999998688698	50.063828
12.5900001525879	2087.67626953125	10.4387057945132	5.91951236128807	0.118243902921677	50.026748
12.6900005340576	2087.74291992188	10.5220163241029	5.98170747980475	0.119487799704075	50.028348
12.789999961853	2085.44311523438	10.60532592237	6.04024389758706	0.120658539235592	49.973236
12.8900003433228	2084.14575195313	10.6884054839611	6.09878031536937	0.121829271316528	49.942148
12.9899997711182	2085.58471679688	10.7717160135508	6.16097543388605	0.123073168098927	49.976628
13.0900001525879	2083.669921875	10.8550265431404	6.21585361659527	0.124170735478401	49.930744
13.1900005340576	2081.81176757813	10.9383361414075	6.27439003437757	0.12541463971138	49.88622
13.289999961853	2080.38720703125	11.0218776389956	6.33292691782117	0.126512199640274	49.852084
13.3900003433228	2080.54760742188	11.1049572005868	6.39878027141094	0.127829268574715	49.855924
13.4899997711182	2080.90844726563	11.1884977668524	6.45731715485454	0.129073172807693	49.864572
13.5900001525879	2078.99487304688	11.271808296442	6.51951227337122	0.130243912339211	49.818716
13.6900005340576	2077.41455078125	11.3551188260317	6.57804869115353	0.131487816572189	49.780848
13.789999961853	2077.6884765625	11.4386593922973	6.63658557459712	0.132585361599922	49.787412
13.8900003433228	2076.14282226563	11.5217389538884	6.6987806931138	0.133902445435524	49.750376
13.9899997711182	2072.73120117188	11.6052804514766	6.76829274743795	0.135219514369965	49.668624
14.0900001525879	2071.82690429688	11.6888210177422	6.82317093014717	0.136317074298859	49.646952
14.1900005340576	2070.29272460938	11.7721315473318	6.8780486471951	0.137414634227753	49.610188
14.289999961853	2070.3701171875	11.8554420769215	6.93658553063869	0.138585358858109	49.612044
14.3900003433228	2065.09814453125	11.938982643187	6.995121948421	0.139829263091087	49.485712
14.4899997711182	2065.11791992188	12.0222931727767	7.05000013113022	0.140926823019981	49.486184
14.5900001525879	2061.7724609375	12.1056037023664	7.10121961310506	0.141951218247414	49.40602
14.6900005340576	2062.68872070313	12.1891442686319	7.15609779581428	0.142975613474846	49.427976
14.789999961853	2061.30493164063	12.2724547982216	7.21463421359658	0.144146353006363	49.394816
14.8900003433228	2059.01611328125	12.3557643964887	7.26585369557142	0.145170733332634	49.339968
14.9899997711182	2055.326171875	12.4393058940768	7.32073187828064	0.146268293261528	49.251548
15.0900001525879	2054.85888671875	12.5228464603424	7.38292699679732	0.147512197494507	49.240348
15.1900005340576	2052.47973632813	12.6059260219336	7.45243905112147	0.14890244603157	49.18334
15.289999961853	2048.95434570313	12.6892365515232	7.51463416963816	0.150219514966011	49.09886
15.3900003433228	2047.64147949219	12.7725470811129	7.58414622396231	0.151536583900452	49.0674
15.4899997711182	2045.32482910156	12.8558566793799	7.64634134247899	0.15278048813343	49.011888
15.5900001525879	2041.98791503906	12.9391672089696	7.71951209753752	0.154170721769333	48.931924
15.6900005340576	2038.51501464844	13.0224777385592	7.7817072160542	0.155487805604935	48.848704
15.789999961853	2037.24060058594	13.1057882681489	7.84390233457088	0.156731694936752	48.818164
15.8900003433228	2033.70727539063	13.189097866416	7.92073179036379	0.158268287777901	48.733496
15.9899997711182	2031.14953613281	13.2721774280071	7.99756124615669	0.159878045320511	48.672204
16.0900001525879	2028.595703125	13.3554879575968	8.06341506540775	0.161195114254951	48.611008
16.1900005340576	2023.30615234375	13.4387984871864	8.12560971826315	0.162439033389091	48.484256
16.2900009155273	2021.00207519531	13.5218780487776	8.1951217725873	0.163756102323532	48.429044
16.3899993896484	2017.03210449219	13.6056495830417	8.26463382691145	0.165146350860596	48.333912
16.4899997711182	2012.75024414063	13.6889601126313	8.33780504763126	0.16660974919796	48.231304
16.5900001525879	2007.80944824219	13.7722697108984	8.41463450342417	0.168073177337646	48.112908
16.6900005340576	2001.90161132813	13.8555802404881	8.48414655774832	0.169609755277634	47.97134
16.7900009155273	1997.70068359375	13.9388907700777	8.56463424861431	0.171146333217621	47.870676
16.8899993896484	1991.87023925781	14.0224313363433	8.6451219394803	0.172756090760231	47.73096
16.9899997711182	1988.3046875	14.1059728339314	8.72926786541939	0.174439027905464	47.64552
17.0900001525879	1980.23461914063	14.1892824321985	8.8024390861392	0.175902426242828	47.452136
17.1900005340576	1976.35705566406	14.2723619937897	8.87926854193211	0.177439019083977	47.35922
17.2900009155273	1967.41564941406	14.3556725233793	8.95609799772501	0.178975611925125	47.144956
17.3899993896484	1963.39624023438	14.4392130896449	9.02926828712225	0.180512204766274	47.04864
17.4899997711182	1952.34411621094	14.5222926512361	9.12804901599884	0.182414636015892	46.7838
17.5900001525879	1941.04089355469	14.6058341488242	9.21585410833359	0.184170737862587	46.512944
17.6900005340576	1931.27233886719	14.6893747150898	9.29634179919958	0.185780495405197	46.27886
17.7900009155273	1916.85241699219	14.7724542766809	9.38414596021175	0.187463402748108	45.933316
17.8899993896484	1899.07922363281	14.8557648062706	9.48292668908834	0.189365863800049	45.50742
17.9899997711182	1864.18701171875	14.9390753358603	9.57804918289185	0.19134147465229	44.6713
18.0699996948242	5.68081951141357	15.0043843314052	10.0792683660984	0.200707316398621	0.136128828125