File: Tensile_tests/PA12_C8_XZ_1 09-27-22 11 50 06 AM/DAQ- Time, … - (Timed).txt
File Path: C:\MTS TestSuite\Data Files\Chahine\DOE\PA12_C8_XZ_1 09-27-22 11 50 06 AM\DAQ- Time, … - (Timed).txt
Test: MTS EM Tension (Extensometer)_Grand_Chahine 1
Test Run: PA12_C8_XZ_1
Date: 9/27/2022 11:49:47 AM


Time 	Load 	Crosshead 	Extensometer 	Strain 	Stress
sec	N	mm	mm	mm/mm	N/mm²
0.110000215470791	45.3853950500488	0.0699252268532291	0.0182926833076635	0.000292682932922617	1.137478625
0.210000187158585	94.1418914794922	0.152312379213981	0.0512195110786706	0.000951219466514885	2.359446
0.310000151395798	147.206817626953	0.236314968788065	0.0804878072813153	0.00160975614562631	3.689394
0.410000115633011	197.074279785156	0.320086779538542	0.117073170258664	0.00226829270832241	4.939205
0.510000109672546	241.943710327148	0.403627811465412	0.150000007124618	0.00292682927101851	6.063752
0.61000007390976	291.888702392578	0.487168843392283	0.182926829438657	0.0035853658337146	7.3155065
0.710000038146973	338.467193603516	0.570479081943631	0.219512192416005	0.00439024390652776	8.482887
0.810000002384186	384.184692382813	0.65378932049498	0.263414636719972	0.00512195099145174	9.628689
0.909999966621399	431.429840087891	0.736868823878467	0.300000014249235	0.00592682929709554	10.812778
1.00999999046326	478.03857421875	0.819948327261955	0.336585362674668	0.00665853684768081	11.980917
1.11000025272369	520.03515625	0.903027772437781	0.369512184988707	0.00739024393260479	13.033463
1.21000015735626	563.010314941406	0.98633801098913	0.406097562517971	0.00804878026247025	14.110534
1.31000018119812	606.796264648438	1.0691867209971	0.442682940047234	0.00878048781305552	15.207926
1.41000008583069	645.608703613281	1.1524970177561	0.475609762361273	0.00943902414292097	16.180669
1.51000010967255	688.103942871094	1.23580719809979	0.508536584675312	0.010097561404109	17.245712
1.61000001430511	729.729064941406	1.31888675969094	0.541463436093181	0.0107560968026519	18.288948
1.71000003814697	768.672058105469	1.40196620486677	0.581707339733839	0.0114878043532372	19.264964
1.80999994277954	808.133544921875	1.48527650162578	0.614634132944047	0.0122195119038224	20.253974
1.9099999666214	847.991394042969	1.5683559468016	0.647560984361917	0.0129512194544077	21.252918
2.00999999046326	882.779174804688	1.65166624356061	0.687804888002574	0.013682927004993	22.124792
2.1100001335144	919.992065429688	1.73474568873644	0.724390265531838	0.0144146336242557	23.057446
2.21000027656555	957.176391601563	1.81805598549545	0.757317058742046	0.0150731708854437	23.989384
2.31000018119812	989.293640136719	1.90136616583914	0.79390243627131	0.0158048775047064	24.794326
2.41000008583069	1022.76861572266	1.98467634618282	0.834146339911968	0.0166097562760115	25.633298
2.50999999046326	1056.85510253906	2.06821737810969	0.870731717441231	0.0173414647579193	26.487596
2.6100001335144	1085.7255859375	2.1515276748687	0.903658510651439	0.0179999992251396	27.211168
2.71000003814697	1119.19946289063	2.23506870679557	0.940243888180703	0.0187317077070475	28.050112
2.80999994277954	1145.99816894531	2.31837900355458	0.980487791821361	0.0195365864783525	28.721758
2.90999984741211	1175.65075683594	2.40168930031359	1.01707316935062	0.020195122808218	29.464932
3.00999999046326	1202.78552246094	2.4849995970726	1.04999996256083	0.0209268294274807	30.145
3.1100001335144	1228.97045898438	2.56830989383161	1.0865853400901	0.0216585379093885	30.801264
3.21000027656555	1254.13989257813	2.65208166092634	1.12682930193841	0.0224634148180485	31.432078
3.31000018119812	1278.83410644531	2.73539195768535	1.16341467946768	0.0231951214373112	32.05098
3.41000008583069	1301.20654296875	2.81870202161372	1.19634147267789	0.0238536577671766	32.611692
3.50999999046326	1326.37426757813	2.90201231837273	1.23292685020715	0.0245853662490845	33.242462
3.6100001335144	1345.2548828125	2.98509187996387	1.27317069564015	0.0253902450203896	33.71566
3.71000003814697	1363.24609375	3.06863291189075	1.31341465748847	0.0261219516396523	34.166568
3.80999994277954	1384.28527832031	3.15194320864975	1.35000003501773	0.0269268285483122	34.693868
3.90999984741211	1400.84741210938	3.23502253741026	1.39024388045073	0.0277317091822624	35.108956
4.00999975204468	1415.76391601563	3.31810209900141	1.43048784229904	0.0285365842282772	35.482804
4.1100001335144	1432.46228027344	3.40141239576042	1.47073168773204	0.0293414648622274	35.901312
4.21000003814697	1447.10363769531	3.48449172452092	1.51097564958036	0.0301463417708874	36.26826
4.30999994277954	1461.42431640625	3.56757128611207	1.55853654723614	0.0310975611209869	36.627176
4.41000032424927	1473.9208984375	3.65065084770322	1.6024389769882	0.0319756120443344	36.940372
4.51000022888184	1487.78979492188	3.73373017646372	1.6499999910593	0.0328536592423916	37.287964
4.6100001335144	1500.60046386719	3.81657900288701	1.69024395290762	0.0336585342884064	37.609036
4.71000003814697	1513.86755371094	3.89988929964602	1.73048779834062	0.0345365852117538	37.941544
4.80999994277954	1524.38293457031	3.98296862840652	1.77804881241173	0.0354878045618534	38.205088
4.90999984741211	1531.30456542969	4.06604818999767	1.82560971006751	0.036439023911953	38.37856
5.00999975204468	1545.79797363281	4.14958922192454	1.86951213981956	0.0372439026832581	38.741804
5.1100001335144	1551.03796386719	4.23266878351569	1.91341468598694	0.0381951220333576	38.873132
5.21000003814697	1564.63037109375	4.31574834510684	1.96097558364272	0.0391463413834572	39.213792
5.30999994277954	1569.39489746094	4.39928937703371	2.00487812981009	0.0400243885815144	39.333204
5.41000032424927	1580.650390625	4.48236847296357	2.04878044314682	0.0408292710781097	39.6153
5.51000022888184	1590.46691894531	4.56567900255322	2.0926829893142	0.041780486702919	39.861328
5.6100001335144	1596.78393554688	4.64922003448009	2.14390247128904	0.0428048819303513	40.019648
5.71000003814697	1606.41967773438	4.73229959607124	2.19146348536015	0.0437560975551605	40.261144
5.80999994277954	1613.65869140625	4.81537915766239	2.23536579869688	0.044634148478508	40.442572
5.90999984741211	1622.94360351563	4.89892018958926	2.28292681276798	0.0455853678286076	40.67528
6.00999975204468	1626.69262695313	4.98223025351763	2.32682935893536	0.0465365871787071	40.76924
6.1100001335144	1632.75219726563	5.06554031744599	2.3780488409102	0.0474146343767643	40.921108
6.21000003814697	1640.50830078125	5.14885084703565	2.42195115424693	0.0482926853001118	41.115496
6.30999994277954	1645.56274414063	5.23216091096401	2.46951216831803	0.0492439046502113	41.242176
6.41000032424927	1649.72839355469	5.31547144055367	2.51707318238914	0.050268292427063	41.346576
6.51000022888184	1657.81079101563	5.39901247248054	2.56463419646025	0.0512195080518723	41.549144
6.6100001335144	1661.84802246094	5.4820915684104	2.61585367843509	0.0522439032793045	41.650328
6.71000003814697	1668.005859375	5.56540209800005	2.65975599177182	0.0531219504773617	41.80466
6.80999994277954	1673.6279296875	5.64871216192842	2.7109757065773	0.0541463419795036	41.945564
6.90999984741211	1677.15893554688	5.73179172351956	2.75853648781776	0.0550975613296032	42.03406
7.00999975204468	1681.02966308594	5.81510178744793	2.80975620262325	0.0560487806797028	42.131068
7.1100001335144	1689.52221679688	5.89841231703758	2.85731698386371	0.0570731684565544	42.343916
7.21000003814697	1691.80822753906	5.98149187862873	2.91219516657293	0.0581707358360291	42.401208
7.30999994277954	1695.92565917969	6.0648019425571	2.95609747990966	0.0591219514608383	42.504404
7.41000032424927	1699.72058105469	6.14811247214675	3.0073169618845	0.0600731708109379	42.599512
7.51000022888184	1706.90490722656	6.23119156807661	3.05853667668998	0.0610243901610374	42.779572
7.6100001335144	1707.23071289063	6.31450209766626	3.10609745793045	0.0620487779378891	42.787736
7.71000003814697	1712.2822265625	6.39781216159463	3.15731717273593	0.063000001013279	42.91434
7.80999994277954	1716.7705078125	6.48112269118428	3.20853665471077	0.0640243887901306	43.026828
7.90999984741211	1721.34533691406	6.56443275511265	3.25975613668561	0.0650487765669823	43.141488
8.01000022888184	1721.06921386719	6.64797378703952	3.31097561866045	0.0661463439464569	43.134568
8.11000061035156	1725.1689453125	6.73105334863067	3.36219510063529	0.0671707317233086	43.237316
8.21000003814697	1728.66772460938	6.81459438055754	3.41341458261013	0.0680487751960754	43.325004
8.3100004196167	1732.50415039063	6.8979044444859	3.46463406458497	0.0691463425755501	43.421156
8.40999984741211	1734.58190917969	6.98121497407556	3.50853661075234	0.0700975656509399	43.473232
8.51000022888184	1737.24816894531	7.06475600600243	3.55975609272718	0.0711219534277916	43.540056
8.60999965667725	1737.47216796875	7.1482970379293	3.61463404260576	0.0721463412046433	43.545668
8.71000003814697	1741.17199707031	7.23160710185766	3.66219505667686	0.0731707289814949	43.638396
8.8100004196167	1743.75573730469	7.31514813378453	3.70975607074797	0.0741219520568848	43.703152
8.90999984741211	1745.4306640625	7.3986891657114	3.76097555272281	0.0751463398337364	43.745128
9.01000022888184	1747.30712890625	7.48199922963977	3.81585373543203	0.0761707276105881	43.79216
9.11000061035156	1748.49389648438	7.56554026156664	3.8707316853106	0.0772682949900627	43.821904
9.21000003814697	1752.37829589844	7.64885079115629	3.92560986801982	0.0783658474683762	43.919256
9.3100004196167	1754.82739257813	7.73216085508466	3.97682934999466	0.0794634148478508	43.980636
9.40999984741211	1754.14770507813	7.81547091901302	4.03170753270388	0.0804878026247025	43.9636
9.51000022888184	1758.40161132813	7.89878144860268	4.08292701467872	0.0815853625535965	44.070216
9.60999965667725	1757.89196777344	7.98186101019382	4.13414649665356	0.0826097577810287	44.057444
9.71000003814697	1760.38793945313	8.06540157645941	4.18902421370149	0.0837073177099228	44.12
9.8100004196167	1759.11877441406	8.14871210604906	4.24024369567633	0.084731712937355	44.088188
9.90999984741211	1758.41821289063	8.23202263563871	4.29512187838554	0.0857561007142067	44.070632
10.0100002288818	1761.43432617188	8.31533316522837	4.34634136036038	0.0868536606431007	44.146224
10.1100006103516	1761.13745117188	8.39864276349545	4.4012195430696	0.0879512131214142	44.138784
10.210000038147	1762.96362304688	8.4819532930851	4.45975596085191	0.0890487805008888	44.184552
10.3100004196167	1761.42272949219	8.56526382267475	4.51097544282675	0.0901463478803635	44.145932
10.4099998474121	1763.34020996094	8.64857342094183	4.56585362553597	0.0912439003586769	44.193992
10.5100002288818	1763.61657714844	8.73188395053148	4.61341440677643	0.0921951234340668	44.200916
10.6099996566772	1763.02282714844	8.81542544811964	4.67195129022002	0.0932926833629608	44.186036
10.710000038147	1764.5439453125	8.89873504638672	4.73048770800233	0.0944634154438972	44.22416
10.8100004196167	1764.25903320313	8.98227654397488	4.78170718997717	0.0954878032207489	44.21702
10.9099998474121	1761.75756835938	9.06558707356453	4.83658537268639	0.0965853706002235	44.154324
11.0100002288818	1763.46984863281	9.14912763983011	4.89512179046869	0.0978292673826218	44.19724
11.1100006103516	1759.46435546875	9.23266913741827	4.94999997317791	0.098853662610054	44.096852
11.210000038147	1761.85559082031	9.31620970368385	5.00487815588713	0.0999512150883675	44.15678
11.3100004196167	1759.17663574219	9.399289265275	5.06341457366943	0.101121954619884	44.08964
11.4099998474121	1757.83312988281	9.48282983154058	5.12195099145174	0.10229267925024	44.055968
11.4700002670288	0.123207993805408	9.53290890902281	4.86951228231192	0.101414628326893	0.00308791967773437