File: Tensile_tests/PA12_C5_XY_1 07-5-22 12 02 22 PM/DAQ- Time, … - (Timed).txt
File Path: C:\MTS TestSuite\Data Files\Chahine\DOE\PA12_C5_XY_1 07-5-22 12 02 22 PM\DAQ- Time, … - (Timed).txt
Test: MTS EM Tension (Extensometer)_Grand_Chahine 1
Test Run: PA12_C5_XY_1
Date: 7/5/2022 12:01:53 PM


Time 	Load 	Crosshead 	Extensometer 	Strain 	Stress
sec	N	mm	mm	mm/mm	N/mm²
0.180000066757202	78.3417129516602	0.107772546471097	0.0292682925646659	0.000512195110786706	1.872926625
0.280000030994415	136.464096069336	0.19108279957436	0.0548780481040012	0.00109756097663194	3.262467
0.379999995231628	188.880096435547	0.274162273854017	0.0841463406686671	0.00160975614562631	4.515584
0.479999989271164	242.867614746094	0.357472541509196	0.109756096208002	0.00219512195326388	5.806271
0.579999923706055	294.285461425781	0.440782780060545	0.142682925797999	0.00285365851595998	7.035525
0.679999887943268	345.478210449219	0.524323841091245	0.179268288775347	0.00351219531148672	8.2593975
0.779999911785126	394.121887207031	0.607403286267072	0.215853651752695	0.0042439023964107	9.422329
0.879999876022339	446.149230957031	0.690482789650559	0.252439029281959	0.00497560948133469	10.666154
0.980000138282776	495.15087890625	0.773793028201908	0.289024377707392	0.00570731703191996	11.837644
1.08000004291534	542.718994140625	0.856641738209873	0.32926828134805	0.00651219487190247	12.974861
1.1800000667572	589.051513671875	0.939721241593361	0.3548780514393	0.00702439062297344	14.08254
1.28000009059906	640.687683105469	1.02326227352023	0.384146347641945	0.00760975573211908	15.317013
1.37999999523163	685.039428710938	1.1061109835282	0.417073169955984	0.00834146328270435	16.377337
1.48000001907349	729.730712890625	1.18942116387188	0.457317073596641	0.00899999961256981	17.445778
1.57999992370605	775.579711914063	1.27273146063089	0.501219532452524	0.00995121896266937	18.541896
1.67999994754791	820.331848144531	1.3560417573899	0.534146325662732	0.0106829265132546	19.611792
1.77999985218048	859.050537109375	1.43958278931677	0.567073177080601	0.0112682934850454	20.537446
1.87999987602234	903.145751953125	1.52312382124364	0.603658554609865	0.0120000001043081	21.591636
1.98000013828278	944.559692382813	1.60620326641947	0.640243873931468	0.0126585364341736	22.581726
2.08000016212463	984.488952636719	1.68974429834634	0.676829251460731	0.0134634142741561	23.53632
2.1800000667572	1023.63494873047	1.77328533027321	0.706097576767206	0.0140487812459469	24.472188
2.27999997138977	1066.42529296875	1.85659562703222	0.74268295429647	0.0147804878652096	25.495184
2.38000011444092	1101.6455078125	1.94013665895909	0.771951221395284	0.0153658539056778	26.337198
2.48000001907349	1142.2939453125	2.02367757447064	0.808536598924547	0.0160975605249405	27.308986
2.57999992370605	1179.58129882813	2.10698787122965	0.841463392134756	0.0168292671442032	28.20042
2.67999982833862	1214.14721679688	2.19052890315652	0.885365880094469	0.017560975626111	29.026794
2.77999997138977	1249.84020996094	2.27406993508339	0.918292673304677	0.0182926822453737	29.88011
2.87999987602234	1284.63830566406	2.35714949667454	0.958536576945335	0.0190243907272816	30.712034
2.98000001907349	1316.16369628906	2.44045979343355	0.991463428363204	0.0197560973465443	31.465716
3.08000016212463	1346.91369628906	2.52376985736191	1.02804880589247	0.020487803965807	32.20086
3.1800000667572	1376.21899414063	2.60684941895306	1.06463418342173	0.021292682737112	32.901466
3.27999997138977	1407.93811035156	2.69015971571207	1.10121956095099	0.0219512190669775	33.65978
3.38000011444092	1438.17895507813	2.77347001247108	1.13048776984215	0.0225365869700909	34.382752
3.48000001907349	1466.36340332031	2.85654934123158	1.17073173169047	0.0233414620161057	35.05656
3.57999992370605	1494.18408203125	2.93985963799059	1.21097557712346	0.0241463426500559	35.721676
3.67999982833862	1516.81518554688	3.02293919958174	1.24756095465273	0.0248780492693186	36.26272
3.77999997138977	1545.74694824219	3.10601876117289	1.28780491650105	0.0257560983300209	36.954396
3.87999987602234	1567.13793945313	3.18932882510126	1.32804876193404	0.0264878049492836	37.465792
3.98000001907349	1589.38537597656	3.2724083866924	1.36829272378236	0.0272926837205887	37.997668
4.07999992370605	1611.5146484375	3.35548794828355	1.40853656921536	0.0280975624918938	38.526712
4.18000030517578	1629.34326171875	3.43879801221192	1.45243899896741	0.0289756096899509	38.952944
4.28000020980835	1650.44580078125	3.52210830897093	1.49634142871946	0.0298536587506533	39.457448
4.38000011444092	1666.9833984375	3.60518787056208	1.54024385847151	0.0307317078113556	39.852812
4.48000001907349	1680.68286132813	3.68872890248895	1.58780487254262	0.0316097550094128	40.180328
4.57999992370605	1697.63061523438	3.77226993441582	1.63170730229467	0.0325609780848026	40.5855
4.67999982833862	1714.07885742188	3.85534949600697	1.67560973204672	0.0334390252828598	40.978732
4.77999973297119	1728.04113769531	3.93889052793384	1.71951216179878	0.0343902446329594	41.312528
4.87999963760376	1741.17065429688	4.02243155986071	1.76707317586988	0.0352682918310165	41.62642
4.98000001907349	1755.3359375	4.10574162378907	1.80731702130288	0.0361463390290737	41.965072
5.07999992370605	1763.09423828125	4.18905215337873	1.85487803537399	0.0369512215256691	42.150548
5.18000030517578	1776.08630371094	4.2725931853056	1.90243904944509	0.0379756093025208	42.461152
5.28000020980835	1789.80212402344	4.35590324923396	1.94999994710088	0.0389268286526203	42.78906
5.38000011444092	1797.33642578125	4.43967524915934	1.99756096117198	0.0398780480027199	42.96918
5.48000001907349	1808.23950195313	4.52321628108621	2.05243891105056	0.0409024395048618	43.229844
5.57999992370605	1816.03845214844	4.60629537701607	2.10365862585604	0.0419999994337559	43.416292
5.67999982833862	1821.49108886719	4.68983640894294	2.15121940709651	0.0429512187838554	43.546652
5.77999973297119	1834.66418457031	4.77337744086981	2.20609758980572	0.0439756065607071	43.861584
5.87999963760376	1840.634765625	4.85645700246096	2.25731707178056	0.044999998062849	44.00432
5.98000001907349	1847.41760253906	4.93976753205061	2.3085365537554	0.0460975617170334	44.16648
6.07999992370605	1856.81408691406	5.02307759597898	2.36341473646462	0.047121949493885	44.391124
6.18000030517578	1864.20153808594	5.10615715757012	2.40731704980135	0.048146340996027	44.567736
6.28000020980835	1868.35375976563	5.18946722149849	2.45853653177619	0.0490243919193745	44.667004
6.38000011444092	1876.59790039063	5.27254678308964	2.5060975458473	0.0500487834215164	44.864096
6.48000001907349	1880.94970703125	5.35562634468079	2.55000009201467	0.0509268268942833	44.968136
6.57999992370605	1885.7099609375	5.43893640860915	2.60121957398951	0.0519512183964252	45.08194
6.67999982833862	1893.34594726563	5.5220159702003	2.66707316040993	0.0531951189041138	45.264496
6.77999973297119	1897.44543457031	5.60486456379294	2.7219511102885	0.0542926825582981	45.362504
6.87999963760376	1903.07958984375	5.6881750933826	2.76585365645587	0.0552439019083977	45.4972
6.98000001907349	1908.11413574219	5.77148515731096	2.81341467052698	0.0561951249837875	45.61756
7.07999992370605	1915.63049316406	5.85456471890211	2.86829262040555	0.0572926849126816	45.797256
7.18000030517578	1917.87426757813	5.93787478283048	2.91585363447666	0.0582439042627811	45.850896
7.28000020980835	1923.46508789063	6.02095434442163	2.97804875299335	0.0594146363437176	45.98456
7.38000011444092	1929.14196777344	6.10403390601277	3.02560976706445	0.0603658519685268	46.120276
7.48000001907349	1934.29797363281	6.18757493793964	3.08048771694303	0.0615365840494633	46.24354
7.57999992370605	1937.30383300781	6.2708854675293	3.13170743174851	0.0624878033995628	46.315404
7.67999982833862	1944.04345703125	6.35396456345916	3.18292691372335	0.0635853633284569	46.476528
7.77999973297119	1945.52294921875	6.43750559538603	3.23414639569819	0.0645365864038467	46.5119
7.87999963760376	1949.7958984375	6.52081612497568	3.28902434557676	0.0657073184847832	46.614052
7.98000001907349	1954.19079589844	6.60389568656683	3.34756099618971	0.0668048784136772	46.719124
8.07999992370605	1957.65209960938	6.6872057504952	3.39878047816455	0.0679024383425713	46.801872
8.18000030517578	1958.55541992188	6.77074678242207	3.46097559668124	0.0690731704235077	46.823468
8.27999973297119	1964.80920410156	6.85405684635043	3.51585354655981	0.0702439025044441	46.972976
8.38000011444092	1966.66076660156	6.93736737594008	3.56341456063092	0.071195125579834	47.017244
8.47999954223633	1969.70458984375	7.02067743986845	3.61829274334013	0.0722195133566856	47.090012
8.57999992370605	1973.73046875	7.1037570014596	3.66585375741124	0.0732439011335373	47.18626
8.68000030517578	1977.22961425781	7.18729803338647	3.71707323938608	0.0742682889103889	47.269916
8.77999973297119	1979.91052246094	7.27060809731483	3.77195118926466	0.0753658562898636	47.334008
8.88000011444092	1980.51440429688	7.35368765890598	3.83414630778134	0.0765365883708	47.348444
8.98000049591064	1986.0380859375	7.43722869083285	3.88536578975618	0.0776341482996941	47.4805
9.07999992370605	1985.35485839844	7.52053922042251	3.94756114110351	0.0787317082285881	47.464164
9.18000030517578	1989.53161621094	7.60361878201365	4.00243885815144	0.0799756124615669	47.56402
9.27999973297119	1991.04223632813	7.68669787794352	4.06097574159503	0.0810731649398804	47.600136
9.38000011444092	1991.42248535156	7.77000840753317	4.11585345864296	0.0822439044713974	47.609224
9.47999954223633	1993.18872070313	7.85331893712282	4.17073164135218	0.0833414644002914	47.651452
9.57999992370605	1996.68664550781	7.9366285353899	4.22926852479577	0.0845121964812279	47.735076
9.68000030517578	1998.53662109375	8.01970809698105	4.29146364331245	0.0856829285621643	47.779304
9.77999973297119	2000.64685058594	8.1027876585722	4.35000006109476	0.0868536606431007	47.829752
9.88000011444092	2004.646484375	8.18609818816185	4.40853647887707	0.0880975648760796	47.925372
9.98000049591064	2005.01708984375	8.2694087177515	4.45975596085191	0.0891219526529312	47.934232
10.0799999237061	2006.97216796875	8.35271831601858	4.51463414356112	0.0902195125818253	47.980972
10.1800003051758	2007.04174804688	8.43625981360674	4.57317056134343	0.0913170725107193	47.982636
10.2799997329712	2008.45080566406	8.51933937519789	4.63170744478703	0.0925609767436981	48.016324
10.3800001144409	2011.35327148438	8.60264897346497	4.69390256330371	0.0936585366725922	48.085712
10.4799995422363	2010.33630371094	8.68595950305462	4.75243898108602	0.094902440905571	48.0614
10.5799999237061	2011.5107421875	8.76950100064278	4.81097539886832	0.0960731655359268	48.08948
10.6800003051758	2012.14770507813	8.85304156690836	4.86951228231192	0.0973170697689056	48.104708
10.7799997329712	2016.36303710938	8.93658306449652	4.9317074008286	0.0984878093004227	48.205484
10.8800001144409	2016.3876953125	9.01966169476509	4.98292688280344	0.0995853617787361	48.206072
10.9800004959106	2015.71838378906	9.10320319235325	5.04146330058575	0.100682929158211	48.190072
11.0799999237061	2015.84753417969	9.18674375861883	5.09634148329496	0.101853653788567	48.19316
11.1800003051758	2017.71691894531	9.27005428820848	5.16219530254602	0.103097558021545	48.237852
11.2799997329712	2018.06396484375	9.35359578579664	5.21707301959395	0.104195117950439	48.246148
11.3800001144409	2018.53515625	9.43690538406372	5.27195120230317	0.105292685329914	48.257412
11.4799995422363	2020.26843261719	9.51998494565487	5.33414632081985	0.106609754264355	48.298848
11.5799999237061	2020.13696289063	9.60352644324303	5.39634143933654	0.107780486345291	48.295708
11.6800003051758	2019.09460449219	9.68660600483418	5.45853655785322	0.109097555279732	48.270788
11.7799997329712	2017.27526855469	9.76991560310125	5.51707297563553	0.110195122659206	48.227292
11.8800001144409	2021.32824707031	9.85322613269091	5.57560985907912	0.111439019441605	48.324188
11.9800004959106	2019.22277832031	9.93653666228056	5.64512191340327	0.112756103277206	48.273852
12.0799999237061	2019.26196289063	10.0198471918702	5.70731703191996	0.114000000059605	48.274788
12.1800003051758	2018.94458007813	10.1031567901373	5.76219521462917	0.115097567439079	48.2672
12.2799997329712	2021.45983886719	10.1864673197269	5.82804856821895	0.11641463637352	48.327332
12.3800001144409	2020.26831054688	10.2697778493166	5.89024368673563	0.117731705307961	48.298848
12.4799995422363	2021.42004394531	10.3530874475837	5.95243880525231	0.118902437388897	48.32638
12.5799999237061	2020.04162597656	10.4363979771733	6.014633923769	0.120219513773918	48.293428
12.6800003051758	2017.76782226563	10.5194775387645	6.07317080721259	0.121390238404274	48.239068
12.7799997329712	2019.38488769531	10.6027880683541	6.14268286153674	0.122707322239876	48.277728
12.8800001144409	2017.54736328125	10.6865596026182	6.20487798005342	0.123951219022274	48.233796
12.9800004959106	2015.74548339844	10.7696391642094	6.27439003437757	0.125341460108757	48.19072
13.0799999237061	2016.34497070313	10.8531797304749	6.33658515289426	0.126585364341736	48.205052
13.1800003051758	2016.90551757813	10.9367212280631	6.39146333560348	0.127756103873253	48.218452
13.2799997329712	2013.28515625	11.0200317576528	6.46097538992763	0.129073172807693	48.1319
13.3800001144409	2014.17321777344	11.1033413559198	6.52682920917869	0.130390241742134	48.153132
13.4799995422363	2013.96276855469	11.186882853508	6.59268302842975	0.131707325577736	48.1481
13.5799999237061	2011.4638671875	11.2699624150991	6.65487814694643	0.132951229810715	48.088356
13.6800003051758	2014.04760742188	11.3535029813647	6.7207315005362	0.134268283843994	48.150128
13.7799997329712	2011.66015625	11.4370444789529	6.79024402052164	0.135658532381058	48.093052
13.8800001144409	2008.89916992188	11.52035407722	6.86341477558017	0.137195125222206	48.027044
13.9800004959106	2007.34558105469	11.6036646068096	6.93292682990432	0.138585358858109	47.9899
14.0799999237061	2008.89404296875	11.6874361410737	7.00243888422847	0.13990244269371	48.02692
14.1800003051758	2005.36853027344	11.7705157026649	7.06829270347953	0.141219511628151	47.942636
14.2799997329712	2004.16687011719	11.854057200253	7.13414652273059	0.142536580562592	47.913908
14.3800001144409	2002.25891113281	11.9373677298427	7.20365857705474	0.143999993801117	47.868292
14.4799995422363	2002.5576171875	12.0204463601112	7.26585369557142	0.145243898034096	47.875436
14.5799999237061	1997.86889648438	12.1037568897009	7.33536574989557	0.146560981869698	47.76334
14.6800003051758	1998.83935546875	12.1870674192905	7.40487826988101	0.148024395108223	47.78654
14.7799997329712	1996.55383300781	12.2701469808817	7.47439032420516	0.149414628744125	47.7319
14.8800001144409	1993.95324707031	12.3534565791488	7.54024367779493	0.150658532977104	47.669728
14.9800004959106	1992.5029296875	12.4367671087384	7.60975619778037	0.151975616812706	47.635056
15.0799999237061	1988.8388671875	12.5198466703296	7.67926825210452	0.153365850448608	47.54746
15.1800003051758	1986.78002929688	12.6031571999192	7.75609770789742	0.154975607991219	47.498236
15.2799997329712	1984.15405273438	12.6864677295089	7.82926846295595	0.156439021229744	47.435456
15.3800001144409	1984.67370605469	12.769777327776	7.90609791874886	0.157975614070892	47.44788
15.4799995422363	1978.8798828125	12.8533188253641	7.9792682081461	0.159439012408257	47.309368
15.5799999237061	1974.62145996094	12.9366284236312	8.05975589901209	0.161048784852028	47.20756
15.6800003051758	1973.90173339844	13.0197079852223	8.1329271197319	0.162512198090553	47.190356
15.7799997329712	1969.80749511719	13.1032494828105	8.20975564420223	0.16397562623024	47.092472
15.8800001144409	1967.34106445313	13.1867900490761	8.28658509999514	0.165512189269066	47.033508
15.9800004959106	1966.98010253906	13.2698696106672	8.35609715431929	0.166975617408752	47.024876
16.0799999237061	1962.49645996094	13.3534111082554	8.43292661011219	0.16851219534874	46.917688
16.1800003051758	1957.67602539063	13.4367207065225	8.506097830832	0.170048773288727	46.802444
16.2800006866455	1955.28356933594	13.5195702314377	8.586585521698	0.171512201428413	46.745248
16.3799991607666	1948.77429199219	13.6031107977033	8.6634149774909	0.173121958971024	46.589628
16.4799995422363	1943.54162597656	13.6864213272929	8.74024350196123	0.174658536911011	46.464532
16.5799999237061	1939.04064941406	13.76973092556	8.82804859429598	0.176414638757706	46.356924
16.6800003051758	1931.82189941406	13.8535033911467	8.91219545155764	0.177951216697693	46.184344
16.7800006866455	1927.99255371094	13.9365829527378	8.98536574095488	0.179560959339142	46.092796
16.8799991607666	1920.822265625	14.019662514329	9.07317083328962	0.181243896484375	45.921376
16.9799995422363	1913.78747558594	14.102972112596	9.15365852415562	0.182926818728447	45.753196
17.0799999237061	1908.65832519531	14.1862826421857	9.23414621502161	0.184463411569595	45.630572
17.1800003051758	1899.57983398438	14.2691312357783	9.32195130735636	0.186292678117752	45.413528
17.2800006866455	1890.34729003906	14.352441765368	9.41707286983728	0.188195124268532	45.192808
17.3799991607666	1881.25024414063	14.4355213269591	9.50121972709894	0.189878046512604	44.97532
17.4799995422363	1867.94201660156	14.5183699205518	9.59268305450678	0.191634148359299	44.65716
17.5799999237061	1855.26940917969	14.6016804501414	9.68048814684153	0.193463414907455	44.354196
17.6800003051758	1838.03198242188	14.68475908041	9.77926794439554	0.195365846157074	43.942096
17.7800006866455	1816.75268554688	14.7678386420012	9.88170690834522	0.1974878013134	43.433368
17.8799991607666	1781.16455078125	14.8513801395893	9.99512150883675	0.199609756469727	42.58256
17.9799995422363	0.612725734710693	14.9344597011805	10.5219511315227	0.206121951341629	0.0146485224609375
18.0200004577637	2.61950731277466	14.9674601852894	10.6499996036291	0.211829259991646	0.06262494140625