File: Tensile_tests/PA12vp_C1_XZ_8 05-16-22 15 27 03 PM/DAQ- Time, … - (Timed).txt
File Path: C:\MTS TestSuite\Data Files\Chahine\DOE\PA12vp_C1_XZ_8 05-16-22 15 27 03 PM\DAQ- Time, … - (Timed).txt
Test: MTS EM Tension (Extensometer)_Grand_Chahine 1
Test Run: PA12vp_C1_XZ_8
Date: 5/16/2022 3:26:33 PM


Time 	Load 	Crosshead 	Extensometer 	Strain 	Stress
sec	N	mm	mm	mm/mm	N/mm²
0.100000001490116	46.0985069274902	0.0611557261436246	0.0182926833076635	0.000292682932922617	1.170963875
0.200000002980232	100.446311950684	0.144004428875633	0.0439024406659883	0.000804878072813153	2.551471
0.300000011920929	159.392562866211	0.228237797273323	0.0768292666180059	0.00146341463550925	4.04878475
0.400000005960464	215.899490356445	0.311778829200193	0.106097562820651	0.00204878044314682	5.4841365
0.5	269.064422607422	0.395089067751542	0.135365859023295	0.0026341462507844	6.834597
0.600000023841858	323.913970947266	0.478399335406721	0.168292681337334	0.0032926828134805	8.2278495
0.699999988079071	377.547271728516	0.561709573958069	0.212195125641301	0.00417073164135218	9.590207
0.800000011920929	428.721618652344	0.644558283966035	0.252439029281959	0.00497560948133469	10.890104
0.899999976158142	477.027282714844	0.727868522517383	0.289024377707392	0.00570731703191996	12.117133
1	529.693237304688	0.810948025900871	0.325609755236655	0.00643902458250523	13.454919
1.10000002384186	578.720031738281	0.894258264452219	0.365853658877313	0.00717073166742921	14.700265
1.20000004768372	630.95947265625	0.977337709628046	0.402439036406577	0.00797560997307301	16.027217
1.29999995231628	681.819152832031	1.06041727121919	0.43902438483201	0.00870731752365828	17.31912
1.39999997615814	728.002197265625	1.14372745156288	0.468292681034654	0.00936585385352373	18.492232
1.5	778.476013183594	1.22703774832189	0.504878058563918	0.0100243911147118	19.774334
1.60000002384186	823.819458007813	1.3103480450809	0.541463436093181	0.0107560968026519	20.92612
1.70000004768372	868.543884277344	1.39365822542459	0.57439022930339	0.0114146340638399	22.06218
1.79999995231628	911.848999023438	1.47719925735146	0.610975606832653	0.0121463416144252	23.162188
1.89999997615814	956.439147949219	1.56050955411047	0.643902458250523	0.0128780491650105	24.294838
2	1001.88470458984	1.64381985086948	0.680487777572125	0.0135365854948759	25.449216
2.09999990463257	1042.86389160156	1.72736088279635	0.713414628989995	0.0141951218247414	26.490142
2.20000004768372	1087.28247070313	1.81090191472322	0.750000006519258	0.0149268293753266	27.618434
2.29999995231628	1128.49536132813	1.89444294665009	0.782926857937127	0.0156585369259119	28.665296
2.40000009536743	1169.75988769531	1.97798386216164	0.81951217725873	0.0163170732557774	29.71347
2.5	1207.07800292969	2.06129415892065	0.856097554787993	0.0170487798750401	30.6614
2.59999990463257	1249.626953125	2.14460445567966	0.892682932317257	0.0177073180675507	31.7422
2.70000004768372	1286.59887695313	2.22814548760653	0.925609783735126	0.0184390246868134	32.681338
2.79999995231628	1322.30615234375	2.31145578436553	0.958536576945335	0.0190975610166788	33.588348
2.90000009536743	1360.75170898438	2.39476608112454	0.991463428363204	0.0197560973465443	34.56492
3	1393.31018066406	2.47807614505291	1.02804880589247	0.020487803965807	35.391948
3.09999990463257	1426.73400878906	2.56115570664406	1.06463418342173	0.0212195124477148	36.240956
3.20000004768372	1461.00537109375	2.64446600340307	1.10853661317378	0.0220243912190199	37.111496
3.29999995231628	1488.80151367188	2.72754556499422	1.14146340638399	0.0227560959756374	37.817556
3.40000009536743	1521.791015625	2.81062489375472	1.17804878391325	0.0234878044575453	38.655532
3.5	1553.65686035156	2.89393519051373	1.21829262934625	0.0242926832288504	39.464968
3.59999990463257	1578.46337890625	2.97724548727274	1.25853659119457	0.0250975601375103	40.095088
3.70000004768372	1606.60815429688	3.06009408086538	1.30243902094662	0.0259024389088154	40.81
3.79999995231628	1633.55395507813	3.14340437762439	1.33902439847589	0.0267073158174753	41.49446
3.90000009536743	1655.46618652344	3.22648393921554	1.37926824390888	0.0275121964514256	42.05106
4	1676.18273925781	3.30956326797605	1.42317079007626	0.0283902436494827	42.577288
4.09999990463257	1697.423828125	3.39287356473506	1.46341463550925	0.0291951205581427	43.11684
4.19999980926514	1718.35095214844	3.47618386149406	1.50365848094225	0.0300000011920929	43.64842
4.30000019073486	1732.84436035156	3.55926342308521	1.54390244279057	0.0308048762381077	44.016572
4.40000009536743	1748.7626953125	3.64257371984422	1.59146345686167	0.0317560955882072	44.420916
4.5	1766.37280273438	3.72588378377259	1.63902435451746	0.0327073186635971	44.86824
4.59999990463257	1779.8349609375	3.8091940805316	1.68292678426951	0.0336585342884064	45.210196
4.69999980926514	1794.9384765625	3.89273511245847	1.73048779834062	0.0345365852117538	45.593844
4.80000019073486	1808.84045410156	3.97627614438534	1.77804881241173	0.0354878045618534	45.946972
4.90000009536743	1819.26245117188	4.05958667397499	1.82560971006751	0.0363658517599106	46.211708
5	1829.76635742188	4.14289673790336	1.86951213981956	0.0372439026832581	46.47852
5.09999990463257	1844.89868164063	4.22620680183172	1.91707315389067	0.0383414626121521	46.8629
5.19999980926514	1852.11889648438	4.30951733142138	1.97195122018456	0.0392926819622517	47.046304
5.30000019073486	1860.71545410156	4.39305836334825	2.01951223425567	0.0403170734643936	47.264668
5.40000009536743	1867.9140625	4.47682989761233	2.06707324832678	0.0412682890892029	47.447524
5.5	1876.15856933594	4.55990945920348	2.11097556166351	0.0421463400125504	47.656944
5.59999990463257	1880.27746582031	4.64321998879313	2.16219504363835	0.0431707315146923	47.761568
5.69999980926514	1887.55493164063	4.72676102072001	2.21341452561319	0.0441951230168343	47.946428
5.80000019073486	1894.51684570313	4.80984011664987	2.2609755396843	0.0451463423669338	48.123268
5.90000009536743	1901.33605957031	4.89315064623952	2.31585372239351	0.0461707301437855	48.296484
6	1909.42895507813	4.97669167816639	2.36707320436835	0.0472682937979698	48.502056
6.09999990463257	1912.41369628906	5.05954027175903	2.41829268634319	0.0482926853001118	48.577872
6.19999980926514	1917.50793457031	5.1428503356874	2.47317063622177	0.0493170730769634	48.707272
6.30000019073486	1925.99194335938	5.22592989727855	2.52804881893098	0.0504878088831902	48.92278
6.40000009536743	1928.31359863281	5.3090094588697	2.57926830090582	0.0514390245079994	48.981752
6.5	1936.40734863281	5.39208902046084	2.63048778288066	0.0524634160101414	49.187344
6.59999990463257	1938.14892578125	5.47539908438921	2.68536596558988	0.0535609759390354	49.231584
6.69999980926514	1943.43969726563	5.55824814364314	2.73658544756472	0.0546585358679295	49.365976
6.80000019073486	1947.63049316406	5.64155820757151	2.78780492953956	0.0556829236447811	49.472428
6.90000009536743	1950.43994140625	5.72463776916265	2.84268287941813	0.0567804872989655	49.543792
7	1954.57934570313	5.8077173307538	2.89024389348924	0.0577317103743553	49.648936
7.09999990463257	1959.50085449219	5.89102739468217	2.94878054410219	0.0588292665779591	49.773948
7.19999980926514	1962.25756835938	5.97433745861053	3.0073169618845	0.0600000023841858	49.843972
7.30000019073486	1964.43627929688	6.05718651786447	3.05853667668998	0.0610243901610374	49.899316
7.40000009536743	1968.7509765625	6.14072754979134	3.11341462656856	0.0621951222419739	50.008916
7.5	1974.27416992188	6.2240376137197	3.16829257644713	0.0632195100188255	50.149212
7.59999990463257	1977.97802734375	6.30711717531085	3.21951229125261	0.064390242099762	50.243296
7.69999980926514	1978.01672363281	6.39042723923922	3.27804870903492	0.0654146373271942	50.244276
7.80000019073486	1980.9443359375	6.47373776882887	3.33292689174414	0.0665121972560883	50.318644
7.90000009536743	1983.62097167969	6.55704783275723	3.38780484162271	0.0676097571849823	50.386632
8	1985.46655273438	6.64035836234689	3.43902432359755	0.0687073171138763	50.433512
8.10000038146973	1987.44738769531	6.72366842627525	3.4975609742105	0.0698048770427704	50.483828
8.19999980926514	1990.79541015625	6.80697849020362	3.54878045618534	0.0709024369716644	50.568872
8.30000019073486	1990.60791015625	6.89051952213049	3.60365863889456	0.0719999969005585	50.564112
8.39999961853027	1995.05163574219	6.97383005172014	3.65853658877313	0.0731707289814949	50.676988
8.5	1995.2822265625	7.05690961331129	3.71707323938608	0.0741951242089272	50.682844
8.60000038146973	1999.73364257813	7.14045064523816	3.77195118926466	0.0752926841378212	50.795916
8.69999980926514	2002.18469238281	7.22376070916653	3.82682937197387	0.0763902440667152	50.858176
8.80000019073486	2002.57043457031	7.30707077309489	3.88536578975618	0.0775609761476517	50.867976
8.89999961853027	2004.44982910156	7.39038130268455	3.94390244036913	0.0787317082285881	50.915716
9	2007.60205078125	7.47369136661291	4.00243885815144	0.0799024403095245	50.995784
9.10000038146973	2008.3095703125	7.55677092820406	4.06097574159503	0.0811463445425034	51.013756
9.19999980926514	2007.83325195313	7.64008145779371	4.11585345864296	0.0822439044713974	51.001656
9.30000019073486	2009.36645507813	7.72316055372357	4.17439034208655	0.0834146291017532	51.040604
9.39999961853027	2008.98461914063	7.80647108331323	4.23292675986886	0.0845121964812279	51.030904
9.5	2011.15185546875	7.88955017924309	4.28780494257808	0.0856829285621643	51.085956
9.60000038146973	2014.05578613281	7.97286070883274	4.34634136036038	0.0867804884910584	51.15972
9.69999980926514	2014.55053710938	8.05617123842239	4.4012195430696	0.0878780484199524	51.172284
9.80000019073486	2017.72229003906	8.13925080001354	4.45975596085191	0.0890487805008888	51.252852
9.89999961853027	2019.96276855469	8.22256039828062	4.51463414356112	0.0901463478803635	51.309764
10	2019.91650390625	8.30587092787027	4.57317056134343	0.0913902446627617	51.308588
10.1000003814697	2019.48217773438	8.38941242545843	4.63170744478703	0.0924877971410751	51.297556
10.1999998092651	2020.9521484375	8.47272202372551	4.6975607983768	0.093731701374054	51.334896
10.3000001907349	2019.5751953125	8.55603255331516	4.74878028035164	0.0948292687535286	51.29992
10.3999996185303	2019.697265625	8.63934308290482	4.80731716379523	0.0960731655359268	51.30302
10.5	2020.37036132813	8.72265268117189	4.86219534650445	0.0971707329154015	51.320116
10.6000003814697	2021.56042480469	8.80619417876005	4.91707306355238	0.0982683002948761	51.350348
10.6999998092651	2019.11743164063	8.88973474502563	4.97560994699597	0.0994390249252319	51.288292
10.8000001907349	2021.85729980469	8.97304527461529	5.0304876640439	0.100536584854126	51.357888
10.8999996185303	2020.45788574219	9.05658677220345	5.09634148329496	0.101780489087105	51.32234
11	2021.86865234375	9.14012733846903	5.15487790107727	0.102951221168041	51.358176
11.1000003814697	2024.23498535156	9.22343786805868	5.21707301959395	0.104268297553062	51.418284
11.1999998092651	2026.80126953125	9.30674746632576	5.28292683884501	0.105512201786041	51.483472
11.3000001907349	2024.89526367188	9.39051993191242	5.34878065809608	0.106829263269901	51.435056
11.3999996185303	2026.7470703125	9.47359949350357	5.40731707587838	0.108000002801418	51.482092
11.5	2026.94226074219	9.55690909177065	5.4621952585876	0.109170734882355	51.487052
11.6000003814697	2024.80249023438	9.6402196213603	5.52439037710428	0.110414631664753	51.4327
11.6999998092651	2023.85498046875	9.72329918295145	5.58292679488659	0.111512199044228	51.408632
11.8000001907349	2022.72619628906	9.8066097125411	5.64512191340327	0.112756103277206	51.37996
11.8999996185303	2022.57214355469	9.89015027880669	5.70731703191996	0.114000000059605	51.376044
12	2021.50732421875	9.97322984039783	5.76951215043664	0.115243904292583	51.348996
12.1000003814697	2020.66333007813	10.056771337986	5.82804856821895	0.116487808525562	51.32756
12.1999998092651	2021.09521484375	10.1400809362531	5.89756108820438	0.117804870009422	51.338528
12.3000001907349	2020.36120605469	10.2233914658427	5.95609750598669	0.119048774242401	51.319884
12.3999996185303	2021.62414550781	10.3067019954324	6.02195132523775	0.12029267847538	51.351964
12.5	2022.283203125	10.390242561698	6.08414644375443	0.121536582708359	51.368704
12.6000003814697	2023.75756835938	10.4733221232891	6.14634156227112	0.122780494391918	51.406156
12.6999998092651	2021.48522949219	10.5566326528788	6.2085366807878	0.124024391174316	51.348436
12.8000001907349	2021.86022949219	10.6401732191443	6.27073179930449	0.125341460108757	51.35796
12.8999996185303	2019.68493652344	10.723483748734	6.33658515289426	0.126585364341736	51.302708
13	2019.41467285156	10.8067942783237	6.39878027141094	0.127829268574715	51.29584
13.1000003814697	2017.06225585938	10.8903348445892	6.464634090662	0.129146337509155	51.236088
13.1999998092651	2018.85424804688	10.9736453741789	6.52682920917869	0.130390241742134	51.281604
13.3000001907349	2018.12854003906	11.0571859404445	6.58902432769537	0.131707325577736	51.263172
13.3999996185303	2016.83630371094	11.1407274380326	6.65853638201952	0.132951229810715	51.230348
13.5	2016.6513671875	11.2238069996238	6.72439020127058	0.134341463446617	51.225648
13.6000003814697	2019.0234375	11.3073475658894	6.78658531978726	0.135658532381058	51.285904
13.6999998092651	2019.13732910156	11.3908890634775	6.85243913903832	0.13697561621666	51.288796
13.8000001907349	2016.67260742188	11.4741995930672	6.9182924926281	0.138219505548477	51.226188
13.8999996185303	2017.74865722656	11.5577401593328	6.98048761114478	0.139390245079994	51.253524
14	2015.30541992188	11.6410506889224	7.04268272966146	0.140707314014435	51.19146
14.1000003814697	2014.78527832031	11.7243602871895	7.10853654891253	0.142024397850037	51.178248
14.1999998092651	2012.66845703125	11.8076708167791	7.17073166742921	0.143268287181854	51.12448
14.3000001907349	2010.23022460938	11.8912123143673	7.23292678594589	0.144512191414833	51.062544
14.3999996185303	2010.32958984375	11.9742918759584	7.2914632037282	0.145756095647812	51.065068
14.5	2010.59765625	12.0576014742255	7.35731702297926	0.147073164582253	51.071876
14.6000003814697	2010.12426757813	12.1409120038152	7.43048777803779	0.148390248417854	51.059852
14.6999998092651	2008.7392578125	12.2242225334048	7.49999983236194	0.14985366165638	51.024672
14.8000001907349	2011.01770019531	12.3075321316719	7.565853651613	0.15117073059082	51.082548
14.8999996185303	2009.81616210938	12.3906116932631	7.63536570593715	0.152560979127884	51.052028
15	2006.48693847656	12.4739222228527	7.70487822592258	0.153951212763786	50.96746
15.1000003814697	2007.86474609375	12.5572327524424	7.77073157951236	0.155268296599388	51.002456
15.1999998092651	2006.17248535156	12.6405423507094	7.84390233457088	0.156731694936752	50.959472
15.3000001907349	2003.271484375	12.7238528802991	7.91341438889503	0.158121958374977	50.885784
15.3999996185303	2000.66845703125	12.8071634098887	7.9792682081461	0.159439012408257	50.819664
15.5	1999.67883300781	12.8907039761543	8.04878026247025	0.160756096243858	50.794524
15.6000003814697	2001.23803710938	12.974014505744	8.1182923167944	0.162219524383545	50.834132
15.6999998092651	1999.53796386719	13.0575560033321	8.18048790097237	0.163463413715363	50.790948
15.8000001907349	1998.19934082031	13.1408656015992	8.25365819036961	0.164926826953888	50.756944
15.8999996185303	1997.6708984375	13.2241761311889	8.32317117601633	0.166317075490952	50.74352
16	1997.75805664063	13.3074866607785	8.38902406394482	0.167707324028015	50.745736
16.1000003814697	1997.97937011719	13.3907962590456	8.45853704959154	0.169024392962456	50.751356
16.2000007629395	1994.49011230469	13.4738758206367	8.53170733898878	0.170414626598358	50.662724
16.2999992370605	1993.80261230469	13.5574173182249	8.60121939331293	0.171804875135422	50.64526
16.3999996185303	1992.1240234375	13.6407278478146	8.66707321256399	0.173121958971024	50.602624
16.5	1990.9384765625	13.7240374460816	8.73658526688814	0.174658536911011	50.572508
16.6000003814697	1989.72924804688	13.8075789436698	8.80975648760796	0.176048785448074	50.541792
16.7000007629395	1986.39794921875	13.8906585052609	8.87560937553644	0.177439019083977	50.457172
16.7999992370605	1986.51586914063	13.973968103528	8.94512236118317	0.178756102919579	50.460168
16.8999996185303	1982.818359375	14.0572786331177	9.01097524911165	0.180146336555481	50.366244
17	1983.20642089844	14.1403581947088	9.08414646983147	0.181463420391083	50.376104
17.1000003814697	1982.2265625	14.2234377563	9.16097592562437	0.183073163032532	50.351212
17.2000007629395	1982.47485351563	14.3067482858896	9.23048797994852	0.184463411569595	50.35752
17.2999992370605	1981.30163574219	14.3898269161582	9.30365826934576	0.185926839709282	50.32772
17.3999996185303	1980.79064941406	14.4726764410734	9.37682949006557	0.187390238046646	50.31474
17.5	1980.1240234375	14.5559860393405	9.44634154438972	0.18878048658371	50.297804
17.6000003814697	1976.60327148438	14.6390656009316	9.51585359871387	0.190170720219612	50.208376
17.7000007629395	1975.68835449219	14.7223761305213	9.58536565303802	0.191634148359299	50.185132
17.7999992370605	1970.65686035156	14.8054556921124	9.66219510883093	0.193097561597824	50.057328
17.8999996185303	1969.01037597656	14.8887662217021	9.73902456462383	0.194560974836349	50.015504
18	1966.42797851563	14.9718448519707	9.80487838387489	0.195951223373413	49.949908
18.1000003814697	1965.27429199219	15.0551553815603	9.88170690834522	0.1974878013134	49.920604
18.2000007629395	1966.02807617188	15.13846591115	9.95487812906504	0.199024394154549	49.939748
18.2999992370605	1964.41442871094	15.2217764407396	10.0280484184623	0.200487807393074	49.89876
18.3999996185303	1962.59033203125	15.3053170070052	10.1085370406508	0.202024400234222	49.852428
18.5	1960.94482421875	15.3886275365949	10.1817073300481	0.20356097817421	49.810628
18.6000003814697	1959.43713378906	15.4721681028605	10.2658532559872	0.205097556114197	49.772332
18.7000007629395	1958.06677246094	15.5557096004486	10.3353662416339	0.206560969352722	49.737524
18.7999992370605	1954.94213867188	15.6390201300383	10.4121947661042	0.208097562193871	49.658152
18.8999996185303	1953.78491210938	15.7225597649813	10.485365986824	0.209560975432396	49.628756
19	1951.14428710938	15.8061012625694	10.5585362762213	0.211024403572083	49.56168
19.1000003814697	1946.41052246094	15.8894117921591	10.6280483305454	0.212487801909447	49.441436
19.2000007629395	1945.46081542969	15.9727223217487	10.7048777863383	0.213878035545349	49.417312
19.2999992370605	1943.94848632813	16.0562638193369	10.7817072421312	0.215487793087959	49.3789
19.3999996185303	1940.25866699219	16.1395743489265	10.8621949329972	0.217024385929108	49.285172
19.5	1938.70483398438	16.222883015871	10.9390243887901	0.218560978770256	49.245704
19.6000003814697	1937.25012207031	16.3064245134592	11.015853844583	0.220097571611404	49.208752
19.7000007629395	1937.64611816406	16.3895040750504	11.0926833003759	0.221707314252853	49.218812
19.7999992370605	1933.09167480469	16.4725836366415	11.1658535897732	0.223243907094002	49.10312
19.8999996185303	1928.91552734375	16.5558941662312	11.2500004470348	0.224853664636612	48.99704
20	1927.27197265625	16.6389737278223	11.3304881379008	0.226463407278061	48.955292
20.1000003814697	1922.63073730469	16.722284257412	11.400000192225	0.227853655815125	48.8374
20.2000007629395	1920.09802246094	16.8053638190031	11.4841461181641	0.229536592960358	48.773064
20.2999992370605	1915.08471679688	16.8882124125957	11.5682929754257	0.23121951520443	48.64572
20.3999996185303	1908.5322265625	16.9715229421854	11.6487806662917	0.23282927274704	48.47928
20.5	1909.0068359375	17.0548316091299	11.7329265922308	0.234439015388489	48.491332
20.6000003814697	1905.58825683594	17.1379111707211	11.8097560480237	0.236121952533722	48.404496
20.7000007629395	1899.45581054688	17.2209907323122	11.9012193754315	0.237804874777794	48.248724
20.7999992370605	1894.54187011719	17.3043012619019	11.9743905961514	0.23926830291748	48.123904
20.8999996185303	1893.87866210938	17.387380823493	12.0585365220904	0.240951210260391	48.10706
21	1891.51770019531	17.4709223210812	12.1390242129564	0.242634147405624	48.047088
21.1000003814697	1885.2275390625	17.5540018826723	12.2195119038224	0.244243904948235	47.887308
21.2000007629395	1879.20874023438	17.637312412262	12.3073169961572	0.246073171496391	47.734424
21.2999992370605	1871.49340820313	17.720852047205	12.3914638534188	0.247682929039001	47.538444
21.3999996185303	1863.69470214844	17.8041625767946	12.479268014431	0.249439030885696	47.340344
21.5	1854.28161621094	17.8874731063843	12.5634148716927	0.251048773527145	47.10124
21.6000003814697	1846.78112792969	17.9710146039724	12.6548781991005	0.252878040075302	46.910716
21.7000007629395	1835.70300292969	18.0545561015606	12.7390241250396	0.254634141921997	46.62932
21.7999992370605	1819.2666015625	18.1376356631517	12.8414630889893	0.256609737873077	46.211812
21.8999996185303	3.93748927116394	18.2211752980947	13.3024388924241	0.265390247106552	0.1000175078125