File: Tensile_tests/PA12_C2_XZ_6 05-24-22 12 42 50 PM/DAQ- Time, … - (Timed).txt
File Path: C:\MTS TestSuite\Data Files\Chahine\DOE\PA12_C2_XZ_6 05-24-22 12 42 50 PM\DAQ- Time, … - (Timed).txt
Test: MTS EM Tension (Extensometer)_Grand_Chahine 1
Test Run: PA12_C2_XZ_6
Date: 5/24/2022 12:42:21 PM


Time 	Load 	Crosshead 	Extensometer 	Strain 	Stress
sec	N	mm	mm	mm/mm	N/mm²
0.100000001490116	45.3761825561523	0.0620788341620937	0.0182926833076635	0.000292682932922617	1.123128375
0.200000002980232	98.9845581054688	0.145158308441751	0.04756097405334	0.000951219466514885	2.45001575
0.300000011920929	152.991790771484	0.229391676839441	0.0804878072813153	0.00153658539056778	3.7867755
0.400000005960464	206.341415405273	0.312932708766311	0.106097562820651	0.00212195119820535	5.1072585
0.5	257.376037597656	0.396473740693182	0.131707318359986	0.00256097549572587	6.3704415
0.600000023841858	306.376037597656	0.47978397924453	0.168292681337334	0.0032926828134805	7.583265
0.699999988079071	357.369750976563	0.56309427600354	0.197560977539979	0.00387804862111807	8.845436
0.800000011920929	404.747772216797	0.646173721179366	0.234146340517327	0.00460975617170334	10.018112
0.899999976158142	454.318817138672	0.729253224562854	0.270731718046591	0.00541463447734714	11.24507
1	503.819061279297	0.81233266973868	0.30365854036063	0.00607317080721259	12.470275
1.10000002384186	551.085815429688	0.895642966497689	0.343902444001287	0.00680487789213657	13.640198
1.20000004768372	595.644897460938	0.978722469881177	0.38048779242672	0.00753658544272184	14.743102
1.29999995231628	640.243103027344	1.061801915057	0.41341464384459	0.0081951217725873	15.846974
1.39999997615814	684.132263183594	1.14511221181601	0.449999992270023	0.00885365903377533	16.933296
1.5	726.985473632813	1.22819165699184	0.486585369799286	0.00965853687375784	17.993978
1.60000002384186	770.230651855469	1.31150183733553	0.52317074732855	0.0104634147137403	19.06436
1.70000004768372	814.191955566406	1.39481213409454	0.556097540538758	0.0110487807542086	20.152468
1.79999995231628	855.780456542969	1.47835316602141	0.589024391956627	0.0116341467946768	21.181846
1.89999997615814	897.531921386719	1.56166346278042	0.621951243374497	0.0123658534139395	22.215256
2	935.101318359375	1.6449736431241	0.658536562696099	0.0130975609645247	23.145156
2.09999990463257	978.073181152344	1.72851467505097	0.691463414113969	0.0137560982257128	24.208774
2.20000004768372	1015.22448730469	1.81182497180998	0.728048791643232	0.0144878048449755	25.128324
2.29999995231628	1052.73937988281	1.89536600373685	0.76829269528389	0.0152926836162806	26.056874
2.40000009536743	1088.07373046875	1.97890703566372	0.797560962382704	0.015951219946146	26.931452
2.5	1122.34875488281	2.06244806759059	0.834146339911968	0.0166097562760115	27.77981
2.59999990463257	1157.7119140625	2.1457583643496	0.870731717441231	0.0174146350473166	28.6551
2.70000004768372	1191.99987792969	2.22929939627647	0.907317094970495	0.0180731695145369	29.50378
2.79999995231628	1222.28857421875	2.31260969303548	0.947560998611152	0.0188780482858419	30.25347
2.90000009536743	1257.0419921875	2.39615072496235	0.984146376140416	0.0196097567677498	31.113668
3	1287.35473632813	2.47946102172136	1.01707316935062	0.0202682912349701	31.863954
3.09999990463257	1317.85510253906	2.56277108564973	1.0463414946571	0.0208536572754383	32.618884
3.20000004768372	1346.10595703125	2.64608138240874	1.0865853400901	0.0216585379093885	33.318134
3.29999995231628	1373.38818359375	2.72916094399989	1.12317071761936	0.0224634148180485	33.993412
3.40000009536743	1402.43591308594	2.81224027276039	1.15975609514862	0.0231219492852688	34.712384
3.5	1424.53967285156	2.8955505695194	1.20000005699694	0.023926829919219	35.259488
3.59999990463257	1451.09826660156	2.97886086627841	1.24024390242994	0.024731706827879	35.916852
3.70000004768372	1472.75927734375	3.06194042786956	1.2768292799592	0.0254634134471416	36.452992
3.79999995231628	1495.59106445313	3.14501975663006	1.32073170971125	0.0262682922184467	37.018116
3.90000009536743	1513.27026367188	3.22809931822121	1.36097555514425	0.0270731709897518	37.4557
4	1531.07739257813	3.31140961498022	1.39756093267351	0.0278780497610569	37.896456
4.09999990463257	1552.62548828125	3.39448917657137	1.43414631020278	0.0286829266697168	38.4298
4.19999980926514	1569.37536621094	3.47779924049973	1.47073168773204	0.0293414648622274	38.844388
4.30000019073486	1585.18884277344	3.56087880209088	1.51097564958036	0.0301463417708874	39.235792
4.40000009536743	1601.79187011719	3.64418909884989	1.54756102710962	0.0308780483901501	39.646744
4.5	1617.12353515625	3.7274993956089	1.58780487254262	0.0316829271614552	40.026224
4.59999990463257	1631.56701660156	3.81080945953727	1.62439025007188	0.0324146337807179	40.383724
4.69999980926514	1644.73132324219	3.89411975629628	1.66829267982394	0.033292680978775	40.70956
4.80000019073486	1656.3486328125	3.97766102105379	1.71219510957599	0.0342439040541649	40.997104
4.90000009536743	1665.76135253906	4.06097108498216	1.75243907142431	0.0349756106734276	41.230084
5	1677.63146972656	4.14428114891052	1.79999996908009	0.0359268300235271	41.523888
5.09999990463257	1685.12329101563	4.22759167850018	1.8475609831512	0.0368048772215843	41.70932
5.19999980926514	1695.25378417969	4.31113271042705	1.89146341290325	0.0377560965716839	41.960064
5.30000019073486	1706.11901855469	4.39444277435541	1.9353658426553	0.0386341474950314	42.228996
5.40000009536743	1714.40441894531	4.47798380628228	1.98292685672641	0.0395853668451309	42.434072
5.5	1721.56018066406	4.56152483820915	2.03048787079751	0.0404634140431881	42.611188
5.59999990463257	1731.70751953125	4.64483536779881	2.07073171623051	0.0413414649665356	42.862348
5.69999980926514	1737.86145019531	4.72814543172717	2.12560966610909	0.0424390248954296	43.014668
5.80000019073486	1746.25085449219	4.81168646365404	2.17682938091457	0.0433902442455292	43.22232
5.90000009536743	1753.19836425781	4.89476602524519	2.22439016215503	0.0444146320223808	43.39428
6	1760.28588867188	4.97807608917356	2.27195117622614	0.0453658550977707	43.569708
6.09999990463257	1766.1328125	5.06138661876321	2.31951219029725	0.0463170744478703	43.714428
6.19999980926514	1773.40710449219	5.14446618035436	2.37073167227209	0.0473414659500122	43.894476
6.30000019073486	1779.64379882813	5.22754527628422	2.42195115424693	0.0483658537268639	44.048844
6.40000009536743	1784.73901367188	5.31085580587387	2.46951216831803	0.0493170730769634	44.17496
6.5	1789.66479492188	5.39393536746502	2.52439035102725	0.0504146330058575	44.29688
6.59999990463257	1795.71240234375	5.47724543139338	2.57195113226771	0.051365852355957	44.446568
6.69999980926514	1801.16052246094	5.56032499298453	2.6231708470732	0.0523170754313469	44.581416
6.80000019073486	1805.5068359375	5.64340455457568	2.67439032904804	0.0533414632081985	44.688992
6.90000009536743	1810.60693359375	5.72648411616683	2.7219511102885	0.0543658509850502	44.815228
7	1816.39233398438	5.80956321209669	2.77682929299772	0.0554634183645248	44.958424
7.09999990463257	1820.18713378906	5.89264277368784	2.83170724287629	0.0564878061413765	45.052352
7.19999980926514	1825.91137695313	5.97595330327749	2.8792682569474	0.0575121939182281	45.194036
7.30000019073486	1828.42810058594	6.05903239920735	2.93414643965662	0.0585365854203701	45.256328
7.40000009536743	1835.54541015625	6.14234292879701	2.98536592163146	0.0596341453492641	45.432492
7.5	1836.50366210938	6.22542249038816	3.04024387151003	0.0606585368514061	45.456212
7.59999990463257	1840.48364257813	6.30873255431652	3.09146335348487	0.0617560967803001	45.55472
7.69999980926514	1841.7158203125	6.39204261824489	3.14268283545971	0.06270731985569	45.58522
7.80000019073486	1847.36730957031	6.47535314783454	3.19024384953082	0.0637317076325417	45.725104
7.90000009536743	1850.35754394531	6.55866321176291	3.23780486360192	0.0646829307079315	45.799116
8	1854.59912109375	6.64197374135256	3.28536587767303	0.0655609741806984	45.9041
8.10000038146973	1859.44226074219	6.72528380528092	3.33658535964787	0.066658541560173	46.023976
8.19999980926514	1863.36267089844	6.80859433487058	3.39146330952644	0.0677560940384865	46.121012
8.30000019073486	1867.85961914063	6.89190439879894	3.47926840186119	0.0695853680372238	46.23232
8.39999961853027	1868.33337402344	6.97521446272731	3.52317071519792	0.0703170746564865	46.244044
8.5	1872.79663085938	7.05852499231696	3.57073172926903	0.0713414624333382	46.354516
8.60000038146973	1874.88391113281	7.14183505624533	3.61829274334013	0.0722926780581474	46.40618
8.69999980926514	1874.52087402344	7.22514558583498	3.67682916112244	0.0734634101390839	46.397196
8.80000019073486	1879.16735839844	7.30845564976335	3.73536581173539	0.0745609775185585	46.5122
8.89999961853027	1880.72094726563	7.39176571369171	3.79390246234834	0.0758048817515373	46.550656
9	1880.5693359375	7.47507624328136	3.84512194432318	0.076829269528389	46.546904
9.10000038146973	1887.03588867188	7.55838630720973	3.89634142629802	0.0778536573052406	46.70696
9.19999980926514	1887.19140625	7.64146586880088	3.95487807691097	0.0790243893861771	46.710808
9.30000019073486	1890.38598632813	7.72477593272924	4.01341449469328	0.0801951289176941	46.78988
9.39999961853027	1890.42517089844	7.80785549432039	4.07560961320996	0.0814390257000923	46.790848
9.5	1892.25	7.89116602391005	4.13780473172665	0.0826829299330711	46.836016
9.60000038146973	1894.107421875	7.9744765534997	4.19268291443586	0.0837804824113846	46.881992
9.69999980926514	1897.56201171875	8.05755518376827	4.24756109714508	0.0848780497908592	46.967496
9.80000019073486	1897.60473632813	8.14086571335793	4.30243881419301	0.0859024375677109	46.968556
9.89999961853027	1900.25830078125	8.22394527494907	4.35365876182914	0.0869268253445625	47.034232
10	1901.84216308594	8.30725580453873	4.40853647887707	0.0880243927240372	47.073436
10.1000003814697	1901.05798339844	8.39056540280581	4.45975596085191	0.0891219526529312	47.054028
10.1999998092651	1901.85607910156	8.47410690039396	4.5182928442955	0.0902195125818253	47.07378
10.3000001907349	1902.42346191406	8.55741742998362	4.58048796281219	0.0914634093642235	47.087824
10.3999996185303	1904.36022949219	8.64072702825069	4.64634131640196	0.0927804857492447	47.135764
10.5	1908.54541015625	8.72403755784035	4.70487819984555	0.0939512178301811	47.239352
10.6000003814697	1909.22802734375	8.80734808743	4.76341461762786	0.0951951146125793	47.256248
10.6999998092651	1910.99230957031	8.89088865369558	4.81829280033708	0.0962195098400116	47.299916
10.8000001907349	1915.06811523438	8.97419918328524	4.86585358157754	0.0972439050674438	47.4008
10.8999996185303	1911.07995605469	9.05774068087339	4.92073176428676	0.0983414649963379	47.302084
11	1912.97595214844	9.14105027914047	4.97926818206906	0.0995121970772743	47.349016
11.1000003814697	1911.53063964844	9.22459177672863	5.04146330058575	0.100682929158211	47.31324
11.1999998092651	1910.71618652344	9.30790137499571	5.10000018402934	0.101853653788567	47.293084
11.3000001907349	1913.47534179688	9.39144287258387	5.15487790107727	0.103024393320084	47.361376
11.3999996185303	1911.80187988281	9.47498343884945	5.22073172032833	0.104268297553062	47.319956
11.5	1913.49743652344	9.5582939684391	5.29390247538686	0.105585366487503	47.361924
11.6000003814697	1912.974609375	9.64160449802876	5.34878065809608	0.106902435421944	47.34898
11.6999998092651	1911.63110351563	9.72491502761841	5.41097577661276	0.10807316750288	47.315728
11.8000001907349	1917.11572265625	9.80799365788698	5.46951219439507	0.109317071735859	47.45148
11.8999996185303	1915.87622070313	9.89130418747664	5.53536601364613	0.110560968518257	47.4208
12	1917.21472167969	9.97461471706629	5.59756113216281	0.111804872751236	47.453932
12.1000003814697	1915.25524902344	10.0579252466559	5.65609754994512	0.113048776984215	47.405432
12.1999998092651	1917.08532714844	10.141234844923	5.7182926684618	0.114219516515732	47.450728
12.3000001907349	1914.52062988281	10.2245453745127	5.78048778697848	0.115463420748711	47.387248
12.3999996185303	1915.03295898438	10.3078559041023	5.84268290549517	0.116707317531109	47.399928
12.5	1912.85119628906	10.3911655023694	5.90121932327747	0.117878049612045	47.345928
12.6000003814697	1914.83984375	10.4744760319591	5.96341444179416	0.119195125997067	47.395148
12.6999998092651	1916.19079589844	10.5577865615487	6.03292696177959	0.120439022779465	47.428588
12.8000001907349	1915.34741210938	10.6410970911384	6.09512208029628	0.121829271316528	47.407712
12.8999996185303	1914.52185058594	10.7246376574039	6.15731719881296	0.122999995946884	47.387276
13	1916.46911621094	10.8079481869936	6.21951231732965	0.124317072331905	47.435476
13.1000003814697	1914.62048339844	10.8912577852607	6.28170743584633	0.125487804412842	47.38972
13.1999998092651	1915.36901855469	10.9747992828488	6.3475607894361	0.126804873347282	47.408248
13.3000001907349	1915.39074707031	11.0581098124385	6.41341460868716	0.128195121884346	47.408784
13.3999996185303	1913.14892578125	11.1414194107056	6.47195102646947	0.129365861415863	47.353296
13.5	1910.15502929688	11.2249609082937	6.53780484572053	0.130609750747681	47.279192
13.6000003814697	1913.06286621094	11.3082714378834	6.60731690004468	0.131926819682121	47.351164
13.6999998092651	1910.94421386719	11.3915810361505	6.67317071929574	0.133317083120346	47.298728
13.8000001907349	1909.71618652344	11.4751225337386	6.7390245385468	0.134707316756248	47.268332
13.8999996185303	1910.13940429688	11.5586631000042	6.80487789213657	0.136024385690689	47.278804
14	1907.67785644531	11.6419736295938	6.86707301065326	0.137268289923668	47.21788
14.1000003814697	1907.06726074219	11.7255141958594	6.93658553063869	0.138585358858109	47.202764
14.1999998092651	1909.67883300781	11.8088247254491	7.00243888422847	0.13990244269371	47.267408
14.3000001907349	1909.57299804688	11.8921352550387	7.06829270347953	0.141146346926689	47.264788
14.3999996185303	1909.79931640625	11.9754457846284	7.13048782199621	0.14246341586113	47.270388
14.5	1909.22375488281	12.058524414897	7.19634164124727	0.14378048479557	47.256144
14.6000003814697	1909.39135742188	12.1420659124851	7.25853675976396	0.145097553730011	47.260292
14.6999998092651	1906.75073242188	12.2253764420748	7.32073187828064	0.14634145796299	47.194932
14.8000001907349	1905.74108886719	12.3084560036659	7.39756086841226	0.147804886102676	47.16994
14.8999996185303	1905.52099609375	12.391765601933	7.46707338839769	0.149195119738579	47.164492
15	1904.10522460938	12.4750761315227	7.53292674198747	0.150512188673019	47.129452
15.1000003814697	1903.5234375	12.5583866611123	7.60609749704599	0.151975616812706	47.115052
15.1999998092651	1902.11291503906	12.6416962593794	7.67926825210452	0.153365850448608	47.08014
15.3000001907349	1901.47082519531	12.7247758209705	7.74878030642867	0.154829263687134	47.064244
15.3999996185303	1901.07092285156	12.8080863505602	7.81463459134102	0.156219512224197	47.054348
15.5	1901.25	12.8918578848243	7.88414664566517	0.157536581158638	47.05878
15.6000003814697	1901.66772460938	12.9751684144139	7.95731693506241	0.159000009298325	47.06912
15.6999998092651	1900.04040527344	13.0584789440036	8.03048815578222	0.160390257835388	47.02884
15.8000001907349	1895.95678710938	13.1417885422707	8.09634104371071	0.161780491471291	46.927764
15.8999996185303	1897.11340332031	13.2250990718603	8.16951226443052	0.163243889808655	46.956392
16	1896.72802734375	13.30840960145	8.24268255382776	0.164634138345718	46.946856
16.1000003814697	1894.44030761719	13.3919501677155	8.31219553947449	0.166097566485405	46.890228
16.2000007629395	1894.34387207031	13.4752606973052	8.37804842740297	0.167487800121307	46.887844
16.2999992370605	1892.20251464844	13.5585712268949	8.45487788319588	0.168951228260994	46.83484
16.3999996185303	1890.05053710938	13.641650788486	8.52804910391569	0.170414626598358	46.781576
16.5	1892.09411621094	13.7251913547516	8.60853679478168	0.171951219439507	46.83216
16.6000003814697	1888.98669433594	13.8085018843412	8.67804884910584	0.173414632678032	46.755244
16.7000007629395	1888.88366699219	13.8920424506068	8.75121913850307	0.174878060817719	46.752696
16.7999992370605	1888.12341308594	13.9753529801965	8.82439035922289	0.176268294453621	46.733876
16.8999996185303	1887.27185058594	14.0584325417876	8.89390241354704	0.177731692790985	46.7128
17	1885.18103027344	14.1417430713773	8.96341446787119	0.179195120930672	46.661048
17.1000003814697	1884.56396484375	14.2250526696444	9.03292652219534	0.180585369467735	46.645776
17.2000007629395	1884.55908203125	14.3081322312355	9.10609774291515	0.181975603103638	46.645656
17.2999992370605	1881.236328125	14.3912117928267	9.18292719870806	0.183512195944786	46.563412
17.3999996185303	1880.4443359375	14.4745223224163	9.25975572317839	0.185048788785934	46.543808
17.5	1879.13000488281	14.5576018840075	9.33658517897129	0.186585366725922	46.511276
17.6000003814697	1877.18103027344	14.6406814455986	9.41341463476419	0.188121944665909	46.463036
17.7000007629395	1873.90502929688	14.7237610071898	9.48292668908834	0.189512208104134	46.381952
17.7999992370605	1873.79052734375	14.8068405687809	9.55243874341249	0.190975606441498	46.379116
17.8999996185303	1873.47631835938	14.890150167048	9.6292681992054	0.192439019680023	46.37134
18	1869.50439453125	14.9734606966376	9.7060976549983	0.19397559762001	46.273028
18.1000003814697	1872.05578613281	15.0567712262273	9.78292711079121	0.195512190461159	46.33618
18.2000007629395	1871.21313476563	15.1398507878184	9.85975656658411	0.197048783302307	46.315324
18.2999992370605	1867.24438476563	15.2229303494096	9.93658509105444	0.198585376143456	46.217092
18.3999996185303	1866.89392089844	15.3064709156752	10.0097563117743	0.20004877448082	46.208416
18.5	1863.26184082031	15.3897814452648	10.0865857675672	0.201585367321968	46.118516
18.6000003814697	1863.27221679688	15.4733220115304	10.1634142920375	0.203121960163116	46.118772
18.7000007629395	1862.09069824219	15.5566325411201	10.2475611492991	0.204804867506027	46.089528
18.7999992370605	1860.48474121094	15.6401731073856	10.3207314386964	0.206341460347176	46.04978
18.8999996185303	1857.65979003906	15.7237146049738	10.4085365310311	0.207878053188324	45.979856
19	1858.00634765625	15.807256102562	10.485365986824	0.209560975432396	45.988436
19.1000003814697	1856.31530761719	15.890795737505	10.5548780411482	0.210951209068298	45.94658
19.2000007629395	1855.93774414063	15.9741062670946	10.6317074969411	0.212487801909447	45.937232
19.2999992370605	1852.59790039063	16.0574167966843	10.708536952734	0.214024394750595	45.854568
19.3999996185303	1852.01342773438	16.1409582942724	10.7853654772043	0.215560972690582	45.8401
19.5	1849.56164550781	16.2242688238621	10.8621949329972	0.217097565531731	45.779416
19.6000003814697	1843.91296386719	16.3075793534517	10.9463417902589	0.218707323074341	45.639604
19.7000007629395	1844.20104980469	16.3908880203962	11.0268294811249	0.220317080616951	45.646732
19.7999992370605	1839.45678710938	16.4741985499859	11.1073171719909	0.222000002861023	45.529304
19.8999996185303	1839.36169433594	16.5575090795755	11.1841466277838	0.22353658080101	45.526952
20	1838.80627441406	16.6408196091652	11.2646343186498	0.22514633834362	45.513204
20.1000003814697	1834.15100097656	16.7238991707563	11.3487802445889	0.226902440190315	45.39798
20.2000007629395	1830.79272460938	16.8069787323475	11.4292679354548	0.228365838527679	45.314856
20.2999992370605	1830.02954101563	16.8902892619371	11.5097565576434	0.230121940374374	45.295968
20.3999996185303	1826.46655273438	16.9733688235283	11.5865850821137	0.231512188911438	45.207776
20.5	1827.29797363281	17.0564483851194	11.6670727729797	0.233121946454048	45.228356
20.6000003814697	1825.89953613281	17.1395279467106	11.7548778653145	0.234951227903366	45.193744
20.7000007629395	1821.46496582031	17.2228384763002	11.8317073211074	0.236487805843353	45.08398
20.7999992370605	1817.67834472656	17.3059161752462	11.9121950119734	0.238097548484802	44.990256
20.8999996185303	1816.50512695313	17.3892267048359	11.996341869235	0.239780485630035	44.961216
21	1810.96276855469	17.4725372344255	12.0841460302472	0.241463407874107	44.824036
21.1000003814697	1806.07836914063	17.5556167960167	12.1646337211132	0.243073165416718	44.70314
21.2000007629395	1803.59362792969	17.6391582936049	12.2487805783749	0.244756102561951	44.64164
21.2999992370605	1796.59436035156	17.7224688231945	12.3365856707096	0.246512204408646	44.468396
21.3999996185303	1786.70825195313	17.8057793527842	12.4243898317218	0.248268276453018	44.2237
21.5	1782.14965820313	17.8890880197287	12.5121949240565	0.250097572803497	44.110868
21.6000003814697	1763.89453125	17.9723985493183	12.6109756529331	0.252073168754578	43.659028
21.6800003051758	-5.72319746017456	18.0393233895302	12.9658533260226	0.256243914365768	-0.1416576875