File: Tensile_tests/PA12_C1_XY_3 05-16-22 14 19 35 PM/DAQ- Time, … - (Timed).txt
File Path: C:\MTS TestSuite\Data Files\Chahine\DOE\PA12_C1_XY_3 05-16-22 14 19 35 PM\DAQ- Time, … - (Timed).txt
Test: MTS EM Tension (Extensometer)_Grand_Chahine 1
Test Run: PA12_C1_XY_3
Date: 5/16/2022 2:19:06 PM


Time 	Load 	Crosshead 	Extensometer 	Strain 	Stress
sec	N	mm	mm	mm/mm	N/mm²
0.109999842941761	54.7058258056641	0.0717714356142096	0.0182926833076635	0.000365853658877313	1.291834375
0.209999844431877	110.765640258789	0.153697037603706	0.0548780481040012	0.00102439022157341	2.615642
0.309999853372574	171.152038574219	0.23700729070697	0.0804878072813153	0.00153658539056778	4.0416185
0.409999847412109	230.735885620117	0.320548337185755	0.106097562820651	0.0019756096880883	5.4486435
0.509999871253967	290.516204833984	0.403858575737104	0.135365859023295	0.0026341462507844	6.860308
0.60999983549118	349.210296630859	0.487168843392283	0.179268288775347	0.00351219531148672	8.246322
0.709999859333038	403.708129882813	0.570479081943631	0.230487799854018	0.00453658541664481	9.533245
0.809999823570251	458.534973144531	0.654020113870502	0.278048770269379	0.00548780476674438	10.827937
0.909999847412109	512.574523925781	0.736868823878467	0.314634147798643	0.00621951231732965	12.104038
1.00999987125397	564.385925292969	0.820179062429816	0.351219525327906	0.00695121940225363	13.327522
1.10999989509583	615.980224609375	0.903258565813303	0.384146347641945	0.00760975573211908	14.545881
1.20999979972839	668.216918945313	0.986568862572312	0.417073169955984	0.00826829299330711	15.779408
1.30999982357025	717.714904785156	1.07010989449918	0.446341466158628	0.00885365903377533	16.948264
1.40999984741211	768.574890136719	1.15365092642605	0.482926843687892	0.00958536565303802	18.149282
1.50999987125397	819.688659667969	1.23696110676974	0.5158536368981	0.0102439019829035	19.356292
1.60999989509583	866.722595214844	1.32050213869661	0.54878048831597	0.0109756095334888	20.466962
1.70999979972839	916.179260253906	1.40404317062348	0.578048755414784	0.0114146340638399	21.63484
1.80999982357025	961.702880859375	1.48712273221463	0.607317080721259	0.0121463416144252	22.709844
1.90999984741211	1012.13165283203	1.57089449930936	0.636585347820073	0.0127317067235708	23.90068
2.00999975204468	1058.73754882813	1.65443553123623	0.673170725349337	0.0133902439847589	25.00124
2.10999989509583	1105.36242675781	1.73751497641206	0.706097576767206	0.0140487812459469	26.10225
2.20999979972839	1151.45068359375	1.82105600833893	0.739024369977415	0.0147073166444898	27.190588
2.30999994277954	1191.77416992188	1.90436630509794	0.771951221395284	0.0153658539056778	28.142794
2.40999984741211	1235.01928710938	1.98767660185695	0.804878072813153	0.0160975605249405	29.163994
2.50999975204468	1278.59594726563	2.07098689861596	0.841463392134756	0.0167560968548059	30.193022
2.60999989509583	1319.38903808594	2.15452793054283	0.874390243552625	0.0174146350473166	31.156318
2.70999979972839	1361.30212402344	2.23760725930333	0.910975621081889	0.0180731695145369	32.146062
2.80999994277954	1399.25329589844	2.32068682089448	0.947560998611152	0.0188780482858419	33.042248
2.90999984741211	1439.94030761719	2.40399711765349	0.984146376140416	0.0196097567677498	34.00304
3.00999975204468	1479.51818847656	2.48707644641399	1.02073175366968	0.0203414633870125	34.93764
3.10999989509583	1513.28405761719	2.57015600800514	1.04999996256083	0.0209999997168779	35.734992
3.20999979972839	1550.04992675781	2.65346630476415	1.09024392440915	0.0216585379093885	36.603188
3.30999994277954	1587.22583007813	2.7363148983568	1.11951224971563	0.0223902445286512	37.481068
3.40999984741211	1619.77844238281	2.8196251951158	1.15243904292583	0.0229024402797222	38.249772
3.50999975204468	1652.93017578125	2.90270475670695	1.18536583613604	0.0236341468989849	39.032624
3.60999989509583	1682.57861328125	2.98578408546746	1.21829262934625	0.0242926832288504	39.732748
3.70999979972839	1712.34497070313	3.06909438222647	1.25853659119457	0.0250975601375103	40.435656
3.80999994277954	1740.20678710938	3.15240467898548	1.29512196872383	0.025829266756773	41.093592
3.90999984741211	1769.46704101563	3.23548424057662	1.3317073462531	0.0265609752386808	41.784548
4.00999975204468	1792.71459960938	3.3190252725035	1.38658541254699	0.0275853648781776	42.333524
4.10999965667725	1817.703125	3.402104601264	1.43048784229904	0.0285365842282772	42.923608
4.21000003814697	1839.76318359375	3.48541489802301	1.4743902720511	0.0293414648622274	43.444536
4.30999994277954	1860.326171875	3.56918666511774	1.51829270180315	0.0302926823496819	43.930116
4.40999984741211	1879.44702148438	3.65249696187675	1.5621951315552	0.0311707314103842	44.38164
4.50999975204468	1900.00939941406	3.73580725863576	1.60609756130725	0.0320487804710865	44.867204
4.60999965667725	1914.56103515625	3.81934829056263	1.64634152315557	0.032926831394434	45.210828
4.71000003814697	1928.689453125	3.90265858732164	1.69756100513041	0.0338780470192432	45.54446
4.80999994277954	1942.19287109375	3.98596888408065	1.7451219027862	0.0348292700946331	45.863332
4.90999984741211	1953.82189941406	4.06950991600752	1.7926829168573	0.0357073172926903	46.137944
5.00999975204468	1964.38171386719	4.15305094793439	1.83658534660935	0.0366585366427898	46.387304
5.10999965667725	1976.06762695313	4.23613050952554	1.89146341290325	0.0377560965716839	46.663256
5.21000003814697	1985.56372070313	4.31967154145241	1.93902442697436	0.0387073159217834	46.8875
5.30999994277954	1993.40661621094	4.40298160538077	1.98658532463014	0.0396585389971733	47.072704
5.40999984741211	2002.9306640625	4.48629166930914	2.03780480660498	0.0406097583472729	47.297608
5.50999975204468	2012.53466796875	4.56960219889879	2.08536582067609	0.0417073145508766	47.524396
5.60999965667725	2019.27209472656	4.65268176048994	2.13658530265093	0.0426585376262665	47.683496
5.71000003814697	2024.34313964844	4.73576132208109	2.18414631672204	0.043536588549614	47.803244
5.80999994277954	2033.009765625	4.81907138600945	2.23170733079314	0.0444878041744232	48.0079
5.90999984741211	2036.54943847656	4.9021509476006	2.27926834486425	0.0455121919512749	48.091488
6.00999975204468	2044.556640625	4.98523050919175	2.33048782683909	0.0465365871787071	48.280572
6.10999965667725	2047.34655761719	5.06830960512161	2.3780488409102	0.0474878028035164	48.346452
6.21000003814697	2054.40258789063	5.15138916671276	2.44024395942688	0.0486585348844528	48.513076
6.30999994277954	2057.22290039063	5.23446872830391	2.49512190930545	0.0498292669653893	48.579676
6.40999984741211	2063.80517578125	5.31754828989506	2.54268292337656	0.0507804900407791	48.735108
6.50999975204468	2068.90307617188	5.40085835382342	2.59756087325513	0.0518048778176308	48.855492
6.60999965667725	2073.69482421875	5.48393791541457	2.65609752386808	0.0529756098985672	48.968644
6.71000003814697	2077.90942382813	5.56724844500422	2.70731700584292	0.0540731698274612	49.068172
6.80999994277954	2084.55322265625	5.65032754093409	2.76585365645587	0.0551707297563553	49.22506
6.90999984741211	2084.30151367188	5.73340710252523	2.81341467052698	0.0562682934105396	49.219116
7.00999975204468	2089.90307617188	5.8169481344521	2.86463415250182	0.0572195127606392	49.351392
7.10999965667725	2092.88891601563	5.90002769604325	2.92317080311477	0.0583902411162853	49.4219
7.21000003814697	2095.92553710938	5.98333775997162	2.98536592163146	0.0595609769225121	49.493608
7.30999994277954	2097.03247070313	6.06664828956127	3.04024387151003	0.0606585368514061	49.519744
7.40999984741211	2099.6767578125	6.14995835348964	3.09878052212298	0.0618292689323425	49.582188
7.50999975204468	2100.33544921875	6.23326888307929	3.15365847200155	0.063000001013279	49.597744
7.60999965667725	2106.07934570313	6.31680991500616	3.2121951226145	0.0641707330942154	49.73338
7.71000003814697	2107.89453125	6.39988901093602	3.26341460458934	0.065195120871067	49.776244
7.80999994277954	2109.26635742188	6.48343004286289	3.31829278729856	0.0662926807999611	49.80864
7.90999984741211	2115.69775390625	6.56674057245255	3.37317073717713	0.0673902481794357	49.960512
8.01000022888184	2116.5048828125	6.64982013404369	3.43170738779008	0.0684878081083298	49.979572
8.10999965667725	2122.7880859375	6.73336116597056	3.49024380557239	0.0696585401892662	50.127944
8.21000003814697	2123.25927734375	6.81667122989893	3.54146352037787	0.0706829279661179	50.139072
8.30999946594238	2128.17504882813	6.89998175948858	3.59999993816018	0.0719268321990967	50.255152
8.40999984741211	2126.14331054688	6.98329182341695	3.66585375741124	0.0731707289814949	50.207176
8.51000022888184	2128.0966796875	7.06660188734531	3.72439017519355	0.0743414610624313	50.2533
8.60999965667725	2130.81787109375	7.14968144893646	3.7829268258065	0.0755121931433678	50.31756
8.71000003814697	2133	7.23299197852612	3.84512194432318	0.0767560973763466	50.369088
8.80999946594238	2131.49829101563	7.31630204245448	3.89999989420176	0.077926829457283	50.333628
8.90999984741211	2134.8466796875	7.39938160404563	3.95853677764535	0.0790243893861771	50.412696
9.01000022888184	2135.51049804688	7.482691667974	4.01707319542766	0.0801951289176941	50.428372
9.10999965667725	2137.55346679688	7.56600219756365	4.07195137813687	0.0813658535480499	50.476616
9.21000003814697	2137.05688476563	7.64908129349351	4.13414649665356	0.0826097577810287	50.464892
9.30999946594238	2138.841796875	7.73239182308316	4.19268291443586	0.0837073177099228	50.50704
9.40999984741211	2141.69946289063	7.81547091901302	4.25487803295255	0.0849512219429016	50.57452
9.51000022888184	2142.73828125	7.89878144860268	4.31341445073485	0.0861219465732574	50.599052
9.60999965667725	2140.6748046875	7.98209197819233	4.37195133417845	0.0872926786541939	50.550324
9.71000003814697	2141.51684570313	8.06563254445791	4.43048775196075	0.0884634181857109	50.570208
9.80999946594238	2141.38159179688	8.14871210604906	4.48170723393559	0.089560978114605	50.567016
9.90999984741211	2144.25537109375	8.23225360363722	4.54390235245228	0.0907317101955414	50.634876
10.0100002288818	2144.19750976563	8.3157941699028	4.60243923589587	0.0919756144285202	50.633512
10.1099996566772	2146.17041015625	8.39910469949245	4.66097565367818	0.093146339058876	50.6801
10.210000038147	2144.3779296875	8.48264526575804	4.71951207146049	0.0942438989877701	50.637772
10.3099994659424	2145.6591796875	8.5661867633462	4.78536589071155	0.0955609828233719	50.668028
10.4099998474121	2147.20947265625	8.64949729293585	4.84390230849385	0.0968048796057701	50.704636
10.5100002288818	2145.5400390625	8.73303785920143	4.90975612774491	0.0979756116867065	50.665212
10.6099996566772	2149.712890625	8.81634838879108	4.96463431045413	0.0992195159196854	50.763752
10.710000038147	2147.17578125	8.89965798705816	5.02317072823644	0.100390240550041	50.70384
10.8099994659424	2148.60205078125	8.98319948464632	5.08536584675312	0.101560980081558	50.73752
10.9099998474121	2147.59643554688	9.06651001423597	5.1475609652698	0.102804884314537	50.713772
11.0100002288818	2145.248046875	9.14981961250305	5.21341478452086	0.104121945798397	50.658316
11.1099996566772	2146.48876953125	9.2331301420927	5.27560990303755	0.105365850031376	50.687616
11.210000038147	2146.22924804688	9.31644067168236	5.33780502155423	0.106682926416397	50.681488
11.3099994659424	2145.37817382813	9.39975120127201	5.40731707587838	0.108000002801418	50.661392
11.4099998474121	2143.57666015625	9.48282983154058	5.47317089512944	0.109317071735859	50.618848
11.5100002288818	2146.38745117188	9.56637132912874	5.53170731291175	0.110560968518257	50.685224
11.6099996566772	2144.12890625	9.6496818587184	5.59756113216281	0.111804872751236	50.631892
11.710000038147	2143.04956054688	9.73299145698547	5.65975625067949	0.113121949136257	50.606404
11.8099994659424	2145.927734375	9.81630198657513	5.72195136919618	0.114292681217194	50.674368
11.9099998474121	2145.57348632813	9.89961251616478	5.78414648771286	0.115536585450172	50.666004
12.0100002288818	2143.21142578125	9.98292211443186	5.84634160622954	0.116780482232571	50.610224
12.1099996566772	2142.25390625	10.0662326440215	5.90853672474623	0.118097558617592	50.587612
12.210000038147	2144.22021484375	10.1493122056127	5.97073184326291	0.119268290698528	50.634048
12.3099994659424	2141.8291015625	10.2330837398767	6.02926826104522	0.120439022779465	50.577584
12.4099998474121	2140.98095703125	10.3163942694664	6.09512208029628	0.121829271316528	50.557552
12.5100002288818	2139.35034179688	10.3997047990561	6.16463413462043	0.123146340250969	50.519048
12.6099996566772	2140.02587890625	10.4832453653216	6.23048795387149	0.12446340918541	50.535
12.710000038147	2139.72680664063	10.5665558949113	6.29634130746126	0.125780493021011	50.52794
12.8099994659424	2140.71826171875	10.6498664245009	6.36219512671232	0.127097561955452	50.551352
12.9099998474121	2137.78271484375	10.7334069907665	6.42439024522901	0.128341466188431	50.482028
13.0100002288818	2138.73315429688	10.8169484883547	6.49390229955316	0.129731714725494	50.504472
13.1099996566772	2139.23583984375	10.9002580866218	6.55975611880422	0.131121948361397	50.516344
13.210000038147	2134.28637695313	10.9835686162114	6.62560993805528	0.132365852594376	50.399468
13.3099994659424	2131.5634765625	11.0671101137996	6.70243892818689	0.133829265832901	50.335168
13.4099998474121	2132.06640625	11.1504197120667	6.76463404670358	0.135146349668503	50.347044
13.5100002288818	2129.67456054688	11.2339612096548	6.82682916522026	0.136463418602943	50.290564
13.6099996566772	2126.927734375	11.3175017759204	6.8963416852057	0.137780487537384	50.2257
13.710000038147	2127.40209960938	11.40081230551	6.96219503879547	0.139170736074448	50.2369
13.8099994659424	2127.10302734375	11.4841228350997	7.035365793854	0.140560984611511	50.229836
13.9099998474121	2124.39916992188	11.5674324333668	7.09756091237068	0.141804873943329	50.165988
14.0100002288818	2121.86157226563	11.6505119949579	7.16707296669483	0.143268287181854	50.106064
14.1099996566772	2123.87719726563	11.7338225245476	7.23658548668027	0.144658535718918	50.153664
14.210000038147	2123.68701171875	11.8171330541372	7.3097562417388	0.14597561955452	50.149172
14.3099994659424	2122.34985351563	11.9002126157284	7.37560959532857	0.147365853190422	50.117596
14.4099998474121	2120.05297851563	11.983753181994	7.4487803503871	0.14890244603157	50.063356
14.5100002288818	2116.14599609375	12.0668327435851	7.51829287037253	0.150292679667473	49.971096
14.6099996566772	2116.69165039063	12.1501432731748	7.58780492469668	0.151609763503075	49.98398
14.710000038147	2114.76342773438	12.2334528714418	7.66097567975521	0.1530731767416	49.938448
14.8099994659424	2111.06567382813	12.3167634010315	7.73780466988683	0.154609754681587	49.851128
14.9099998474121	2109.54150390625	12.4000739306211	7.81463459134102	0.156146347522736	49.815136
15.0100002288818	2107.46997070313	12.4836144968867	7.89146311581135	0.1576097458601	49.76622
15.1099996566772	2107.66064453125	12.5669250264764	7.9609751701355	0.159073173999786	49.77072
15.210000038147	2102.30126953125	12.650235556066	8.03048815578222	0.16046342253685	49.644164
15.3099994659424	2103.65307617188	12.7337761223316	8.11097584664822	0.162073165178299	49.676084
15.4099998474121	2098.98193359375	12.8170866519213	8.18048790097237	0.163463413715363	49.56578
15.5100002288818	2097.34033203125	12.9003971815109	8.25365819036961	0.164926826953888	49.527016
15.6099996566772	2093.66040039063	12.9839377477765	8.33048764616251	0.166390240192413	49.440116
15.710000038147	2090.03466796875	13.0670173093677	8.39999970048666	0.1678536683321	49.354496
15.8099994659424	2089.14135742188	13.1503278389573	8.47682915627956	0.169390231370926	49.333404
15.9099998474121	2082.77099609375	13.233638368547	8.55000037699938	0.170853659510612	49.182972
16.0100002288818	2079.01684570313	13.316947966814	8.63048806786537	0.172536581754684	49.09432
16.1100006103516	2078.2998046875	13.4002584964037	8.70731752365828	0.174073159694672	49.077388
16.2099990844727	2074.3056640625	13.4835690259933	8.79512168467045	0.175756096839905	48.983072
16.3099994659424	2070.41650390625	13.5668786242604	8.87195114046335	0.177292674779892	48.891232
16.4099998474121	2066.57690429688	13.6501891538501	8.94512236118317	0.178682938218117	48.80056
16.5100002288818	2063.94018554688	13.7334996834397	9.0219508856535	0.180292695760727	48.738296
16.6100006103516	2060.60864257813	13.8165792450309	9.10609774291515	0.181902438402176	48.659624
16.7099990844727	2053.8486328125	13.899658806622	9.20121930539608	0.183878064155579	48.499992
16.8099994659424	2047.16760253906	13.9829684048891	9.28170699626207	0.185487806797028	48.342228
16.9099998474121	2042.16552734375	14.0660479664803	9.35853645205498	0.187097564339638	48.224108
17.0100002288818	2035.78100585938	14.1491275280714	9.44634154438972	0.188707321882248	48.07334
17.1100006103516	2027.68566894531	14.2322070896626	9.52682923525572	0.190390229225159	47.882176
17.2099990844727	2019.52722167969	14.3152866512537	9.6109751611948	0.19200000166893	47.68952
17.3099994659424	2010.42236328125	14.3985971808434	9.69146378338337	0.193682923913002	47.474516
17.4099998474121	2004.31860351563	14.4819067791104	9.77560970932245	0.195365846157074	47.33038
17.5100002288818	1992.01928710938	14.5649863407016	9.86707303673029	0.197195127606392	47.039944
17.6100006103516	1985.92993164063	14.6482968702912	9.95853636413813	0.199024394154549	46.896148
17.7099990844727	1973.78173828125	14.7316073998809	10.0536588579416	0.200853660702705	46.609276
17.8099994659424	1960.76843261719	14.814686961472	10.1487804204226	0.202682927250862	46.30198
17.9099998474121	1944.78796386719	14.8982275277376	10.2439019829035	0.204658538103104	45.924612
18.0100002288818	1907.00109863281	14.9815380573273	10.3536583483219	0.20678049325943	45.032308
18.0699996948242	-16.9185218811035	15.0316162034869	10.7304882258177	0.211609750986099	-0.399517375