File: Tensile_tests/PA12vp_C2_XY_5 05-24-22 13 58 01 PM/DAQ- Time, … - (Timed).txt
File Path: C:\MTS TestSuite\Data Files\Chahine\DOE\PA12vp_C2_XY_5 05-24-22 13 58 01 PM\DAQ- Time, … - (Timed).txt
Test: MTS EM Tension (Extensometer)_Grand_Chahine 1
Test Run: PA12vp_C2_XY_5
Date: 5/24/2022 1:57:33 PM


Time 	Load 	Crosshead 	Extensometer 	Strain 	Stress
sec	N	mm	mm	mm/mm	N/mm²
0.100000001490116	48.9728927612305	0.0620788341620937	0.0182926833076635	0.000365853658877313	1.2372235
0.200000002980232	107.384338378906	0.145158308441751	0.0548780481040012	0.00102439022157341	2.71289725
0.300000011920929	160.814422607422	0.229160898015834	0.0841463406686671	0.00160975614562631	4.06272475
0.400000005960464	215.098266601563	0.312932708766311	0.117073170258664	0.00226829270832241	5.434121
0.5	271.045349121094	0.39624294731766	0.146341466461308	0.00285365851595998	6.8475365
0.600000023841858	322.624755859375	0.47978397924453	0.179268288775347	0.00351219531148672	8.1506095
0.699999988079071	373.379486083984	0.56309427600354	0.215853651752695	0.0042439023964107	9.432848
0.800000011920929	425.972015380859	0.646404514554888	0.252439029281959	0.00497560948133469	10.761516
0.899999976158142	477.851013183594	0.729714753106236	0.292682932922617	0.00570731703191996	12.072158
1	524.46435546875	0.812563463114202	0.32926828134805	0.00651219487190247	13.249771
1.10000002384186	573.1123046875	0.895642966497689	0.365853658877313	0.00717073166742921	14.478785
1.20000004768372	623.397277832031	0.978722469881177	0.398780481191352	0.00790243875235319	15.749156
1.29999995231628	667.367370605469	1.06203265022486	0.435365858720616	0.00856097601354122	16.859992
1.39999997615814	713.810913085938	1.14511221181601	0.468292681034654	0.00929268263280392	18.033316
1.5	759.249145507813	1.2284223921597	0.501219532452524	0.00995121896266937	19.181242
1.60000002384186	806.015075683594	1.31150183733553	0.537804851774126	0.0106829265132546	20.36271
1.70000004768372	850.494567871094	1.39481213409454	0.57439022930339	0.0114146340638399	21.486414
1.79999995231628	894.645812988281	1.47789157927036	0.610975606832653	0.0121463416144252	22.601826
1.89999997615814	936.329345703125	1.56143261119723	0.647560984361917	0.0128780491650105	23.654896
2	978.409301757813	1.64474290795624	0.68414636189118	0.0136097557842731	24.71798
2.09999990463257	1019.96343994141	1.72828393988311	0.720731681212783	0.0143414633348584	25.76778
2.20000004768372	1057.61596679688	1.81159423664212	0.753658532630652	0.0150000005960464	26.719012
2.29999995231628	1097.37133789063	1.89513526856899	0.790243910159916	0.0157317072153091	27.723368
2.40000009536743	1139.06164550781	1.97867630049586	0.830487813800573	0.0165365859866142	28.77661
2.5	1175.27014160156	2.06198659725487	0.867073191329837	0.0172682926058769	29.69136
2.59999990463257	1211.72741699219	2.14552762918174	0.899999984540045	0.0179268289357424	30.612396
2.70000004768372	1247.95861816406	2.22906866110861	0.936585362069309	0.0187317077070475	31.52772
2.79999995231628	1280.58996582031	2.31237895786762	0.973170739598572	0.0193902440369129	32.3521
2.90000009536743	1317.90026855469	2.39591998979449	1.00609753280878	0.0200487822294235	33.294688
3	1351.19018554688	2.47923005372286	1.04268291033804	0.0207804888486862	34.135704
3.09999990463257	1385.45617675781	2.56254035048187	1.07926828786731	0.0215121936053038	35.00138
3.20000004768372	1414.50109863281	2.64585064724088	1.11219508107752	0.0221707317978144	35.735156
3.29999995231628	1441.66967773438	2.72916094399989	1.14878045860678	0.0229756087064743	36.421528
3.40000009536743	1471.91882324219	2.8124712407589	1.1890244204551	0.0237073171883821	37.185724
3.5	1499.80346679688	2.8955505695194	1.22926826588809	0.0245121959596872	37.890188
3.59999990463257	1525.87390136719	2.97863013111055	1.26951222773641	0.0253170728683472	38.548816
3.70000004768372	1549.40869140625	3.06194042786956	1.30975607316941	0.0261219516396523	39.143384
3.79999995231628	1574.17272949219	3.14501975663006	1.35365850292146	0.0269268285483122	39.769008
3.90000009536743	1597.59350585938	3.22809931822121	1.39390246476978	0.0278780497610569	40.3607
4	1621.19287109375	3.31140961498022	1.43780489452183	0.0286097563803196	40.9569
4.09999990463257	1639.91967773438	3.39448917657137	1.47804873995483	0.0295609757304192	41.430004
4.19999980926514	1661.04321289063	3.47779924049973	1.51829270180315	0.0303658545017242	41.963656
4.30000019073486	1678.62902832031	3.56087880209088	1.5621951315552	0.0311707314103842	42.407936
4.40000009536743	1695.57580566406	3.64418909884989	1.60975614562631	0.0320487804710865	42.836068
4.5	1710.49987792969	3.7274993956089	1.65365857537836	0.032926831394434	43.2131
4.59999990463257	1726.07849121094	3.81057872436941	1.69390242081136	0.0338048785924912	43.606672
4.69999980926514	1738.15100097656	3.89411975629628	1.74146343488246	0.0347560979425907	43.911664
4.80000019073486	1753.49353027344	3.97743005305529	1.78902444895357	0.0357073172926903	44.299268
4.90000009536743	1765.37438964844	4.06074011698365	1.83658534660935	0.0365853644907475	44.59942
5	1777.04309082031	4.14428114891052	1.88414636068046	0.0376097559928894	44.894212
5.09999990463257	1789.50561523438	4.22759167850018	1.92804879043251	0.0384878031909466	45.209056
5.19999980926514	1801.34655761719	4.31090174242854	1.9756096880883	0.0394390225410461	45.5082
5.30000019073486	1812.85913085938	4.39421227201819	2.02682917006314	0.0403170734643936	45.799048
5.40000009536743	1822.87475585938	4.47752233594656	2.07439018413424	0.0413414649665356	46.052076
5.5	1831.24243164063	4.56106336787343	2.11829273030162	0.0423658564686775	46.263472
5.59999990463257	1841.13854980469	4.6446043998003	2.16585374437273	0.0432438999414444	46.513484
5.69999980926514	1848.580078125	4.72814543172717	2.21707322634757	0.0441951230168343	46.70148
5.80000019073486	1857.56457519531	4.81145596131682	2.26829270832241	0.0452926829457283	46.92846
5.90000009536743	1865.22668457031	4.89476602524519	2.31951219029725	0.0463170744478703	47.122032
6	1870.86865234375	4.97807608917356	2.37073167227209	0.0473414659500122	47.264568
6.09999990463257	1879.27917480469	5.06138661876321	2.41829268634319	0.0482926853001118	47.477048
6.19999980926514	1884.33117675781	5.14469668269157	2.47317063622177	0.0493170730769634	47.604676
6.30000019073486	1892.76647949219	5.22777624428272	2.52073165029287	0.0503414645791054	47.81778
6.40000009536743	1901.6865234375	5.31108630821109	2.56829266436398	0.0512926839292049	48.043132
6.5	1906.25085449219	5.39416586980224	2.6231708470732	0.0523170754313469	48.158444
6.59999990463257	1914.24645996094	5.47724543139338	2.67439032904804	0.0534146316349506	48.36044
6.69999980926514	1917.11999511719	5.56032499298453	2.7219511102885	0.0543658509850502	48.433036
6.80000019073486	1925.72668457031	5.64340455457568	2.78048776090145	0.0554634183645248	48.650468
6.90000009536743	1930.95324707031	5.72671461850405	2.82804877497256	0.0564878061413765	48.782512
7	1934.51733398438	5.80956321209669	2.87560978904366	0.0574390254914761	48.872552
7.09999990463257	1940.41430664063	5.89287374168634	2.92317080311477	0.0583902411162853	49.021528
7.19999980926514	1944.61669921875	5.97595330327749	2.97804875299335	0.0594146363437176	49.127696
7.30000019073486	1948.53588867188	6.05903239920735	3.02926823496819	0.0605121962726116	49.226708
7.40000009536743	1952.12341308594	6.14234292879701	3.0841464176774	0.0616097524762154	49.31734
7.5	1957.65051269531	6.22542249038816	3.13902436755598	0.0626341477036476	49.456976
7.59999990463257	1963.75061035156	6.30873255431652	3.19024384953082	0.0636585354804993	49.611084
7.69999980926514	1968.30810546875	6.39204261824489	3.24146333150566	0.0646829307079315	49.726224
7.80000019073486	1974.31616210938	6.47512217983603	3.29268304631114	0.0657804906368256	49.878008
7.90000009536743	1977.28381347656	6.55843270942569	3.3402438275516	0.0667317062616348	49.95298
8	1980.30090332031	6.64197374135256	3.39512201026082	0.0679024383425713	50.029204
8.10000038146973	1983.15319824219	6.72505330294371	3.44999996013939	0.0689268261194229	50.10126
8.19999980926514	1986.73608398438	6.80836336687207	3.50121944211423	0.0698780491948128	50.191776
8.30000019073486	1989.99304199219	6.89190439879894	3.55243892408907	0.0709024369716644	50.27406
8.39999961853027	1992.73620605469	6.97498396039009	3.60365863889456	0.0719268321990967	50.34336
8.5	1994.78601074219	7.05852499231696	3.65853658877313	0.0730243921279907	50.395144
8.60000038146973	1997.44152832031	7.14160455390811	3.7134145386517	0.0741219520568848	50.462232
8.69999980926514	2001.77734375	7.22491461783648	3.76829272136092	0.0752195119857788	50.571772
8.80000019073486	2003.89770507813	7.30845564976335	3.81951220333576	0.0763170719146729	50.62534
8.89999961853027	2006.05493164063	7.39176571369171	3.87804885394871	0.0774146318435669	50.679836
9	2010.19506835938	7.47507624328136	3.93658550456166	0.0785121992230415	50.784432
9.10000038146973	2012.19506835938	7.55838630720973	3.98414628580213	0.079609751701355	50.83496
9.19999980926514	2013.5517578125	7.64169683679938	4.03902446851134	0.080707311630249	50.869232
9.30000019073486	2016.91760253906	7.72500690072775	4.09390265122056	0.0817317068576813	50.954264
9.39999961853027	2018.86206054688	7.8080864623189	4.15243906900287	0.0829024463891983	51.003388
9.5	2019.66748046875	7.89116602391005	4.20365855097771	0.0839999988675117	51.023736
9.60000038146973	2022.68334960938	7.9744765534997	4.26219496876001	0.0851707309484482	51.099928
9.69999980926514	2025.14416503906	8.05778615176678	4.31707315146923	0.0861951261758804	51.162096
9.80000019073486	2025.61877441406	8.14109668135643	4.36829263344407	0.0872195139527321	51.174088
9.89999961853027	2026.62463378906	8.22417624294758	4.43048775196075	0.0884634181857109	51.1995
10	2030.32019042969	8.30748677253723	4.48170723393559	0.0894878059625626	51.29286
10.1000003814697	2033.00756835938	8.39056540280581	4.54024411737919	0.0907317101955414	51.360752
10.1999998092651	2036.16064453125	8.47387593239546	4.5987805351615	0.0919024348258972	51.440412
10.3000001907349	2035.466796875	8.55741742998362	4.65365871787071	0.0929268300533295	51.422884
10.3999996185303	2038.59826660156	8.64072702825069	4.71219513565302	0.0941707268357277	51.501992
10.5	2038.14660644531	8.72403755784035	4.77073155343533	0.0952682942152023	51.490584
10.6000003814697	2038.65075683594	8.80734808743	4.82926843687892	0.0964390188455582	51.50332
10.6999998092651	2039.15759277344	8.89088865369558	4.88414615392685	0.0975365862250328	51.516124
10.8000001907349	2039.51416015625	8.97396821528673	4.93902433663607	0.0987073108553886	51.525132
10.8999996185303	2040.19372558594	9.05750971287489	4.99756075441837	0.0998780503869057	51.5423
11	2043.06103515625	9.14105027914047	5.05975587293506	0.101121954619884	51.61474
11.1000003814697	2043.15905761719	9.22436080873013	5.11463405564427	0.102219514548779	51.617216
11.1999998092651	2043.39978027344	9.30767133831978	5.17317093908787	0.103317067027092	51.623296
11.3000001907349	2044.62414550781	9.39121190458536	5.23536605760455	0.104560971260071	51.654228
11.3999996185303	2045.98303222656	9.47452243417501	5.29390247538686	0.105731710791588	51.68856
11.5	2049.12573242188	9.5580630004406	5.3451219573617	0.106756098568439	51.767952
11.6000003814697	2047.20288085938	9.64137353003025	5.40731707587838	0.108000002801418	51.719376
11.6999998092651	2050.6123046875	9.7246840596199	5.46951219439507	0.109243907034397	51.805508
11.8000001907349	2049.76342773438	9.80799365788698	5.52804861217737	0.110487803816795	51.784064
11.8999996185303	2051.16625976563	9.89130418747664	5.58658549562097	0.111658535897732	51.819504
12	2050.732421875	9.97461471706629	5.64878061413765	0.112829267978668	51.808544
12.1000003814697	2050.25805664063	10.0576942786574	5.70731703191996	0.114000000059605	51.79656
12.1999998092651	2050.02612304688	10.141234844923	5.77317085117102	0.115243904292583	51.7907
12.3000001907349	2050.06298828125	10.2245453745127	5.83170726895332	0.116487808525562	51.791632
12.3999996185303	2053.33447265625	10.3078559041023	5.89024368673563	0.117658533155918	51.87428
12.5	2051.26611328125	10.3911655023694	5.95243880525231	0.118975609540939	51.822028
12.6000003814697	2052.77807617188	10.4744760319591	6.014633923769	0.120219513773918	51.860224
12.6999998092651	2052.48364257813	10.5577865615487	6.07682904228568	0.121390238404274	51.852784
12.8000001907349	2051.14306640625	10.6410970911384	6.14268286153674	0.122707322239876	51.81892
12.8999996185303	2052.9560546875	10.7241757214069	6.20121974498034	0.123878046870232	51.86472
13	2051.39526367188	10.8077172189951	6.25975616276264	0.125048786401749	51.825288
13.1000003814697	2050.52954101563	10.8912577852607	6.3256099820137	0.126365855336189	51.80342
13.1999998092651	2050.080078125	10.9745683148503	6.39146333560348	0.12768292427063	51.792064
13.3000001907349	2048.88500976563	11.0581098124385	6.45000021904707	0.128926828503609	51.761872
13.3999996185303	2050.60107421875	11.1414194107056	6.51585357263684	0.130170732736588	51.805224
13.5	2048.43041992188	11.2249609082937	6.58536609262228	0.131634145975113	51.750388
13.6000003814697	2048.40405273438	11.3082714378834	6.65487814694643	0.132878050208092	51.74972
13.6999998092651	2047.49047851563	11.3915810361505	6.72439020127058	0.134341463446617	51.72664
13.8000001907349	2048.87670898438	11.4751225337386	6.79024402052164	0.135658532381058	51.761664
13.8999996185303	2049.45556640625	11.5584321320057	6.85243913903832	0.13697561621666	51.776288
14	2047.73217773438	11.6417426615953	6.91097555682063	0.138146340847015	51.732748
14.1000003814697	2044.85766601563	11.7252841591835	6.97317067533731	0.139390245079994	51.660128
14.1999998092651	2045.25708007813	11.8088247254491	7.03902449458838	0.140707314014435	51.67022
14.3000001907349	2046.03601074219	11.8921352550387	7.10853654891253	0.141951218247414	51.689896
14.3999996185303	2042.07189941406	11.9754457846284	7.17439036816359	0.143341451883316	51.589748
14.5	2040.62365722656	12.0587553828955	7.23658548668027	0.144585356116295	51.553164
14.6000003814697	2040.28210449219	12.1420659124851	7.30243884027004	0.145902439951897	51.544532
14.6999998092651	2036.59582519531	12.2251454740763	7.36463395878673	0.147146344184875	51.451404
14.8000001907349	2036.61303710938	12.3086860403419	7.43414647877216	0.148536577820778	51.45184
14.8999996185303	2037.15930175781	12.391765601933	7.50731723383069	0.150073170661926	51.46564
15	2034.12023925781	12.4750761315227	7.58048798888922	0.15146341919899	51.388864
15.1000003814697	2036.72644042969	12.5583866611123	7.64634134247899	0.15278048813343	51.454704
15.1999998092651	2033.98425292969	12.6416962593794	7.72317079827189	0.154243901371956	51.385428
15.3000001907349	2032.46057128906	12.725006788969	7.79268285259604	0.155707314610481	51.346936
15.3999996185303	2031.60266113281	12.8080863505602	7.86219537258148	0.157024398446083	51.32526
15.5	2028.73132324219	12.8916278481483	7.92804919183254	0.158487796783447	51.25272
15.6000003814697	2026.18395996094	12.9749374464154	8.00121948122978	0.159878045320511	51.188364
15.6999998092651	2024.8271484375	13.0582479760051	8.07073153555393	0.161341458559036	51.154088
15.8000001907349	2025.90393066406	13.1417885422707	8.14390275627375	0.1627317070961	51.181292
15.8999996185303	2021.28076171875	13.2248681038618	8.2134148105979	0.164121955633163	51.064496
16	2020.95581054688	13.30840960145	8.2902442663908	0.165585368871689	51.056284
16.1000003814697	2018.46301269531	13.3917201310396	8.36341455578804	0.167121946811676	50.993308
16.2000007629395	2017.53857421875	13.4750297293067	8.43292661011219	0.16851219534874	50.969952
16.2999992370605	2014.47131347656	13.5583402588964	8.506097830832	0.170048773288727	50.892464
16.3999996185303	2015.36010742188	13.641650788486	8.57926812022924	0.171439036726952	50.914916
16.5	2011.26696777344	13.7249603867531	8.65609757602215	0.173048794269562	50.811512
16.6000003814697	2009.27648925781	13.8085018843412	8.73292703181505	0.174439027905464	50.761224
16.7000007629395	2005.70483398438	13.8918124139309	8.80975648760796	0.175975620746613	50.670992
16.7999992370605	2005.23803710938	13.9753529801965	8.87926854193211	0.177439019083977	50.6592
16.8999996185303	2001.39318847656	14.0586635097861	8.95243883132935	0.178902447223663	50.562064
17	1998.00378417969	14.1419740393758	9.02926828712225	0.180439025163651	50.476436
17.1000003814697	1993.18603515625	14.2250526696444	9.09512210637331	0.181829273700714	50.354724
17.2000007629395	1990.74450683594	14.308363199234	9.17926803231239	0.183439031243324	50.293044
17.2999992370605	1990.71899414063	14.3914427608252	9.25975572317839	0.185048788785934	50.2924
17.3999996185303	1985.587890625	14.4747532904148	9.34024434536695	0.186585366725922	50.162768
17.5	1982.80493164063	14.557832852006	9.42073203623295	0.188195124268532	50.092464
17.6000003814697	1981.08728027344	14.6409124135971	9.49390232563019	0.189658537507057	50.049068
17.7000007629395	1976.40173339844	14.7239910438657	9.57439001649618	0.19134147465229	49.930696
17.7999992370605	1971.0283203125	14.8070706054568	9.65487770736218	0.192878037691116	49.794944
17.8999996185303	1966.38537597656	14.890150167048	9.73170716315508	0.194560974836349	49.677648
18	1961.27490234375	14.9734606966376	9.81585402041674	0.196097567677498	49.54854
18.1000003814697	1954.73303222656	15.0567712262273	9.89268254488707	0.19778048992157	49.383268
18.2000007629395	1950.4140625	15.1398507878184	9.97317116707563	0.199243903160095	49.274156
18.2999992370605	1939.26794433594	15.2229303494096	10.0609753280878	0.200999990105629	48.992568
18.3999996185303	1933.17333984375	15.3064709156752	10.1451221853495	0.202682927250862	48.838596
18.5	1921.32702636719	15.3895504772663	10.2365855127573	0.204512193799019	48.53932
18.6000003814697	1905.06372070313	15.4730910435319	10.3353662416339	0.206414625048637	48.128452
18.7000007629395	6.56924104690552	15.5566325411201	10.6865856796503	0.209853664040565	0.16596159375